Switched to branch 'candidate'
Traceback (most recent call last):
  File "./01.interactive.e2e.py", line 75, in <module>
    run.upload_file(name = "outputs/" + model_file_name, path_or_stream = model_file_name)
  File "/home/ninghai/miniconda3/envs/candidate/lib/python3.6/site-packages/azureml/core/run.py", line 510, in upload_file
    return self._client.upload_file(name, path_or_stream)
  File "/home/ninghai/miniconda3/envs/candidate/lib/python3.6/site-packages/azureml/_run_impl/artifacts_client.py", line 57, in upload_file
    assert(len(artifact_keys) == 1)
AssertionError
Traceback (most recent call last):
  File "./02.local.py", line 51, in <module>
    script_to_run = train_script)
  File "/home/ninghai/miniconda3/envs/candidate/lib/python3.6/site-packages/azureml/core/run.py", line 96, in submit
    execute_with_zip=_execute_with_zip)
  File "/home/ninghai/miniconda3/envs/candidate/lib/python3.6/site-packages/azureml/execution/_commands.py", line 110, in start_run
    telemetry_values=telemetry_values)
  File "/home/ninghai/miniconda3/envs/candidate/lib/python3.6/site-packages/azureml/execution/_commands.py", line 258, in _start_internal_local_cloud
    _raise_request_error(response, "starting run")
  File "/home/ninghai/miniconda3/envs/candidate/lib/python3.6/site-packages/azureml/execution/_commands.py", line 729, in _raise_request_error
    raise ExperimentExecutionException(get_http_exception_response_string(response))
azureml.exceptions.azureml_exception.ExperimentExecutionException: {
    "url": "https://eastus2.experiments.azureml.net/execution/v1.0/subscriptions/fac34303-435d-4486-8c3f-7094d82a0b60/resourceGroups/aml-notebooks/providers/Microsoft.MachineLearningServices/workspaces/haieastus2ws3/projects/e2e-02/localrun?runId=e2e-02_1528189458",
    "status_code": 500,
    "text": "{\n  \"error\": {\n    \"code\": \"ServiceError\",\n    \"message\": \"InternalServerError\",\n    \"target\": null,\n    \"details\": [],\n    \"innerError\": null,\n    \"debugInfo\": {\n      \"type\": \"System.Net.Http.HttpRequestException\",\n      \"message\": \"An error occurred while sending the request.\",\n      \"stackTrace\": \"   at System.Runtime.ExceptionServices.ExceptionDispatchInfo.Throw()\\n   at System.Runtime.CompilerServices.TaskAwaiter.HandleNonSuccessAndDebuggerNotification(Task task)\\n   at System.Runtime.CompilerServices.ConfiguredTaskAwaitable`1.ConfiguredTaskAwaiter.GetResult()\\n   at System.Net.Http.DiagnosticsHandler.<SendAsync>d__2.MoveNext()\\n--- End of stack trace from previous location where exception was thrown ---\\n   at System.Runtime.ExceptionServices.ExceptionDispatchInfo.Throw()\\n   at System.Runtime.CompilerServices.TaskAwaiter.HandleNonSuccessAndDebuggerNotification(Task task)\\n   at System.Runtime.CompilerServices.ConfiguredTaskAwaitable`1.ConfiguredTaskAwaiter.GetResult()\\n   at System.Net.Http.HttpClient.<FinishSendAsyncBuffered>d__58.MoveNext()\\n--- End of stack trace from previous location where exception was thrown ---\\n   at System.Runtime.ExceptionServices.ExceptionDispatchInfo.Throw()\\n   at System.Runtime.CompilerServices.TaskAwaiter.HandleNonSuccessAndDebuggerNotification(Task task)\\n   at Microsoft.IdentityModel.Clients.ActiveDirectory.HttpClientWrapper.<GetResponseAsync>d__31.MoveNext()\\n--- End of stack trace from previous location where exception was thrown ---\\n   at System.Runtime.ExceptionServices.ExceptionDispatchInfo.Throw()\\n   at System.Runtime.CompilerServices.TaskAwaiter.HandleNonSuccessAndDebuggerNotification(Task task)\\n   at Microsoft.IdentityModel.Clients.ActiveDirectory.AdalHttpClient.<GetResponseAsync>d__22`1.MoveNext()\\n--- End of stack trace from previous location where exception was thrown ---\\n   at System.Runtime.ExceptionServices.ExceptionDispatchInfo.Throw()\\n   at System.Runtime.CompilerServices.TaskAwaiter.HandleNonSuccessAndDebuggerNotification(Task task)\\n   at Microsoft.IdentityModel.Clients.ActiveDirectory.AdalHttpClient.<GetResponseAsync>d__21`1.MoveNext()\\n--- End of stack trace from previous location where exception was thrown ---\\n   at System.Runtime.ExceptionServices.ExceptionDispatchInfo.Throw()\\n   at System.Runtime.CompilerServices.TaskAwaiter.HandleNonSuccessAndDebuggerNotification(Task task)\\n   at Microsoft.IdentityModel.Clients.ActiveDirectory.AcquireTokenHandlerBase.<SendHttpMessageAsync>d__71.MoveNext()\\n--- End of stack trace from previous location where exception was thrown ---\\n   at System.Runtime.ExceptionServices.ExceptionDispatchInfo.Throw()\\n   at System.Runtime.CompilerServices.TaskAwaiter.HandleNonSuccessAndDebuggerNotification(Task task)\\n   at Microsoft.IdentityModel.Clients.ActiveDirectory.AcquireTokenHandlerBase.<SendTokenRequestAsync>d__68.MoveNext()\\n--- End of stack trace from previous location where exception was thrown ---\\n   at System.Runtime.ExceptionServices.ExceptionDispatchInfo.Throw()\\n   at System.Runtime.CompilerServices.TaskAwaiter.HandleNonSuccessAndDebuggerNotification(Task task)\\n   at Microsoft.IdentityModel.Clients.ActiveDirectory.AcquireTokenHandlerBase.<CheckAndAcquireTokenUsingBroker>d__59.MoveNext()\\n--- End of stack trace from previous location where exception was thrown ---\\n   at System.Runtime.ExceptionServices.ExceptionDispatchInfo.Throw()\\n   at System.Runtime.CompilerServices.TaskAwaiter.HandleNonSuccessAndDebuggerNotification(Task task)\\n   at Microsoft.IdentityModel.Clients.ActiveDirectory.AcquireTokenHandlerBase.<RunAsync>d__57.MoveNext()\\n--- End of stack trace from previous location where exception was thrown ---\\n   at System.Runtime.ExceptionServices.ExceptionDispatchInfo.Throw()\\n   at System.Runtime.CompilerServices.TaskAwaiter.HandleNonSuccessAndDebuggerNotification(Task task)\\n   at Microsoft.IdentityModel.Clients.ActiveDirectory.AuthenticationContext.<AcquireTokenForClientCommonAsync>d__33.MoveNext()\\n--- End of stack trace from previous location where exception was thrown ---\\n   at System.Runtime.ExceptionServices.ExceptionDispatchInfo.Throw()\\n   at System.Runtime.CompilerServices.TaskAwaiter.HandleNonSuccessAndDebuggerNotification(Task task)\\n   at Microsoft.IdentityModel.Clients.ActiveDirectory.AuthenticationContext.<AcquireTokenAsync>d__58.MoveNext()\\n--- End of stack trace from previous location where exception was thrown ---\\n   at System.Runtime.ExceptionServices.ExceptionDispatchInfo.Throw()\\n   at System.Runtime.CompilerServices.TaskAwaiter.HandleNonSuccessAndDebuggerNotification(Task task)\\n   at Microsoft.MachineLearning.Common.WebApi.Security.ServicePrincipalAADTokenProvider.<AcquireTokenForServicePrincipal>d__5.MoveNext() in /opt/vsts/work/1/s/src/azureml-api/src/Common/WebApi/Security/ActiveDirectoryTokenProvider.cs:line 45\\n--- End of stack trace from previous location where exception was thrown ---\\n   at System.Runtime.ExceptionServices.ExceptionDispatchInfo.Throw()\\n   at System.Runtime.CompilerServices.TaskAwaiter.HandleNonSuccessAndDebuggerNotification(Task task)\\n   at Microsoft.MachineLearning.Common.WebApi.Security.ServicePrincipalAADTokenProvider.<GetToken>d__6.MoveNext() in /opt/vsts/work/1/s/src/azureml-api/src/Common/WebApi/Security/ActiveDirectoryTokenProvider.cs:line 54\\n--- End of stack trace from previous location where exception was thrown ---\\n   at System.Runtime.ExceptionServices.ExceptionDispatchInfo.Throw()\\n   at System.Runtime.CompilerServices.TaskAwaiter.HandleNonSuccessAndDebuggerNotification(Task task)\\n   at Microsoft.MachineLearning.Common.WebApi.TeamAccounts.S2SClientFactory.<GenerateAuthenticationHeaderValue>d__4.MoveNext() in /opt/vsts/work/1/s/src/azureml-api/src/Common/WebApi.TeamAccounts/S2SClientFactory.cs:line 58\\n--- End of stack trace from previous location where exception was thrown ---\\n   at System.Runtime.ExceptionServices.ExceptionDispatchInfo.Throw()\\n   at System.Runtime.CompilerServices.TaskAwaiter.HandleNonSuccessAndDebuggerNotification(Task task)\\n   at Microsoft.MachineLearning.Common.WebApi.Client.ServiceInvoker.<_Invoke>d__18`1.MoveNext() in /opt/vsts/work/1/s/src/azureml-api/src/Common/WebApi.Client/ServiceInvoker.cs:line 241\\n--- End of stack trace from previous location where exception was thrown ---\\n   at System.Runtime.ExceptionServices.ExceptionDispatchInfo.Throw()\\n   at System.Runtime.CompilerServices.TaskAwaiter.HandleNonSuccessAndDebuggerNotification(Task task)\\n   at Microsoft.MachineLearning.Common.WebApi.TeamAccounts.ProjectResourceCache.<GetProjectPropertiesS2S>d__8.MoveNext() in /opt/vsts/work/1/s/src/azureml-api/src/Common/WebApi.TeamAccounts/ProjectResourceCache.cs:line 75\\n--- End of stack trace from previous location where exception was thrown ---\\n   at System.Runtime.ExceptionServices.ExceptionDispatchInfo.Throw()\\n   at System.Runtime.CompilerServices.TaskAwaiter.HandleNonSuccessAndDebuggerNotification(Task task)\\n   at Microsoft.MachineLearning.Common.Caching.ObjectCacheExtensions.<GetOrSet>d__0`1.MoveNext() in /opt/vsts/work/1/s/src/azureml-api/src/Common/Core/Caching/IObjectCache.cs:line 45\\n--- End of stack trace from previous location where exception was thrown ---\\n   at System.Runtime.ExceptionServices.ExceptionDispatchInfo.Throw()\\n   at System.Runtime.CompilerServices.TaskAwaiter.HandleNonSuccessAndDebuggerNotification(Task task)\\n   at Microsoft.MachineLearning.Common.WebApi.TeamAccounts.ProjectResourceCache.<GetProjectProperties>d__5.MoveNext() in /opt/vsts/work/1/s/src/azureml-api/src/Common/WebApi.TeamAccounts/ProjectResourceCache.cs:line 54\\n--- End of stack trace from previous location where exception was thrown ---\\n   at System.Runtime.ExceptionServices.ExceptionDispatchInfo.Throw()\\n   at System.Runtime.CompilerServices.TaskAwaiter.HandleNonSuccessAndDebuggerNotification(Task task)\\n   at Microsoft.MachineLearning.Common.WebApi.TeamAccounts.ProjectContext.<GetProjectPropertiesFromProjectServiceS2S>d__15.MoveNext() in /opt/vsts/work/1/s/src/azureml-api/src/Common/WebApi.TeamAccounts/ProjectContext.cs:line 181\\n--- End of stack trace from previous location where exception was thrown ---\\n   at System.Runtime.ExceptionServices.ExceptionDispatchInfo.Throw()\\n   at System.Runtime.CompilerServices.TaskAwaiter.HandleNonSuccessAndDebuggerNotification(Task task)\\n   at Microsoft.MachineLearning.Common.WebApi.TeamAccounts.ProjectContext.<GetTeamProject>d__12.MoveNext() in /opt/vsts/work/1/s/src/azureml-api/src/Common/WebApi.TeamAccounts/ProjectContext.cs:line 94\\n--- End of stack trace from previous location where exception was thrown ---\\n   at System.Runtime.ExceptionServices.ExceptionDispatchInfo.Throw()\\n   at System.Runtime.CompilerServices.TaskAwaiter.HandleNonSuccessAndDebuggerNotification(Task task)\\n   at Microsoft.MachineLearning.Execution.EntryPoints.Api.Controllers.ExecutionController.<MakeStrategyState>d__40.MoveNext() in /opt/vsts/work/1/s/src/azureml-api/src/Execution/EntryPoints/Api/Controllers/ExecutionController.cs:line 682\\n--- End of stack trace from previous location where exception was thrown ---\\n   at System.Runtime.ExceptionServices.ExceptionDispatchInfo.Throw()\\n   at System.Runtime.CompilerServices.TaskAwaiter.HandleNonSuccessAndDebuggerNotification(Task task)\\n   at Microsoft.MachineLearning.Execution.EntryPoints.Api.Controllers.ExecutionController.<StartLocalRun>d__25.MoveNext() in /opt/vsts/work/1/s/src/azureml-api/src/Execution/EntryPoints/Api/Controllers/ExecutionController.cs:line 268\\n--- End of stack trace from previous location where exception was thrown ---\\n   at System.Runtime.ExceptionServices.ExceptionDispatchInfo.Throw()\\n   at System.Runtime.CompilerServices.TaskAwaiter.HandleNonSuccessAndDebuggerNotification(Task task)\\n   at Microsoft.MachineLearning.Execution.EntryPoints.Api.Controllers.ExecutionController.<StartLocalRun>d__21.MoveNext() in /opt/vsts/work/1/s/src/azureml-api/src/Execution/EntryPoints/Api/Controllers/ExecutionController.cs:line 195\\n--- End of stack trace from previous location where exception was thrown ---\\n   at System.Runtime.ExceptionServices.ExceptionDispatchInfo.Throw()\\n   at System.Runtime.CompilerServices.TaskAwaiter.HandleNonSuccessAndDebuggerNotification(Task task)\\n   at Microsoft.AspNetCore.Mvc.Internal.ControllerActionInvoker.<InvokeActionMethodAsync>d__12.MoveNext()\\n--- End of stack trace from previous location where exception was thrown ---\\n   at System.Runtime.ExceptionServices.ExceptionDispatchInfo.Throw()\\n   at System.Runtime.CompilerServices.TaskAwaiter.HandleNonSuccessAndDebuggerNotification(Task task)\\n   at Microsoft.AspNetCore.Mvc.Internal.ControllerActionInvoker.<InvokeNextActionFilterAsync>d__10.MoveNext()\\n--- End of stack trace from previous location where exception was thrown ---\\n   at System.Runtime.ExceptionServices.ExceptionDispatchInfo.Throw()\\n   at Microsoft.AspNetCore.Mvc.Internal.ControllerActionInvoker.Rethrow(ActionExecutedContext context)\\n   at Microsoft.AspNetCore.Mvc.Internal.ControllerActionInvoker.Next(State& next, Scope& scope, Object& state, Boolean& isCompleted)\\n   at Microsoft.AspNetCore.Mvc.Internal.ControllerActionInvoker.<InvokeInnerFilterAsync>d__14.MoveNext()\\n--- End of stack trace from previous location where exception was thrown ---\\n   at System.Runtime.ExceptionServices.ExceptionDispatchInfo.Throw()\\n   at System.Runtime.CompilerServices.TaskAwaiter.HandleNonSuccessAndDebuggerNotification(Task task)\\n   at Microsoft.AspNetCore.Mvc.Internal.ResourceInvoker.<InvokeNextExceptionFilterAsync>d__23.MoveNext()\",\n      \"innerException\": {\n        \"type\": \"System.Net.Http.CurlException\",\n        \"message\": \"Couldn't resolve host name\",\n        \"stackTrace\": \"   at System.Net.Http.CurlHandler.ThrowIfCURLEError(CURLcode error)\\n   at System.Net.Http.CurlHandler.MultiAgent.FinishRequest(StrongToWeakReference`1 easyWrapper, CURLcode messageResult)\",\n        \"innerException\": null,\n        \"data\": {},\n        \"errorResponse\": null\n      },\n      \"data\": {},\n      \"errorResponse\": null\n    }\n  },\n  \"correlation\": {\n    \"operation\": \"d1b9fbfe-497ef97aa3f562c4\",\n    \"request\": \"Ggx0bY8zVjg=\"\n  }\n}"
}
Traceback (most recent call last):
  File "./03.aci.py", line 85, in <module>
    script_to_run = train_script)
  File "/home/ninghai/miniconda3/envs/candidate/lib/python3.6/site-packages/azureml/core/run.py", line 96, in submit
    execute_with_zip=_execute_with_zip)
  File "/home/ninghai/miniconda3/envs/candidate/lib/python3.6/site-packages/azureml/execution/_commands.py", line 116, in start_run
    execute_with_zip=execute_with_zip)
  File "/home/ninghai/miniconda3/envs/candidate/lib/python3.6/site-packages/azureml/execution/_commands.py", line 383, in _start_internal
    _raise_request_error(response, "starting run")
  File "/home/ninghai/miniconda3/envs/candidate/lib/python3.6/site-packages/azureml/execution/_commands.py", line 729, in _raise_request_error
    raise ExperimentExecutionException(get_http_exception_response_string(response))
azureml.exceptions.azureml_exception.ExperimentExecutionException: {
    "url": "https://eastus2.experiments.azureml.net/execution/v1.0/subscriptions/fac34303-435d-4486-8c3f-7094d82a0b60/resourceGroups/aml-notebooks/providers/Microsoft.MachineLearningServices/workspaces/haieastus2ws3/projects/e2e-03/run",
    "status_code": 500,
    "text": "{\n  \"error\": {\n    \"code\": \"ServiceError\",\n    \"message\": \"InternalServerError\",\n    \"target\": null,\n    \"details\": [],\n    \"innerError\": null,\n    \"debugInfo\": {\n      \"type\": \"System.Net.Http.HttpRequestException\",\n      \"message\": \"An error occurred while sending the request.\",\n      \"stackTrace\": \"   at System.Runtime.ExceptionServices.ExceptionDispatchInfo.Throw()\\n   at System.Runtime.CompilerServices.TaskAwaiter.HandleNonSuccessAndDebuggerNotification(Task task)\\n   at System.Runtime.CompilerServices.ConfiguredTaskAwaitable`1.ConfiguredTaskAwaiter.GetResult()\\n   at System.Net.Http.DiagnosticsHandler.<SendAsync>d__2.MoveNext()\\n--- End of stack trace from previous location where exception was thrown ---\\n   at System.Runtime.ExceptionServices.ExceptionDispatchInfo.Throw()\\n   at System.Runtime.CompilerServices.TaskAwaiter.HandleNonSuccessAndDebuggerNotification(Task task)\\n   at System.Runtime.CompilerServices.ConfiguredTaskAwaitable`1.ConfiguredTaskAwaiter.GetResult()\\n   at System.Net.Http.HttpClient.<FinishSendAsyncBuffered>d__58.MoveNext()\\n--- End of stack trace from previous location where exception was thrown ---\\n   at System.Runtime.ExceptionServices.ExceptionDispatchInfo.Throw()\\n   at System.Runtime.CompilerServices.TaskAwaiter.HandleNonSuccessAndDebuggerNotification(Task task)\\n   at Microsoft.MachineLearning.Common.WebApi.Client.ServiceInvoker.<_Invoke>d__18`1.MoveNext() in /opt/vsts/work/1/s/src/azureml-api/src/Common/WebApi.Client/ServiceInvoker.cs:line 247\\n--- End of stack trace from previous location where exception was thrown ---\\n   at System.Runtime.ExceptionServices.ExceptionDispatchInfo.Throw()\\n   at System.Runtime.CompilerServices.TaskAwaiter.HandleNonSuccessAndDebuggerNotification(Task task)\\n   at Microsoft.MachineLearning.Execution.Services.WorkspaceResourcesRetriever.<GetWorkspaceResources>d__7.MoveNext() in /opt/vsts/work/1/s/src/azureml-api/src/Execution/Services/WorkspaceResourcesRetriever.cs:line 114\\n--- End of stack trace from previous location where exception was thrown ---\\n   at System.Runtime.ExceptionServices.ExceptionDispatchInfo.Throw()\\n   at System.Runtime.CompilerServices.TaskAwaiter.HandleNonSuccessAndDebuggerNotification(Task task)\\n   at Microsoft.MachineLearning.Execution.Services.DynamicStrategy.<RetrieveWorkspaceResources>d__26.MoveNext() in /opt/vsts/work/1/s/src/azureml-api/src/Execution/Services/DynamicStrategy.cs:line 380\\n--- End of stack trace from previous location where exception was thrown ---\\n   at System.Runtime.ExceptionServices.ExceptionDispatchInfo.Throw()\\n   at System.Runtime.CompilerServices.TaskAwaiter.HandleNonSuccessAndDebuggerNotification(Task task)\\n   at Microsoft.MachineLearning.Execution.Services.ContainerInstanceStrategy.<CreateUnderlyingJob>d__1.MoveNext() in /opt/vsts/work/1/s/src/azureml-api/src/Execution/Services/ContainerInstanceStrategy.cs:line 55\\n--- End of stack trace from previous location where exception was thrown ---\\n   at System.Runtime.ExceptionServices.ExceptionDispatchInfo.Throw()\\n   at System.Runtime.CompilerServices.TaskAwaiter.HandleNonSuccessAndDebuggerNotification(Task task)\\n   at Microsoft.MachineLearning.Execution.Services.DynamicStrategy.<StartRun>d__20.MoveNext() in /opt/vsts/work/1/s/src/azureml-api/src/Execution/Services/DynamicStrategy.cs:line 216\\n--- End of stack trace from previous location where exception was thrown ---\\n   at System.Runtime.ExceptionServices.ExceptionDispatchInfo.Throw()\\n   at System.Runtime.CompilerServices.TaskAwaiter.HandleNonSuccessAndDebuggerNotification(Task task)\\n   at Microsoft.MachineLearning.Execution.EntryPoints.Api.Controllers.ExecutionController.<StartRun>d__26.MoveNext() in /opt/vsts/work/1/s/src/azureml-api/src/Execution/EntryPoints/Api/Controllers/ExecutionController.cs:line 336\\n--- End of stack trace from previous location where exception was thrown ---\\n   at System.Runtime.ExceptionServices.ExceptionDispatchInfo.Throw()\\n   at Microsoft.MachineLearning.Execution.EntryPoints.Api.Controllers.ExecutionController.<StartRun>d__26.MoveNext() in /opt/vsts/work/1/s/src/azureml-api/src/Execution/EntryPoints/Api/Controllers/ExecutionController.cs:line 343\\n--- End of stack trace from previous location where exception was thrown ---\\n   at System.Runtime.ExceptionServices.ExceptionDispatchInfo.Throw()\\n   at System.Runtime.CompilerServices.TaskAwaiter.HandleNonSuccessAndDebuggerNotification(Task task)\\n   at Microsoft.MachineLearning.Execution.EntryPoints.Api.Controllers.ExecutionController.<StartRun>d__22.MoveNext() in /opt/vsts/work/1/s/src/azureml-api/src/Execution/EntryPoints/Api/Controllers/ExecutionController.cs:line 215\\n--- End of stack trace from previous location where exception was thrown ---\\n   at System.Runtime.ExceptionServices.ExceptionDispatchInfo.Throw()\\n   at System.Runtime.CompilerServices.TaskAwaiter.HandleNonSuccessAndDebuggerNotification(Task task)\\n   at lambda_method(Closure , Object )\\n   at Microsoft.AspNetCore.Mvc.Internal.ControllerActionInvoker.<InvokeActionMethodAsync>d__12.MoveNext()\\n--- End of stack trace from previous location where exception was thrown ---\\n   at System.Runtime.ExceptionServices.ExceptionDispatchInfo.Throw()\\n   at System.Runtime.CompilerServices.TaskAwaiter.HandleNonSuccessAndDebuggerNotification(Task task)\\n   at Microsoft.AspNetCore.Mvc.Internal.ControllerActionInvoker.<InvokeNextActionFilterAsync>d__10.MoveNext()\\n--- End of stack trace from previous location where exception was thrown ---\\n   at System.Runtime.ExceptionServices.ExceptionDispatchInfo.Throw()\\n   at Microsoft.AspNetCore.Mvc.Internal.ControllerActionInvoker.Rethrow(ActionExecutedContext context)\\n   at Microsoft.AspNetCore.Mvc.Internal.ControllerActionInvoker.Next(State& next, Scope& scope, Object& state, Boolean& isCompleted)\\n   at Microsoft.AspNetCore.Mvc.Internal.ControllerActionInvoker.<InvokeInnerFilterAsync>d__14.MoveNext()\\n--- End of stack trace from previous location where exception was thrown ---\\n   at System.Runtime.ExceptionServices.ExceptionDispatchInfo.Throw()\\n   at System.Runtime.CompilerServices.TaskAwaiter.HandleNonSuccessAndDebuggerNotification(Task task)\\n   at Microsoft.AspNetCore.Mvc.Internal.ResourceInvoker.<InvokeNextExceptionFilterAsync>d__23.MoveNext()\",\n      \"innerException\": {\n        \"type\": \"System.Net.Http.CurlException\",\n        \"message\": \"Couldn't resolve host name\",\n        \"stackTrace\": \"   at System.Net.Http.CurlHandler.ThrowIfCURLEError(CURLcode error)\\n   at System.Net.Http.CurlHandler.MultiAgent.FinishRequest(StrongToWeakReference`1 easyWrapper, CURLcode messageResult)\",\n        \"innerException\": null,\n        \"data\": {},\n        \"errorResponse\": null\n      },\n      \"data\": {},\n      \"errorResponse\": null\n    }\n  },\n  \"correlation\": {\n    \"operation\": \"30a968db-4406832514f354ce\",\n    \"request\": \"7qVp3evxKHY=\"\n  }\n}"
}
Traceback (most recent call last):
  File "./04.dsvm.py", line 113, in <module>
    script_to_run = train_script)
  File "/home/ninghai/miniconda3/envs/candidate/lib/python3.6/site-packages/azureml/core/run.py", line 96, in submit
    execute_with_zip=_execute_with_zip)
  File "/home/ninghai/miniconda3/envs/candidate/lib/python3.6/site-packages/azureml/execution/_commands.py", line 116, in start_run
    execute_with_zip=execute_with_zip)
  File "/home/ninghai/miniconda3/envs/candidate/lib/python3.6/site-packages/azureml/execution/_commands.py", line 365, in _start_internal
    snapshot_id = snapshot_async.get()
  File "/home/ninghai/miniconda3/envs/candidate/lib/python3.6/multiprocessing/pool.py", line 644, in get
    raise self._value
  File "/home/ninghai/miniconda3/envs/candidate/lib/python3.6/multiprocessing/pool.py", line 119, in worker
    result = (True, func(*args, **kwds))
  File "/home/ninghai/miniconda3/envs/candidate/lib/python3.6/site-packages/azureml/base_sdk_common/create_snapshot.py", line 102, in create_snapshot
    raise ExperimentExecutionException(get_http_exception_response_string(response))
azureml.exceptions.azureml_exception.ExperimentExecutionException: {
    "url": "https://eastus2.experiments.azureml.net/content/v1.0/subscriptions/fac34303-435d-4486-8c3f-7094d82a0b60/resourceGroups/aml-notebooks/providers/Microsoft.MachineLearningServices/workspaces/haieastus2ws3/snapshots/3bdc1c45-b517-4e83-9798-3521faa1752b?parentSnapshotId=87dccbbf-8da2-4491-8229-d752e0b937ae",
    "status_code": 500,
    "text": "{\n  \"error\": {\n    \"code\": \"ServiceError\",\n    \"message\": \"InternalServerError\",\n    \"target\": null,\n    \"details\": [],\n    \"innerError\": null,\n    \"debugInfo\": {\n      \"type\": \"System.Net.Http.HttpRequestException\",\n      \"message\": \"An error occurred while sending the request.\",\n      \"stackTrace\": \"   at System.Runtime.ExceptionServices.ExceptionDispatchInfo.Throw()\\n   at System.Runtime.CompilerServices.TaskAwaiter.HandleNonSuccessAndDebuggerNotification(Task task)\\n   at System.Runtime.CompilerServices.ConfiguredTaskAwaitable`1.ConfiguredTaskAwaiter.GetResult()\\n   at System.Net.Http.DiagnosticsHandler.<SendAsync>d__2.MoveNext()\\n--- End of stack trace from previous location where exception was thrown ---\\n   at System.Runtime.ExceptionServices.ExceptionDispatchInfo.Throw()\\n   at System.Runtime.CompilerServices.TaskAwaiter.HandleNonSuccessAndDebuggerNotification(Task task)\\n   at System.Runtime.CompilerServices.ConfiguredTaskAwaitable`1.ConfiguredTaskAwaiter.GetResult()\\n   at System.Net.Http.HttpClient.<FinishSendAsyncBuffered>d__58.MoveNext()\\n--- End of stack trace from previous location where exception was thrown ---\\n   at System.Runtime.ExceptionServices.ExceptionDispatchInfo.Throw()\\n   at System.Runtime.CompilerServices.TaskAwaiter.HandleNonSuccessAndDebuggerNotification(Task task)\\n   at Microsoft.MachineLearning.Common.WebApi.Client.ServiceInvoker.<_Invoke>d__18`1.MoveNext() in /opt/vsts/work/1/s/src/azureml-api/src/Common/WebApi.Client/ServiceInvoker.cs:line 247\\n--- End of stack trace from previous location where exception was thrown ---\\n   at System.Runtime.ExceptionServices.ExceptionDispatchInfo.Throw()\\n   at System.Runtime.CompilerServices.TaskAwaiter.HandleNonSuccessAndDebuggerNotification(Task task)\\n   at Microsoft.MachineLearning.Common.WebApi.TeamAccounts.WorkspaceControllerBase.<GetWorkspace>d__21.MoveNext() in /opt/vsts/work/1/s/src/azureml-api/src/Common/WebApi.TeamAccounts/WorkspaceControllerBase.cs:line 153\\n--- End of stack trace from previous location where exception was thrown ---\\n   at System.Runtime.ExceptionServices.ExceptionDispatchInfo.Throw()\\n   at System.Runtime.CompilerServices.TaskAwaiter.HandleNonSuccessAndDebuggerNotification(Task task)\\n   at Microsoft.MachineLearning.Common.WebApi.TeamAccounts.WorkspaceControllerBase.<LoadWorkspaceAsync>d__19.MoveNext() in /opt/vsts/work/1/s/src/azureml-api/src/Common/WebApi.TeamAccounts/WorkspaceControllerBase.cs:line 100\\n--- End of stack trace from previous location where exception was thrown ---\\n   at System.Runtime.ExceptionServices.ExceptionDispatchInfo.Throw()\\n   at System.Runtime.CompilerServices.TaskAwaiter.HandleNonSuccessAndDebuggerNotification(Task task)\\n   at Microsoft.MachineLearning.Common.WebApi.TeamAccounts.WorkspaceControllerBase.<OnActionExecutionAsync>d__18.MoveNext() in /opt/vsts/work/1/s/src/azureml-api/src/Common/WebApi.TeamAccounts/WorkspaceControllerBase.cs:line 89\\n--- End of stack trace from previous location where exception was thrown ---\\n   at System.Runtime.ExceptionServices.ExceptionDispatchInfo.Throw()\\n   at System.Runtime.CompilerServices.TaskAwaiter.HandleNonSuccessAndDebuggerNotification(Task task)\\n   at Microsoft.AspNetCore.Mvc.Internal.ControllerActionFilter.<OnActionExecutionAsync>d__4.MoveNext()\\n--- End of stack trace from previous location where exception was thrown ---\\n   at System.Runtime.ExceptionServices.ExceptionDispatchInfo.Throw()\\n   at System.Runtime.CompilerServices.TaskAwaiter.HandleNonSuccessAndDebuggerNotification(Task task)\\n   at Microsoft.AspNetCore.Mvc.Internal.ControllerActionInvoker.<InvokeInnerFilterAsync>d__14.MoveNext()\\n--- End of stack trace from previous location where exception was thrown ---\\n   at System.Runtime.ExceptionServices.ExceptionDispatchInfo.Throw()\\n   at System.Runtime.CompilerServices.TaskAwaiter.HandleNonSuccessAndDebuggerNotification(Task task)\\n   at Microsoft.AspNetCore.Mvc.Internal.ResourceInvoker.<InvokeNextExceptionFilterAsync>d__23.MoveNext()\",\n      \"innerException\": {\n        \"type\": \"System.Net.Http.CurlException\",\n        \"message\": \"Couldn't resolve host name\",\n        \"stackTrace\": \"   at System.Net.Http.CurlHandler.ThrowIfCURLEError(CURLcode error)\\n   at System.Net.Http.CurlHandler.MultiAgent.FinishRequest(StrongToWeakReference`1 easyWrapper, CURLcode messageResult)\",\n        \"innerException\": null,\n        \"data\": {},\n        \"errorResponse\": null\n      },\n      \"data\": {},\n      \"errorResponse\": null\n    }\n  },\n  \"correlation\": {\n    \"operation\": \"5668b521-486516ff560018c0\",\n    \"request\": \"O7ZJKdTFjqg=\"\n  }\n}"
}
Traceback (most recent call last):
  File "./05.spark.py", line 81, in <module>
    script_to_run = "train-spark.py")
  File "/home/ninghai/miniconda3/envs/candidate/lib/python3.6/site-packages/azureml/core/run.py", line 96, in submit
    execute_with_zip=_execute_with_zip)
  File "/home/ninghai/miniconda3/envs/candidate/lib/python3.6/site-packages/azureml/execution/_commands.py", line 116, in start_run
    execute_with_zip=execute_with_zip)
  File "/home/ninghai/miniconda3/envs/candidate/lib/python3.6/site-packages/azureml/execution/_commands.py", line 383, in _start_internal
    _raise_request_error(response, "starting run")
  File "/home/ninghai/miniconda3/envs/candidate/lib/python3.6/site-packages/azureml/execution/_commands.py", line 729, in _raise_request_error
    raise ExperimentExecutionException(get_http_exception_response_string(response))
azureml.exceptions.azureml_exception.ExperimentExecutionException: {
    "url": "https://eastus2.experiments.azureml.net/execution/v1.0/subscriptions/fac34303-435d-4486-8c3f-7094d82a0b60/resourceGroups/aml-notebooks/providers/Microsoft.MachineLearningServices/workspaces/haieastus2ws3/projects/e2e-05/run",
    "status_code": 500,
    "text": "{\n  \"error\": {\n    \"code\": \"ServiceError\",\n    \"message\": \"InternalServerError\",\n    \"target\": null,\n    \"details\": [],\n    \"innerError\": null,\n    \"debugInfo\": {\n      \"type\": \"System.Net.Http.HttpRequestException\",\n      \"message\": \"An error occurred while sending the request.\",\n      \"stackTrace\": \"   at System.Runtime.ExceptionServices.ExceptionDispatchInfo.Throw()\\n   at System.Runtime.CompilerServices.TaskAwaiter.HandleNonSuccessAndDebuggerNotification(Task task)\\n   at System.Runtime.CompilerServices.ConfiguredTaskAwaitable`1.ConfiguredTaskAwaiter.GetResult()\\n   at System.Net.Http.DiagnosticsHandler.<SendAsync>d__2.MoveNext()\\n--- End of stack trace from previous location where exception was thrown ---\\n   at System.Runtime.ExceptionServices.ExceptionDispatchInfo.Throw()\\n   at System.Runtime.CompilerServices.TaskAwaiter.HandleNonSuccessAndDebuggerNotification(Task task)\\n   at System.Runtime.CompilerServices.ConfiguredTaskAwaitable`1.ConfiguredTaskAwaiter.GetResult()\\n   at System.Net.Http.HttpClient.<FinishSendAsyncBuffered>d__58.MoveNext()\\n--- End of stack trace from previous location where exception was thrown ---\\n   at System.Runtime.ExceptionServices.ExceptionDispatchInfo.Throw()\\n   at System.Runtime.CompilerServices.TaskAwaiter.HandleNonSuccessAndDebuggerNotification(Task task)\\n   at Microsoft.MachineLearning.Common.WebApi.Client.ServiceInvoker.<_Invoke>d__18`1.MoveNext() in /opt/vsts/work/1/s/src/azureml-api/src/Common/WebApi.Client/ServiceInvoker.cs:line 247\\n--- End of stack trace from previous location where exception was thrown ---\\n   at System.Runtime.ExceptionServices.ExceptionDispatchInfo.Throw()\\n   at System.Runtime.CompilerServices.TaskAwaiter.HandleNonSuccessAndDebuggerNotification(Task task)\\n   at Microsoft.MachineLearning.Execution.Services.ProxyClients.ArtifactServiceProxy.<BatchCreateEmptyArtifacts>d__4.MoveNext() in /opt/vsts/work/1/s/src/azureml-api/src/Execution/Services/ProxyClients/ArtifactServiceProxy.cs:line 56\\n--- End of stack trace from previous location where exception was thrown ---\\n   at System.Runtime.ExceptionServices.ExceptionDispatchInfo.Throw()\\n   at System.Runtime.CompilerServices.TaskAwaiter.HandleNonSuccessAndDebuggerNotification(Task task)\\n   at Microsoft.MachineLearning.Execution.Services.HistoryManager.<CreateArtifactWithWriteSas>d__9.MoveNext() in /opt/vsts/work/1/s/src/azureml-api/src/Execution/Services/HistoryManager.cs:line 155\\n--- End of stack trace from previous location where exception was thrown ---\\n   at System.Runtime.ExceptionServices.ExceptionDispatchInfo.Throw()\\n   at System.Runtime.CompilerServices.TaskAwaiter.HandleNonSuccessAndDebuggerNotification(Task task)\\n   at Microsoft.MachineLearning.Execution.Services.DynamicStrategy.<CreateIceLogsStructure>d__31.MoveNext() in /opt/vsts/work/1/s/src/azureml-api/src/Execution/Services/DynamicStrategy.cs:line 481\\n--- End of stack trace from previous location where exception was thrown ---\\n   at System.Runtime.ExceptionServices.ExceptionDispatchInfo.Throw()\\n   at System.Runtime.CompilerServices.TaskAwaiter.HandleNonSuccessAndDebuggerNotification(Task task)\\n   at Microsoft.MachineLearning.Execution.Services.DynamicStrategy.<StartRun>d__20.MoveNext() in /opt/vsts/work/1/s/src/azureml-api/src/Execution/Services/DynamicStrategy.cs:line 207\\n--- End of stack trace from previous location where exception was thrown ---\\n   at System.Runtime.ExceptionServices.ExceptionDispatchInfo.Throw()\\n   at System.Runtime.CompilerServices.TaskAwaiter.HandleNonSuccessAndDebuggerNotification(Task task)\\n   at Microsoft.MachineLearning.Execution.EntryPoints.Api.Controllers.ExecutionController.<StartRun>d__26.MoveNext() in /opt/vsts/work/1/s/src/azureml-api/src/Execution/EntryPoints/Api/Controllers/ExecutionController.cs:line 336\\n--- End of stack trace from previous location where exception was thrown ---\\n   at System.Runtime.ExceptionServices.ExceptionDispatchInfo.Throw()\\n   at Microsoft.MachineLearning.Execution.EntryPoints.Api.Controllers.ExecutionController.<StartRun>d__26.MoveNext() in /opt/vsts/work/1/s/src/azureml-api/src/Execution/EntryPoints/Api/Controllers/ExecutionController.cs:line 343\\n--- End of stack trace from previous location where exception was thrown ---\\n   at System.Runtime.ExceptionServices.ExceptionDispatchInfo.Throw()\\n   at System.Runtime.CompilerServices.TaskAwaiter.HandleNonSuccessAndDebuggerNotification(Task task)\\n   at Microsoft.MachineLearning.Execution.EntryPoints.Api.Controllers.ExecutionController.<StartRun>d__22.MoveNext() in /opt/vsts/work/1/s/src/azureml-api/src/Execution/EntryPoints/Api/Controllers/ExecutionController.cs:line 215\\n--- End of stack trace from previous location where exception was thrown ---\\n   at System.Runtime.ExceptionServices.ExceptionDispatchInfo.Throw()\\n   at System.Runtime.CompilerServices.TaskAwaiter.HandleNonSuccessAndDebuggerNotification(Task task)\\n   at lambda_method(Closure , Object )\\n   at Microsoft.AspNetCore.Mvc.Internal.ControllerActionInvoker.<InvokeActionMethodAsync>d__12.MoveNext()\\n--- End of stack trace from previous location where exception was thrown ---\\n   at System.Runtime.ExceptionServices.ExceptionDispatchInfo.Throw()\\n   at System.Runtime.CompilerServices.TaskAwaiter.HandleNonSuccessAndDebuggerNotification(Task task)\\n   at Microsoft.AspNetCore.Mvc.Internal.ControllerActionInvoker.<InvokeNextActionFilterAsync>d__10.MoveNext()\\n--- End of stack trace from previous location where exception was thrown ---\\n   at System.Runtime.ExceptionServices.ExceptionDispatchInfo.Throw()\\n   at Microsoft.AspNetCore.Mvc.Internal.ControllerActionInvoker.Rethrow(ActionExecutedContext context)\\n   at Microsoft.AspNetCore.Mvc.Internal.ControllerActionInvoker.Next(State& next, Scope& scope, Object& state, Boolean& isCompleted)\\n   at Microsoft.AspNetCore.Mvc.Internal.ControllerActionInvoker.<InvokeInnerFilterAsync>d__14.MoveNext()\\n--- End of stack trace from previous location where exception was thrown ---\\n   at System.Runtime.ExceptionServices.ExceptionDispatchInfo.Throw()\\n   at System.Runtime.CompilerServices.TaskAwaiter.HandleNonSuccessAndDebuggerNotification(Task task)\\n   at Microsoft.AspNetCore.Mvc.Internal.ResourceInvoker.<InvokeNextExceptionFilterAsync>d__23.MoveNext()\",\n      \"innerException\": {\n        \"type\": \"System.Net.Http.CurlException\",\n        \"message\": \"Couldn't resolve host name\",\n        \"stackTrace\": \"   at System.Net.Http.CurlHandler.ThrowIfCURLEError(CURLcode error)\\n   at System.Net.Http.CurlHandler.MultiAgent.FinishRequest(StrongToWeakReference`1 easyWrapper, CURLcode messageResult)\",\n        \"innerException\": null,\n        \"data\": {},\n        \"errorResponse\": null\n      },\n      \"data\": {},\n      \"errorResponse\": null\n    }\n  },\n  \"correlation\": {\n    \"operation\": \"153640f3-4dbe7a3d9a7bb369\",\n    \"request\": \"9E7rDLVVC8o=\"\n  }\n}"
}
Traceback (most recent call last):
  File "/home/ninghai/miniconda3/envs/candidate/lib/python3.6/site-packages/azureml/core/compute/compute.py", line 255, in list
    resp.raise_for_status()
  File "/home/ninghai/miniconda3/envs/candidate/lib/python3.6/site-packages/requests/models.py", line 935, in raise_for_status
    raise HTTPError(http_error_msg, response=self)
requests.exceptions.HTTPError: 500 Server Error: InternalServerError for url: https://management.azure.com/subscriptions/fac34303-435d-4486-8c3f-7094d82a0b60/resourceGroups/aml-notebooks/providers/Microsoft.MachineLearningServices/workspaces/haieastus2ws3/computes?api-version=2018-03-01-preview

During handling of the above exception, another exception occurred:

Traceback (most recent call last):
  File "./07.sklearn.hd.py", line 47, in <module>
    for ct in ws.list_compute_targets():
  File "/home/ninghai/miniconda3/envs/candidate/lib/python3.6/site-packages/azureml/core/workspace.py", line 770, in list_compute_targets
    return ComputeTarget.list(self)
  File "/home/ninghai/miniconda3/envs/candidate/lib/python3.6/site-packages/azureml/core/compute/compute.py", line 260, in list
    'Content: {}'.format(resp.status_code, resp.headers, resp.content))
azureml.exceptions.azureml_exception.ComputeTargetException: Error occurred retrieving targets:
Response Code: 500
Headers: {'Cache-Control': 'no-cache', 'Pragma': 'no-cache', 'Content-Length': '271', 'Content-Type': 'application/json; charset=utf-8', 'Expires': '-1', 'x-ms-ratelimit-remaining-subscription-reads': '14998', 'x-ms-failure-cause': 'service', 'Request-Context': 'appId=cid-v1:1b9e04bd-9ec9-4db8-a06f-499e913f340c', 'x-ms-client-request-id': '9d8b15a3-075e-4afe-9cfe-8fb82709395c', 'x-ms-client-session-id': '', 'Strict-Transport-Security': 'max-age=31536000; includeSubDomains', 'x-ms-request-id': '923e0dd3-21cc-4eb5-bea4-e952e2b1ed4e', 'x-ms-correlation-request-id': '923e0dd3-21cc-4eb5-bea4-e952e2b1ed4e', 'x-ms-routing-request-id': 'SOUTHCENTRALUS:20180605T091509Z:923e0dd3-21cc-4eb5-bea4-e952e2b1ed4e', 'X-Content-Type-Options': 'nosniff', 'Date': 'Tue, 05 Jun 2018 09:15:09 GMT', 'Connection': 'close'}
Content: b'{\n  "error": {\n    "code": "ServiceError",\n    "message": "InternalServerError",\n    "target": null,\n    "details": [],\n    "innerError": null,\n    "debugInfo": null\n  },\n  "correlation": {\n    "operation": "b4798013-4828380ac948b037",\n    "request": "8o1TeJFG/p8="\n  }\n}'
Traceback (most recent call last):
  File "./08.tf.hd.py", line 92, in <module>
    run = tfe.fit()
  File "/home/ninghai/miniconda3/envs/candidate/lib/python3.6/site-packages/azureml/train/dnn.py", line 320, in fit
    return super(TensorFlow, self).fit()
  File "/home/ninghai/miniconda3/envs/candidate/lib/python3.6/site-packages/azureml/train/estimator.py", line 91, in fit
    _telemetry_values=telemetry_values)
  File "/home/ninghai/miniconda3/envs/candidate/lib/python3.6/site-packages/azureml/core/run.py", line 96, in submit
    execute_with_zip=_execute_with_zip)
  File "/home/ninghai/miniconda3/envs/candidate/lib/python3.6/site-packages/azureml/execution/_commands.py", line 116, in start_run
    execute_with_zip=execute_with_zip)
  File "/home/ninghai/miniconda3/envs/candidate/lib/python3.6/site-packages/azureml/execution/_commands.py", line 383, in _start_internal
    _raise_request_error(response, "starting run")
  File "/home/ninghai/miniconda3/envs/candidate/lib/python3.6/site-packages/azureml/execution/_commands.py", line 729, in _raise_request_error
    raise ExperimentExecutionException(get_http_exception_response_string(response))
azureml.exceptions.azureml_exception.ExperimentExecutionException: {
    "url": "https://eastus2.experiments.azureml.net/execution/v1.0/subscriptions/fac34303-435d-4486-8c3f-7094d82a0b60/resourceGroups/aml-notebooks/providers/Microsoft.MachineLearningServices/workspaces/haieastus2ws3/projects/e2e-08/run",
    "status_code": 502,
    "text": "<html>\r\n<head><title>502 Bad Gateway</title></head>\r\n<body bgcolor=\"white\">\r\n<center><h1>502 Bad Gateway</h1></center>\r\n<hr><center>nginx</center>\r\n</body>\r\n</html>\r\n"
}
Client-Request-ID=2dba5786-68a1-11e8-9288-000d3a71b7c3 Retry policy did not allow for a retry: Server-Timestamp=Tue, 05 Jun 2018 09:16:49 GMT, Server-Request-ID=5f9a5a3d-f01e-0124-78ad-fc8b2a000000, HTTP status code=409, Exception=The specified container already exists.ErrorCode: ContainerAlreadyExists<?xml version="1.0" encoding="utf-8"?><Error><Code>ContainerAlreadyExists</Code><Message>The specified container already exists.RequestId:5f9a5a3d-f01e-0124-78ad-fc8b2a000000Time:2018-06-05T09:16:50.2411123Z</Message></Error>.
Client-Request-ID=7fe0cefa-68a1-11e8-9288-000d3a71b7c3 Retry policy did not allow for a retry: Server-Timestamp=Tue, 05 Jun 2018 09:19:07 GMT, Server-Request-ID=7b89ebf2-d01e-005a-5cae-fc52b0000000, HTTP status code=409, Exception=The specified container already exists.ErrorCode: ContainerAlreadyExists<?xml version="1.0" encoding="utf-8"?><Error><Code>ContainerAlreadyExists</Code><Message>The specified container already exists.RequestId:7b89ebf2-d01e-005a-5cae-fc52b0000000Time:2018-06-05T09:19:08.1097751Z</Message></Error>.
Client-Request-ID=7fe0cefc-68a1-11e8-9288-000d3a71b7c3 Retry policy did not allow for a retry: Server-Timestamp=Tue, 05 Jun 2018 09:19:07 GMT, Server-Request-ID=5b87b643-801e-002f-04ae-fcd50b000000, HTTP status code=409, Exception=The specified container already exists.ErrorCode: ContainerAlreadyExists<?xml version="1.0" encoding="utf-8"?><Error><Code>ContainerAlreadyExists</Code><Message>The specified container already exists.RequestId:5b87b643-801e-002f-04ae-fcd50b000000Time:2018-06-05T09:19:08.3266980Z</Message></Error>.
Client-Request-ID=7fe0cefe-68a1-11e8-9288-000d3a71b7c3 Retry policy did not allow for a retry: Server-Timestamp=Tue, 05 Jun 2018 09:19:08 GMT, Server-Request-ID=b8bd3016-b01e-0068-0aae-fc0a60000000, HTTP status code=409, Exception=The specified container already exists.ErrorCode: ContainerAlreadyExists<?xml version="1.0" encoding="utf-8"?><Error><Code>ContainerAlreadyExists</Code><Message>The specified container already exists.RequestId:b8bd3016-b01e-0068-0aae-fc0a60000000Time:2018-06-05T09:19:08.5036305Z</Message></Error>.
Client-Request-ID=7fe0cf00-68a1-11e8-9288-000d3a71b7c3 Retry policy did not allow for a retry: Server-Timestamp=Tue, 05 Jun 2018 09:19:08 GMT, Server-Request-ID=bc5d396a-d01e-0015-3fae-fc96a8000000, HTTP status code=409, Exception=The specified container already exists.ErrorCode: ContainerAlreadyExists<?xml version="1.0" encoding="utf-8"?><Error><Code>ContainerAlreadyExists</Code><Message>The specified container already exists.RequestId:bc5d396a-d01e-0015-3fae-fc96a8000000Time:2018-06-05T09:19:08.6948983Z</Message></Error>.
Traceback (most recent call last):
  File "./10.o16n.py", line 64, in <module>
    image = image)
  File "/home/ninghai/miniconda3/envs/candidate/lib/python3.6/site-packages/azureml/core/workspace.py", line 818, in deploy_webservice
    'creation state.'.format(image.id))
azureml.exceptions.azureml_exception.WebserviceException: Unable to create service with image myimage:24 in non "Succeeded" creation state.
error: Your local changes to the following files would be overwritten by checkout:
	e2e_test/aml_config/config.json
Please, commit your changes or stash them before you can switch branches.
Aborting
