Switched to branch 'candidate'
Client-Request-ID=0c9b3aba-670d-11e8-9288-000d3a71b7c3 Retry policy did not allow for a retry: Server-Timestamp=Sun, 03 Jun 2018 09:03:57 GMT, Server-Request-ID=bc9361ac-d01e-0040-1e19-fb2291000000, HTTP status code=409, Exception=The specified container already exists.ErrorCode: ContainerAlreadyExists<?xml version="1.0" encoding="utf-8"?><Error><Code>ContainerAlreadyExists</Code><Message>The specified container already exists.RequestId:bc9361ac-d01e-0040-1e19-fb2291000000Time:2018-06-03T09:03:57.9611880Z</Message></Error>.
Client-Request-ID=0e2e40de-670d-11e8-9288-000d3a71b7c3 Retry policy did not allow for a retry: Server-Timestamp=Sun, 03 Jun 2018 09:04:00 GMT, Server-Request-ID=57837424-501e-0085-3c19-fb0874000000, HTTP status code=409, Exception=The specified container already exists.ErrorCode: ContainerAlreadyExists<?xml version="1.0" encoding="utf-8"?><Error><Code>ContainerAlreadyExists</Code><Message>The specified container already exists.RequestId:57837424-501e-0085-3c19-fb0874000000Time:2018-06-03T09:04:00.6016223Z</Message></Error>.
Client-Request-ID=0e2e40e0-670d-11e8-9288-000d3a71b7c3 Retry policy did not allow for a retry: Server-Timestamp=Sun, 03 Jun 2018 09:03:59 GMT, Server-Request-ID=804c644a-801e-005d-1119-fb2f2d000000, HTTP status code=409, Exception=The specified container already exists.ErrorCode: ContainerAlreadyExists<?xml version="1.0" encoding="utf-8"?><Error><Code>ContainerAlreadyExists</Code><Message>The specified container already exists.RequestId:804c644a-801e-005d-1119-fb2f2d000000Time:2018-06-03T09:04:00.7590608Z</Message></Error>.
Client-Request-ID=0e2e40e2-670d-11e8-9288-000d3a71b7c3 Retry policy did not allow for a retry: Server-Timestamp=Sun, 03 Jun 2018 09:03:59 GMT, Server-Request-ID=005d8cee-201e-0044-0219-fbaf96000000, HTTP status code=409, Exception=The specified container already exists.ErrorCode: ContainerAlreadyExists<?xml version="1.0" encoding="utf-8"?><Error><Code>ContainerAlreadyExists</Code><Message>The specified container already exists.RequestId:005d8cee-201e-0044-0219-fbaf96000000Time:2018-06-03T09:04:00.9155088Z</Message></Error>.
Client-Request-ID=0e2e40e4-670d-11e8-9288-000d3a71b7c3 Retry policy did not allow for a retry: Server-Timestamp=Sun, 03 Jun 2018 09:04:01 GMT, Server-Request-ID=94144f50-d01e-0032-6c19-fb25de000000, HTTP status code=409, Exception=The specified container already exists.ErrorCode: ContainerAlreadyExists<?xml version="1.0" encoding="utf-8"?><Error><Code>ContainerAlreadyExists</Code><Message>The specified container already exists.RequestId:94144f50-d01e-0032-6c19-fb25de000000Time:2018-06-03T09:04:01.0771627Z</Message></Error>.
Traceback (most recent call last):
  File "/home/ninghai/miniconda3/envs/candidate/lib/python3.6/site-packages/azureml/core/webservice/webservice.py", line 281, in _deploy_webservice
    resp.raise_for_status()
  File "/home/ninghai/miniconda3/envs/candidate/lib/python3.6/site-packages/requests/models.py", line 935, in raise_for_status
    raise HTTPError(http_error_msg, response=self)
requests.exceptions.HTTPError: 409 Client Error: Conflict for url: https://eastus2euap.modelmanagement.azureml.net/api/subscriptions/fac34303-435d-4486-8c3f-7094d82a0b60/resourceGroups/aml-notebooks/providers/Microsoft.MachineLearningServices/workspaces/haieastus2euapws/services?api-version=2018-03-01-preview

During handling of the above exception, another exception occurred:

Traceback (most recent call last):
  File "./01.interactive.e2e.py", line 139, in <module>
    driver = 'score.py')
  File "/home/ninghai/miniconda3/envs/candidate/lib/python3.6/site-packages/azureml/core/workspace.py", line 819, in deploy_webservice
    return Webservice.deploy_from_image(self, name, image, deploy_config, target)
  File "/home/ninghai/miniconda3/envs/candidate/lib/python3.6/site-packages/azureml/core/webservice/webservice.py", line 242, in deploy_from_image
    return child._deploy(workspace, name, image, deployment_config)
  File "/home/ninghai/miniconda3/envs/candidate/lib/python3.6/site-packages/azureml/core/webservice/aci.py", line 109, in _deploy
    return Webservice._deploy_webservice(workspace, name, create_payload, AciWebservice)
  File "/home/ninghai/miniconda3/envs/candidate/lib/python3.6/site-packages/azureml/core/webservice/webservice.py", line 286, in _deploy_webservice
    'Content: {}'.format(resp.status_code, resp.headers, resp.content))
azureml.exceptions.azureml_exception.WebserviceException: Received bad response from Model Management Service:
Response Code: 409
Headers: {'Date': 'Sun, 03 Jun 2018 09:05:28 GMT', 'Content-Type': 'application/json', 'Transfer-Encoding': 'chunked', 'Connection': 'keep-alive', 'api-supported-versions': '2018-03-01-preview', 'x-ms-client-request-id': '1216cf2dafea4dfc8580c69f024c4340', 'x-ms-client-session-id': '', 'Strict-Transport-Security': 'max-age=15724800; includeSubDomains; preload'}
Content: b'{"code":"Conflict","statusCode":409,"message":"Conflict","details":[{"code":"ServiceWithNameExists","message":"Workspace haieastus2euapws already contains a Service with name: rrs01a"}]}'
Traceback (most recent call last):
  File "./04.dsvm.py", line 45, in <module>
    password = 'Spark888*123'))
  File "/home/ninghai/miniconda3/envs/candidate/lib/python3.6/site-packages/azureml/core/project.py", line 285, in attach_legacy_compute_target
    _compute_target_commands.attach_ssh_based_compute_targets(self, compute_target)
  File "/home/ninghai/miniconda3/envs/candidate/lib/python3.6/site-packages/azureml/project/_compute_target_commands.py", line 67, in attach_ssh_based_compute_targets
    ssh_key_info, project_context, compute_skeleton)
  File "/home/ninghai/miniconda3/envs/candidate/lib/python3.6/site-packages/azureml/project/_compute_target_commands.py", line 163, in _set_password_or_key_info
    set_credentials(project_context, key, password)
  File "/home/ninghai/miniconda3/envs/candidate/lib/python3.6/site-packages/azureml/base_sdk_common/credentials.py", line 21, in set_credentials
    response.raise_for_status()
  File "/home/ninghai/miniconda3/envs/candidate/lib/python3.6/site-packages/requests/models.py", line 935, in raise_for_status
    raise HTTPError(http_error_msg, response=self)
requests.exceptions.HTTPError: 500 Server Error: InternalServerError for url: https://eastus2euap.experiments.azureml.net/credential/v1.0/subscriptions/fac34303-435d-4486-8c3f-7094d82a0b60/resourceGroups/aml-notebooks/providers/Microsoft.MachineLearningServices/workspaces/haieastus2euapws/secrets
Traceback (most recent call last):
  File "./08.tf.hd.py", line 94, in <module>
    run.wait_for_completion(show_output = True)
  File "/home/ninghai/miniconda3/envs/candidate/lib/python3.6/site-packages/azureml/core/experiment_run.py", line 69, in wait_for_completion
  File "/home/ninghai/miniconda3/envs/candidate/lib/python3.6/site-packages/azureml/core/experiment_run.py", line 214, in _stream_run_output
  File "/home/ninghai/miniconda3/envs/candidate/lib/python3.6/site-packages/azureml/execution/_commands.py", line 830, in _get_content_from_uri
  File "/home/ninghai/miniconda3/envs/candidate/lib/python3.6/site-packages/requests/sessions.py", line 521, in get
  File "/home/ninghai/miniconda3/envs/candidate/lib/python3.6/site-packages/requests/sessions.py", line 508, in request
  File "/home/ninghai/miniconda3/envs/candidate/lib/python3.6/site-packages/requests/sessions.py", line 618, in send
  File "/home/ninghai/miniconda3/envs/candidate/lib/python3.6/site-packages/requests/adapters.py", line 407, in send
  File "/home/ninghai/miniconda3/envs/candidate/lib/python3.6/site-packages/requests/adapters.py", line 226, in cert_verify
OSError: Could not find a suitable TLS CA certificate bundle, invalid path: /home/ninghai/miniconda3/envs/candidate/lib/python3.6/site-packages/certifi/cacert.pem
Traceback (most recent call last):
  File "./10.o16n.py", line 6, in <module>
    import azureml.core
ImportError: No module named azureml.core
Already on 'master'
