Traceback (most recent call last):
  File "/home/ninghai/miniconda3/envs/rc/lib/python3.6/site-packages/requests/adapters.py", line 440, in send
    timeout=timeout
  File "/home/ninghai/miniconda3/envs/rc/lib/python3.6/site-packages/urllib3/connectionpool.py", line 732, in urlopen
    body_pos=body_pos, **response_kw)
  File "/home/ninghai/miniconda3/envs/rc/lib/python3.6/site-packages/urllib3/connectionpool.py", line 732, in urlopen
    body_pos=body_pos, **response_kw)
  File "/home/ninghai/miniconda3/envs/rc/lib/python3.6/site-packages/urllib3/connectionpool.py", line 732, in urlopen
    body_pos=body_pos, **response_kw)
  File "/home/ninghai/miniconda3/envs/rc/lib/python3.6/site-packages/urllib3/connectionpool.py", line 712, in urlopen
    retries = retries.increment(method, url, response=response, _pool=self)
  File "/home/ninghai/miniconda3/envs/rc/lib/python3.6/site-packages/urllib3/util/retry.py", line 388, in increment
    raise MaxRetryError(_pool, url, error or ResponseError(cause))
urllib3.exceptions.MaxRetryError: HTTPSConnectionPool(host='eastus2euap.experiments.azureml.net', port=443): Max retries exceeded with url: /artifact/v1.0/subscriptions/fac34303-435d-4486-8c3f-7094d82a0b60/resourceGroups/aml-notebooks/providers/Microsoft.MachineLearningServices/workspaces/haieastus2euapws/artifacts/batch/metadata/ExperimentRun/1b6d5e57-7b46-42bd-84b9-ff799dca335e (Caused by ResponseError('too many 500 error responses',))

During handling of the above exception, another exception occurred:

Traceback (most recent call last):
  File "/home/ninghai/miniconda3/envs/rc/lib/python3.6/site-packages/msrest/service_client.py", line 257, in send
    **kwargs)
  File "/home/ninghai/miniconda3/envs/rc/lib/python3.6/site-packages/requests/sessions.py", line 508, in request
    resp = self.send(prep, **send_kwargs)
  File "/home/ninghai/miniconda3/envs/rc/lib/python3.6/site-packages/requests/sessions.py", line 618, in send
    r = adapter.send(request, **kwargs)
  File "/home/ninghai/miniconda3/envs/rc/lib/python3.6/site-packages/requests/adapters.py", line 499, in send
    raise RetryError(e, request=request)
requests.exceptions.RetryError: HTTPSConnectionPool(host='eastus2euap.experiments.azureml.net', port=443): Max retries exceeded with url: /artifact/v1.0/subscriptions/fac34303-435d-4486-8c3f-7094d82a0b60/resourceGroups/aml-notebooks/providers/Microsoft.MachineLearningServices/workspaces/haieastus2euapws/artifacts/batch/metadata/ExperimentRun/1b6d5e57-7b46-42bd-84b9-ff799dca335e (Caused by ResponseError('too many 500 error responses',))

During handling of the above exception, another exception occurred:

Traceback (most recent call last):
  File "./01.interactive.e2e.py", line 75, in <module>
    run.upload_file(name = "outputs/" + model_file_name, path_or_stream = model_file_name)
  File "/home/ninghai/miniconda3/envs/rc/lib/python3.6/site-packages/azureml/core/run.py", line 461, in upload_file
    return self._client.upload_file(name, path_or_stream)
  File "/home/ninghai/miniconda3/envs/rc/lib/python3.6/site-packages/azureml/_run_impl/artifacts_client.py", line 46, in upload_file
    res = self.batch_create_empty_artifacts(batch_create)
  File "/home/ninghai/miniconda3/envs/rc/lib/python3.6/site-packages/azureml/_run_impl/run_client.py", line 230, in batch_create_empty_artifacts
    batch_create)
  File "/home/ninghai/miniconda3/envs/rc/lib/python3.6/site-packages/azureml/_run_impl/run_client.py", line 136, in call_workspace_client
    *args, **kwargs)
  File "/home/ninghai/miniconda3/envs/rc/lib/python3.6/site-packages/azureml/restclient/operations/artifact_operations.py", line 787, in batch_create_empty_artifacts
    request, header_parameters, body_content, stream=False, **operation_config)
  File "/home/ninghai/miniconda3/envs/rc/lib/python3.6/site-packages/msrest/service_client.py", line 290, in send
    raise_with_traceback(ClientRequestError, msg, err)
  File "/home/ninghai/miniconda3/envs/rc/lib/python3.6/site-packages/msrest/exceptions.py", line 45, in raise_with_traceback
    raise error.with_traceback(exc_traceback)
  File "/home/ninghai/miniconda3/envs/rc/lib/python3.6/site-packages/msrest/service_client.py", line 257, in send
    **kwargs)
  File "/home/ninghai/miniconda3/envs/rc/lib/python3.6/site-packages/requests/sessions.py", line 508, in request
    resp = self.send(prep, **send_kwargs)
  File "/home/ninghai/miniconda3/envs/rc/lib/python3.6/site-packages/requests/sessions.py", line 618, in send
    r = adapter.send(request, **kwargs)
  File "/home/ninghai/miniconda3/envs/rc/lib/python3.6/site-packages/requests/adapters.py", line 499, in send
    raise RetryError(e, request=request)
msrest.exceptions.ClientRequestError: Error occurred in request., RetryError: HTTPSConnectionPool(host='eastus2euap.experiments.azureml.net', port=443): Max retries exceeded with url: /artifact/v1.0/subscriptions/fac34303-435d-4486-8c3f-7094d82a0b60/resourceGroups/aml-notebooks/providers/Microsoft.MachineLearningServices/workspaces/haieastus2euapws/artifacts/batch/metadata/ExperimentRun/1b6d5e57-7b46-42bd-84b9-ff799dca335e (Caused by ResponseError('too many 500 error responses',))

During handling of the above exception, another exception occurred:

Traceback (most recent call last):
  File "/home/ninghai/miniconda3/envs/rc/lib/python3.6/site-packages/requests/adapters.py", line 440, in send
    timeout=timeout
  File "/home/ninghai/miniconda3/envs/rc/lib/python3.6/site-packages/urllib3/connectionpool.py", line 732, in urlopen
    body_pos=body_pos, **response_kw)
  File "/home/ninghai/miniconda3/envs/rc/lib/python3.6/site-packages/urllib3/connectionpool.py", line 732, in urlopen
    body_pos=body_pos, **response_kw)
  File "/home/ninghai/miniconda3/envs/rc/lib/python3.6/site-packages/urllib3/connectionpool.py", line 732, in urlopen
    body_pos=body_pos, **response_kw)
  File "/home/ninghai/miniconda3/envs/rc/lib/python3.6/site-packages/urllib3/connectionpool.py", line 712, in urlopen
    retries = retries.increment(method, url, response=response, _pool=self)
  File "/home/ninghai/miniconda3/envs/rc/lib/python3.6/site-packages/urllib3/util/retry.py", line 388, in increment
    raise MaxRetryError(_pool, url, error or ResponseError(cause))
urllib3.exceptions.MaxRetryError: HTTPSConnectionPool(host='eastus2euap.experiments.azureml.net', port=443): Max retries exceeded with url: /history/v1.0/subscriptions/fac34303-435d-4486-8c3f-7094d82a0b60/resourceGroups/aml-notebooks/providers/Microsoft.MachineLearningServices/workspaces/haieastus2euapws/projects/e2e-01/runs/1b6d5e57-7b46-42bd-84b9-ff799dca335e/events (Caused by ResponseError('too many 504 error responses',))

During handling of the above exception, another exception occurred:

Traceback (most recent call last):
  File "/home/ninghai/miniconda3/envs/rc/lib/python3.6/site-packages/msrest/service_client.py", line 257, in send
    **kwargs)
  File "/home/ninghai/miniconda3/envs/rc/lib/python3.6/site-packages/requests/sessions.py", line 508, in request
    resp = self.send(prep, **send_kwargs)
  File "/home/ninghai/miniconda3/envs/rc/lib/python3.6/site-packages/requests/sessions.py", line 618, in send
    r = adapter.send(request, **kwargs)
  File "/home/ninghai/miniconda3/envs/rc/lib/python3.6/site-packages/requests/adapters.py", line 499, in send
    raise RetryError(e, request=request)
requests.exceptions.RetryError: HTTPSConnectionPool(host='eastus2euap.experiments.azureml.net', port=443): Max retries exceeded with url: /history/v1.0/subscriptions/fac34303-435d-4486-8c3f-7094d82a0b60/resourceGroups/aml-notebooks/providers/Microsoft.MachineLearningServices/workspaces/haieastus2euapws/projects/e2e-01/runs/1b6d5e57-7b46-42bd-84b9-ff799dca335e/events (Caused by ResponseError('too many 504 error responses',))

During handling of the above exception, another exception occurred:

Traceback (most recent call last):
  File "./01.interactive.e2e.py", line 78, in <module>
    os.remove(model_file_name)
  File "/home/ninghai/miniconda3/envs/rc/lib/python3.6/site-packages/azureml/core/run.py", line 383, in __exit__
    self.fail()
  File "/home/ninghai/miniconda3/envs/rc/lib/python3.6/site-packages/azureml/core/run.py", line 374, in fail
    self._client.fail()
  File "/home/ninghai/miniconda3/envs/rc/lib/python3.6/site-packages/azureml/_run_impl/scope_client.py", line 61, in fail
    self._client.post_event_run_failed(self.get_run_id())
  File "/home/ninghai/miniconda3/envs/rc/lib/python3.6/site-packages/azureml/restclient/run_history_client.py", line 72, in post_event_run_failed
    return self.post_event(run_id, event)
  File "/home/ninghai/miniconda3/envs/rc/lib/python3.6/site-packages/azureml/restclient/run_history_client.py", line 64, in post_event
    event_message=event)
  File "/home/ninghai/miniconda3/envs/rc/lib/python3.6/site-packages/azureml/restclient/project_client.py", line 58, in _execute_with_project_arguments
    **kwargs_copy)
  File "/home/ninghai/miniconda3/envs/rc/lib/python3.6/site-packages/azureml/restclient/clientbase.py", line 101, in _execute_with_base_arguments
    return func(*args, **kwargs)
  File "/home/ninghai/miniconda3/envs/rc/lib/python3.6/site-packages/azureml/restclient/operations/events_operations.py", line 182, in post
    request, header_parameters, body_content, stream=False, **operation_config)
  File "/home/ninghai/miniconda3/envs/rc/lib/python3.6/site-packages/msrest/service_client.py", line 290, in send
    raise_with_traceback(ClientRequestError, msg, err)
  File "/home/ninghai/miniconda3/envs/rc/lib/python3.6/site-packages/msrest/exceptions.py", line 45, in raise_with_traceback
    raise error.with_traceback(exc_traceback)
  File "/home/ninghai/miniconda3/envs/rc/lib/python3.6/site-packages/msrest/service_client.py", line 257, in send
    **kwargs)
  File "/home/ninghai/miniconda3/envs/rc/lib/python3.6/site-packages/requests/sessions.py", line 508, in request
    resp = self.send(prep, **send_kwargs)
  File "/home/ninghai/miniconda3/envs/rc/lib/python3.6/site-packages/requests/sessions.py", line 618, in send
    r = adapter.send(request, **kwargs)
  File "/home/ninghai/miniconda3/envs/rc/lib/python3.6/site-packages/requests/adapters.py", line 499, in send
    raise RetryError(e, request=request)
msrest.exceptions.ClientRequestError: Error occurred in request., RetryError: HTTPSConnectionPool(host='eastus2euap.experiments.azureml.net', port=443): Max retries exceeded with url: /history/v1.0/subscriptions/fac34303-435d-4486-8c3f-7094d82a0b60/resourceGroups/aml-notebooks/providers/Microsoft.MachineLearningServices/workspaces/haieastus2euapws/projects/e2e-01/runs/1b6d5e57-7b46-42bd-84b9-ff799dca335e/events (Caused by ResponseError('too many 504 error responses',))
Traceback (most recent call last):
  File "/home/ninghai/miniconda3/envs/rc/lib/python3.6/site-packages/requests/adapters.py", line 440, in send
    timeout=timeout
  File "/home/ninghai/miniconda3/envs/rc/lib/python3.6/site-packages/urllib3/connectionpool.py", line 732, in urlopen
    body_pos=body_pos, **response_kw)
  File "/home/ninghai/miniconda3/envs/rc/lib/python3.6/site-packages/urllib3/connectionpool.py", line 732, in urlopen
    body_pos=body_pos, **response_kw)
  File "/home/ninghai/miniconda3/envs/rc/lib/python3.6/site-packages/urllib3/connectionpool.py", line 732, in urlopen
    body_pos=body_pos, **response_kw)
  File "/home/ninghai/miniconda3/envs/rc/lib/python3.6/site-packages/urllib3/connectionpool.py", line 712, in urlopen
    retries = retries.increment(method, url, response=response, _pool=self)
  File "/home/ninghai/miniconda3/envs/rc/lib/python3.6/site-packages/urllib3/util/retry.py", line 388, in increment
    raise MaxRetryError(_pool, url, error or ResponseError(cause))
urllib3.exceptions.MaxRetryError: HTTPSConnectionPool(host='eastus2euap.experiments.azureml.net', port=443): Max retries exceeded with url: /project/v1.0/subscriptions/fac34303-435d-4486-8c3f-7094d82a0b60/resourceGroups/aml-notebooks/providers/Microsoft.MachineLearningServices/workspaces/haieastus2euapws/projects/e2e-02?api-version=2018-03-01-preview (Caused by ResponseError('too many 500 error responses',))

During handling of the above exception, another exception occurred:

Traceback (most recent call last):
  File "/home/ninghai/miniconda3/envs/rc/lib/python3.6/site-packages/msrest/service_client.py", line 257, in send
    **kwargs)
  File "/home/ninghai/miniconda3/envs/rc/lib/python3.6/site-packages/requests/sessions.py", line 508, in request
    resp = self.send(prep, **send_kwargs)
  File "/home/ninghai/miniconda3/envs/rc/lib/python3.6/site-packages/requests/sessions.py", line 618, in send
    r = adapter.send(request, **kwargs)
  File "/home/ninghai/miniconda3/envs/rc/lib/python3.6/site-packages/requests/adapters.py", line 499, in send
    raise RetryError(e, request=request)
requests.exceptions.RetryError: HTTPSConnectionPool(host='eastus2euap.experiments.azureml.net', port=443): Max retries exceeded with url: /project/v1.0/subscriptions/fac34303-435d-4486-8c3f-7094d82a0b60/resourceGroups/aml-notebooks/providers/Microsoft.MachineLearningServices/workspaces/haieastus2euapws/projects/e2e-02?api-version=2018-03-01-preview (Caused by ResponseError('too many 500 error responses',))

During handling of the above exception, another exception occurred:

Traceback (most recent call last):
  File "./02.local.py", line 30, in <module>
    directory = project_folder)
  File "/home/ninghai/miniconda3/envs/rc/lib/python3.6/site-packages/azureml/core/project.py", line 150, in attach
    workspace_object.subscription_id, project_path=directory, location=_location)
  File "/home/ninghai/miniconda3/envs/rc/lib/python3.6/site-packages/azureml/project/_commands.py", line 155, in attach_project
    workspace_service_object)
  File "/home/ninghai/miniconda3/envs/rc/lib/python3.6/site-packages/azureml/project/_commands.py", line 242, in _get_or_create_project
    workspace_name, cloud_project_name)
  File "/home/ninghai/miniconda3/envs/rc/lib/python3.6/site-packages/azureml/base_sdk_common/project/project_service.py", line 109, in get_project
    response = self._client.send(request, header_parameters, stream=False, **operation_config)
  File "/home/ninghai/miniconda3/envs/rc/lib/python3.6/site-packages/msrest/service_client.py", line 290, in send
    raise_with_traceback(ClientRequestError, msg, err)
  File "/home/ninghai/miniconda3/envs/rc/lib/python3.6/site-packages/msrest/exceptions.py", line 45, in raise_with_traceback
    raise error.with_traceback(exc_traceback)
  File "/home/ninghai/miniconda3/envs/rc/lib/python3.6/site-packages/msrest/service_client.py", line 257, in send
    **kwargs)
  File "/home/ninghai/miniconda3/envs/rc/lib/python3.6/site-packages/requests/sessions.py", line 508, in request
    resp = self.send(prep, **send_kwargs)
  File "/home/ninghai/miniconda3/envs/rc/lib/python3.6/site-packages/requests/sessions.py", line 618, in send
    r = adapter.send(request, **kwargs)
  File "/home/ninghai/miniconda3/envs/rc/lib/python3.6/site-packages/requests/adapters.py", line 499, in send
    raise RetryError(e, request=request)
msrest.exceptions.ClientRequestError: Error occurred in request., RetryError: HTTPSConnectionPool(host='eastus2euap.experiments.azureml.net', port=443): Max retries exceeded with url: /project/v1.0/subscriptions/fac34303-435d-4486-8c3f-7094d82a0b60/resourceGroups/aml-notebooks/providers/Microsoft.MachineLearningServices/workspaces/haieastus2euapws/projects/e2e-02?api-version=2018-03-01-preview (Caused by ResponseError('too many 500 error responses',))
Traceback (most recent call last):
  File "/home/ninghai/miniconda3/envs/rc/lib/python3.6/site-packages/requests/adapters.py", line 440, in send
    timeout=timeout
  File "/home/ninghai/miniconda3/envs/rc/lib/python3.6/site-packages/urllib3/connectionpool.py", line 732, in urlopen
    body_pos=body_pos, **response_kw)
  File "/home/ninghai/miniconda3/envs/rc/lib/python3.6/site-packages/urllib3/connectionpool.py", line 732, in urlopen
    body_pos=body_pos, **response_kw)
  File "/home/ninghai/miniconda3/envs/rc/lib/python3.6/site-packages/urllib3/connectionpool.py", line 732, in urlopen
    body_pos=body_pos, **response_kw)
  File "/home/ninghai/miniconda3/envs/rc/lib/python3.6/site-packages/urllib3/connectionpool.py", line 712, in urlopen
    retries = retries.increment(method, url, response=response, _pool=self)
  File "/home/ninghai/miniconda3/envs/rc/lib/python3.6/site-packages/urllib3/util/retry.py", line 388, in increment
    raise MaxRetryError(_pool, url, error or ResponseError(cause))
urllib3.exceptions.MaxRetryError: HTTPSConnectionPool(host='eastus2euap.experiments.azureml.net', port=443): Max retries exceeded with url: /history/v1.0/subscriptions/fac34303-435d-4486-8c3f-7094d82a0b60/resourceGroups/aml-notebooks/providers/Microsoft.MachineLearningServices/workspaces/haieastus2euapws/projects/e2e-03/runs/e2e-03_1527668529312/runstatus (Caused by ResponseError('too many 500 error responses',))

During handling of the above exception, another exception occurred:

Traceback (most recent call last):
  File "./03.aci.py", line 90, in <module>
    run.wait_for_completion(show_output = True)
  File "/home/ninghai/miniconda3/envs/rc/lib/python3.6/site-packages/azureml/core/experiment_run.py", line 69, in wait_for_completion
    self._stream_run_output(file_handle=sys.stdout, wait_post_processing=wait_post_processing)
  File "/home/ninghai/miniconda3/envs/rc/lib/python3.6/site-packages/azureml/core/experiment_run.py", line 201, in _stream_run_output
    self._current_status = self.get_status()
  File "/home/ninghai/miniconda3/envs/rc/lib/python3.6/site-packages/azureml/core/experiment_run.py", line 136, in get_status
    return self._get_run_status_with_retry(3)
  File "/home/ninghai/miniconda3/envs/rc/lib/python3.6/site-packages/azureml/core/experiment_run.py", line 158, in _get_run_status_with_retry
    return _commands.run_status(self._project_object, self._run_config_object, self._run_id)
  File "/home/ninghai/miniconda3/envs/rc/lib/python3.6/site-packages/azureml/execution/_commands.py", line 537, in run_status
    return _get_status_from_history(project_object, run_id, project_context)
  File "/home/ninghai/miniconda3/envs/rc/lib/python3.6/site-packages/azureml/execution/_commands.py", line 791, in _get_status_from_history
    response = session.get(runstatus_uri, headers=headers)
  File "/home/ninghai/miniconda3/envs/rc/lib/python3.6/site-packages/requests/sessions.py", line 521, in get
    return self.request('GET', url, **kwargs)
  File "/home/ninghai/miniconda3/envs/rc/lib/python3.6/site-packages/requests/sessions.py", line 508, in request
    resp = self.send(prep, **send_kwargs)
  File "/home/ninghai/miniconda3/envs/rc/lib/python3.6/site-packages/requests/sessions.py", line 618, in send
    r = adapter.send(request, **kwargs)
  File "/home/ninghai/miniconda3/envs/rc/lib/python3.6/site-packages/requests/adapters.py", line 499, in send
    raise RetryError(e, request=request)
requests.exceptions.RetryError: HTTPSConnectionPool(host='eastus2euap.experiments.azureml.net', port=443): Max retries exceeded with url: /history/v1.0/subscriptions/fac34303-435d-4486-8c3f-7094d82a0b60/resourceGroups/aml-notebooks/providers/Microsoft.MachineLearningServices/workspaces/haieastus2euapws/projects/e2e-03/runs/e2e-03_1527668529312/runstatus (Caused by ResponseError('too many 500 error responses',))
