Already on 'master'
ERROR:azure.storage.common.storageclient:Client-Request-ID=b11f60e4-77a6-11e8-9288-000d3a71b7c3 Retry policy did not allow for a retry: Server-Timestamp=Sun, 24 Jun 2018 12:04:05 GMT, Server-Request-ID=34c63581-501e-00e9-26b3-0ba762000000, HTTP status code=409, Exception=The specified container already exists.ErrorCode: ContainerAlreadyExists<?xml version="1.0" encoding="utf-8"?><Error><Code>ContainerAlreadyExists</Code><Message>The specified container already exists.RequestId:34c63581-501e-00e9-26b3-0ba762000000Time:2018-06-24T12:04:05.5832904Z</Message></Error>.
ERROR:azure.storage.common.storageclient:Client-Request-ID=b11f60e6-77a6-11e8-9288-000d3a71b7c3 Retry policy did not allow for a retry: Server-Timestamp=Sun, 24 Jun 2018 12:04:05 GMT, Server-Request-ID=1b0bd942-801e-0086-6db3-0b0fb6000000, HTTP status code=409, Exception=The specified container already exists.ErrorCode: ContainerAlreadyExists<?xml version="1.0" encoding="utf-8"?><Error><Code>ContainerAlreadyExists</Code><Message>The specified container already exists.RequestId:1b0bd942-801e-0086-6db3-0b0fb6000000Time:2018-06-24T12:04:05.7733513Z</Message></Error>.
ERROR:azure.storage.common.storageclient:Client-Request-ID=b11f60e8-77a6-11e8-9288-000d3a71b7c3 Retry policy did not allow for a retry: Server-Timestamp=Sun, 24 Jun 2018 12:04:05 GMT, Server-Request-ID=bb5c4574-601e-000f-21b3-0bb692000000, HTTP status code=409, Exception=The specified container already exists.ErrorCode: ContainerAlreadyExists<?xml version="1.0" encoding="utf-8"?><Error><Code>ContainerAlreadyExists</Code><Message>The specified container already exists.RequestId:bb5c4574-601e-000f-21b3-0bb692000000Time:2018-06-24T12:04:05.9700221Z</Message></Error>.
ERROR:azure.storage.common.storageclient:Client-Request-ID=b11f60ea-77a6-11e8-9288-000d3a71b7c3 Retry policy did not allow for a retry: Server-Timestamp=Sun, 24 Jun 2018 12:04:05 GMT, Server-Request-ID=1a056376-901e-00b0-12b3-0ba2e4000000, HTTP status code=409, Exception=The specified container already exists.ErrorCode: ContainerAlreadyExists<?xml version="1.0" encoding="utf-8"?><Error><Code>ContainerAlreadyExists</Code><Message>The specified container already exists.RequestId:1a056376-901e-00b0-12b3-0ba2e4000000Time:2018-06-24T12:04:06.2059844Z</Message></Error>.
Traceback (most recent call last):
  File "./02.local.py", line 51, in <module>
    script_to_run = train_script)
  File "/home/ninghai/miniconda3/envs/preview/lib/python3.6/site-packages/azureml/core/run.py", line 64, in submit
    return _commands.start_run(project_object, run_config_object, telemetry_values=_telemetry_values)
  File "/home/ninghai/miniconda3/envs/preview/lib/python3.6/site-packages/azureml/execution/_commands.py", line 109, in start_run
    telemetry_values=telemetry_values)
  File "/home/ninghai/miniconda3/envs/preview/lib/python3.6/site-packages/azureml/execution/_commands.py", line 272, in _start_internal_local_cloud
    snapshot_id = snapshot_async.get() if snapshot_async else None
  File "/home/ninghai/miniconda3/envs/preview/lib/python3.6/multiprocessing/pool.py", line 644, in get
    raise self._value
  File "/home/ninghai/miniconda3/envs/preview/lib/python3.6/multiprocessing/pool.py", line 119, in worker
    result = (True, func(*args, **kwds))
  File "/home/ninghai/miniconda3/envs/preview/lib/python3.6/site-packages/azureml/base_sdk_common/create_snapshot.py", line 129, in create_snapshot
    raise SnapshotException(get_http_exception_response_string(response))
azureml.exceptions.azureml_exception.SnapshotException: {
    "status_code": 404,
    "text": {
        "correlation": {
            "operation": "e87db379-4dafe5d5581f0658",
            "request": "f5X5dOOmBpc="
        },
        "error": {
            "code": "UserError",
            "debugInfo": {
                "data": {},
                "errorResponse": null,
                "innerException": null,
                "message": "Unable to find snapshot with id: 2bd3167f-0978-42bd-9795-6c89fc1e31b2",
                "stackTrace": "   at Microsoft.MachineLearning.Project.Services.SnapshotStore.<GetBlobAsStringOrFailNotFound>d__17.MoveNext() in /opt/vsts/work/1/s/src/azureml-api/src/ProjectContent/Services/SnapshotStore.cs:line 271\n--- End of stack trace from previous location where exception was thrown ---\n   at System.Runtime.ExceptionServices.ExceptionDispatchInfo.Throw()\n   at System.Runtime.CompilerServices.TaskAwaiter.HandleNonSuccessAndDebuggerNotification(Task task)\n   at Microsoft.MachineLearning.Project.Services.SnapshotStore.<GetSnapshot>d__7.MoveNext() in /opt/vsts/work/1/s/src/azureml-api/src/ProjectContent/Services/SnapshotStore.cs:line 113\n--- End of stack trace from previous location where exception was thrown ---\n   at System.Runtime.ExceptionServices.ExceptionDispatchInfo.Throw()\n   at System.Runtime.CompilerServices.TaskAwaiter.HandleNonSuccessAndDebuggerNotification(Task task)\n   at Microsoft.MachineLearning.ProjectContent.EntryPoints.Controllers.SnapshotController.<CreateSnapshot>d__12.MoveNext() in /opt/vsts/work/1/s/src/azureml-api/src/ProjectContent/EntryPoints/Controllers/SnapshotController.cs:line 212\n--- End of stack trace from previous location where exception was thrown ---\n   at System.Runtime.ExceptionServices.ExceptionDispatchInfo.Throw()\n   at System.Runtime.CompilerServices.TaskAwaiter.HandleNonSuccessAndDebuggerNotification(Task task)\n   at Microsoft.AspNetCore.Mvc.Internal.ControllerActionInvoker.<InvokeActionMethodAsync>d__12.MoveNext()\n--- End of stack trace from previous location where exception was thrown ---\n   at System.Runtime.ExceptionServices.ExceptionDispatchInfo.Throw()\n   at System.Runtime.CompilerServices.TaskAwaiter.HandleNonSuccessAndDebuggerNotification(Task task)\n   at Microsoft.AspNetCore.Mvc.Internal.ControllerActionInvoker.<InvokeNextActionFilterAsync>d__10.MoveNext()\n--- End of stack trace from previous location where exception was thrown ---\n   at System.Runtime.ExceptionServices.ExceptionDispatchInfo.Throw()\n   at Microsoft.AspNetCore.Mvc.Internal.ControllerActionInvoker.Rethrow(ActionExecutedContext context)\n   at Microsoft.AspNetCore.Mvc.Internal.ControllerActionInvoker.Next(State& next, Scope& scope, Object& state, Boolean& isCompleted)\n   at Microsoft.AspNetCore.Mvc.Internal.ControllerActionInvoker.<InvokeInnerFilterAsync>d__14.MoveNext()\n--- End of stack trace from previous location where exception was thrown ---\n   at System.Runtime.ExceptionServices.ExceptionDispatchInfo.Throw()\n   at System.Runtime.CompilerServices.TaskAwaiter.HandleNonSuccessAndDebuggerNotification(Task task)\n   at Microsoft.AspNetCore.Mvc.Internal.ResourceInvoker.<InvokeNextExceptionFilterAsync>d__23.MoveNext()",
                "type": "Common.WebApi.Exceptions.ResourceNotFoundException"
            },
            "details": [],
            "innerError": null,
            "message": "Unable to find snapshot with id: 2bd3167f-0978-42bd-9795-6c89fc1e31b2",
            "target": null
        }
    },
    "url": "https://eastus2.experiments.azureml.net/content/v1.0/subscriptions/fac34303-435d-4486-8c3f-7094d82a0b60/resourceGroups/aml-notebooks/providers/Microsoft.MachineLearningServices/workspaces/haieastus2ws3/snapshots/e8ee6610-1a06-4e50-a293-83efc7f3850a?parentSnapshotId=2bd3167f-0978-42bd-9795-6c89fc1e31b2"
}
Traceback (most recent call last):
  File "./03.aci.py", line 85, in <module>
    script_to_run = train_script)
  File "/home/ninghai/miniconda3/envs/preview/lib/python3.6/site-packages/azureml/core/run.py", line 64, in submit
    return _commands.start_run(project_object, run_config_object, telemetry_values=_telemetry_values)
  File "/home/ninghai/miniconda3/envs/preview/lib/python3.6/site-packages/azureml/execution/_commands.py", line 114, in start_run
    telemetry_values=telemetry_values)
  File "/home/ninghai/miniconda3/envs/preview/lib/python3.6/site-packages/azureml/execution/_commands.py", line 381, in _start_internal
    snapshot_id = snapshot_async.get() if snapshot_async else None
  File "/home/ninghai/miniconda3/envs/preview/lib/python3.6/multiprocessing/pool.py", line 644, in get
    raise self._value
  File "/home/ninghai/miniconda3/envs/preview/lib/python3.6/multiprocessing/pool.py", line 119, in worker
    result = (True, func(*args, **kwds))
  File "/home/ninghai/miniconda3/envs/preview/lib/python3.6/site-packages/azureml/base_sdk_common/create_snapshot.py", line 129, in create_snapshot
    raise SnapshotException(get_http_exception_response_string(response))
azureml.exceptions.azureml_exception.SnapshotException: {
    "status_code": 404,
    "text": {
        "correlation": {
            "operation": "70ec6f5c-4fa154d2e7b3b1f2",
            "request": "AtyyaDyt19k="
        },
        "error": {
            "code": "UserError",
            "debugInfo": {
                "data": {},
                "errorResponse": null,
                "innerException": null,
                "message": "Unable to find snapshot with id: b8317c26-6671-44a6-9859-67a0a7be6afa",
                "stackTrace": "   at Microsoft.MachineLearning.Project.Services.SnapshotStore.<GetBlobAsStringOrFailNotFound>d__17.MoveNext() in /opt/vsts/work/1/s/src/azureml-api/src/ProjectContent/Services/SnapshotStore.cs:line 271\n--- End of stack trace from previous location where exception was thrown ---\n   at System.Runtime.ExceptionServices.ExceptionDispatchInfo.Throw()\n   at System.Runtime.CompilerServices.TaskAwaiter.HandleNonSuccessAndDebuggerNotification(Task task)\n   at Microsoft.MachineLearning.Project.Services.SnapshotStore.<GetSnapshot>d__7.MoveNext() in /opt/vsts/work/1/s/src/azureml-api/src/ProjectContent/Services/SnapshotStore.cs:line 113\n--- End of stack trace from previous location where exception was thrown ---\n   at System.Runtime.ExceptionServices.ExceptionDispatchInfo.Throw()\n   at System.Runtime.CompilerServices.TaskAwaiter.HandleNonSuccessAndDebuggerNotification(Task task)\n   at Microsoft.MachineLearning.ProjectContent.EntryPoints.Controllers.SnapshotController.<CreateSnapshot>d__12.MoveNext() in /opt/vsts/work/1/s/src/azureml-api/src/ProjectContent/EntryPoints/Controllers/SnapshotController.cs:line 212\n--- End of stack trace from previous location where exception was thrown ---\n   at System.Runtime.ExceptionServices.ExceptionDispatchInfo.Throw()\n   at System.Runtime.CompilerServices.TaskAwaiter.HandleNonSuccessAndDebuggerNotification(Task task)\n   at Microsoft.AspNetCore.Mvc.Internal.ControllerActionInvoker.<InvokeActionMethodAsync>d__12.MoveNext()\n--- End of stack trace from previous location where exception was thrown ---\n   at System.Runtime.ExceptionServices.ExceptionDispatchInfo.Throw()\n   at System.Runtime.CompilerServices.TaskAwaiter.HandleNonSuccessAndDebuggerNotification(Task task)\n   at Microsoft.AspNetCore.Mvc.Internal.ControllerActionInvoker.<InvokeNextActionFilterAsync>d__10.MoveNext()\n--- End of stack trace from previous location where exception was thrown ---\n   at System.Runtime.ExceptionServices.ExceptionDispatchInfo.Throw()\n   at Microsoft.AspNetCore.Mvc.Internal.ControllerActionInvoker.Rethrow(ActionExecutedContext context)\n   at Microsoft.AspNetCore.Mvc.Internal.ControllerActionInvoker.Next(State& next, Scope& scope, Object& state, Boolean& isCompleted)\n   at Microsoft.AspNetCore.Mvc.Internal.ControllerActionInvoker.<InvokeInnerFilterAsync>d__14.MoveNext()\n--- End of stack trace from previous location where exception was thrown ---\n   at System.Runtime.ExceptionServices.ExceptionDispatchInfo.Throw()\n   at System.Runtime.CompilerServices.TaskAwaiter.HandleNonSuccessAndDebuggerNotification(Task task)\n   at Microsoft.AspNetCore.Mvc.Internal.ResourceInvoker.<InvokeNextExceptionFilterAsync>d__23.MoveNext()",
                "type": "Common.WebApi.Exceptions.ResourceNotFoundException"
            },
            "details": [],
            "innerError": null,
            "message": "Unable to find snapshot with id: b8317c26-6671-44a6-9859-67a0a7be6afa",
            "target": null
        }
    },
    "url": "https://eastus2.experiments.azureml.net/content/v1.0/subscriptions/fac34303-435d-4486-8c3f-7094d82a0b60/resourceGroups/aml-notebooks/providers/Microsoft.MachineLearningServices/workspaces/haieastus2ws3/snapshots/df967d63-6bee-44a6-bf88-d6a8066bb5ed?parentSnapshotId=b8317c26-6671-44a6-9859-67a0a7be6afa"
}
Traceback (most recent call last):
  File "./04.dsvm.py", line 71, in <module>
    script_to_run = train_script)
  File "/home/ninghai/miniconda3/envs/preview/lib/python3.6/site-packages/azureml/core/run.py", line 64, in submit
    return _commands.start_run(project_object, run_config_object, telemetry_values=_telemetry_values)
  File "/home/ninghai/miniconda3/envs/preview/lib/python3.6/site-packages/azureml/execution/_commands.py", line 114, in start_run
    telemetry_values=telemetry_values)
  File "/home/ninghai/miniconda3/envs/preview/lib/python3.6/site-packages/azureml/execution/_commands.py", line 381, in _start_internal
    snapshot_id = snapshot_async.get() if snapshot_async else None
  File "/home/ninghai/miniconda3/envs/preview/lib/python3.6/multiprocessing/pool.py", line 644, in get
    raise self._value
  File "/home/ninghai/miniconda3/envs/preview/lib/python3.6/multiprocessing/pool.py", line 119, in worker
    result = (True, func(*args, **kwds))
  File "/home/ninghai/miniconda3/envs/preview/lib/python3.6/site-packages/azureml/base_sdk_common/create_snapshot.py", line 129, in create_snapshot
    raise SnapshotException(get_http_exception_response_string(response))
azureml.exceptions.azureml_exception.SnapshotException: {
    "status_code": 404,
    "text": {
        "correlation": {
            "operation": "a387316f-475176cfac6b28be",
            "request": "M/6dOAOjTTA="
        },
        "error": {
            "code": "UserError",
            "debugInfo": {
                "data": {},
                "errorResponse": null,
                "innerException": null,
                "message": "Unable to find snapshot with id: 4eb7d8fa-4b2e-4c7c-99cc-37dd5695023d",
                "stackTrace": "   at Microsoft.MachineLearning.Project.Services.SnapshotStore.<GetBlobAsStringOrFailNotFound>d__17.MoveNext() in /opt/vsts/work/1/s/src/azureml-api/src/ProjectContent/Services/SnapshotStore.cs:line 271\n--- End of stack trace from previous location where exception was thrown ---\n   at System.Runtime.ExceptionServices.ExceptionDispatchInfo.Throw()\n   at System.Runtime.CompilerServices.TaskAwaiter.HandleNonSuccessAndDebuggerNotification(Task task)\n   at Microsoft.MachineLearning.Project.Services.SnapshotStore.<GetSnapshot>d__7.MoveNext() in /opt/vsts/work/1/s/src/azureml-api/src/ProjectContent/Services/SnapshotStore.cs:line 113\n--- End of stack trace from previous location where exception was thrown ---\n   at System.Runtime.ExceptionServices.ExceptionDispatchInfo.Throw()\n   at System.Runtime.CompilerServices.TaskAwaiter.HandleNonSuccessAndDebuggerNotification(Task task)\n   at Microsoft.MachineLearning.ProjectContent.EntryPoints.Controllers.SnapshotController.<CreateSnapshot>d__12.MoveNext() in /opt/vsts/work/1/s/src/azureml-api/src/ProjectContent/EntryPoints/Controllers/SnapshotController.cs:line 212\n--- End of stack trace from previous location where exception was thrown ---\n   at System.Runtime.ExceptionServices.ExceptionDispatchInfo.Throw()\n   at System.Runtime.CompilerServices.TaskAwaiter.HandleNonSuccessAndDebuggerNotification(Task task)\n   at Microsoft.AspNetCore.Mvc.Internal.ControllerActionInvoker.<InvokeActionMethodAsync>d__12.MoveNext()\n--- End of stack trace from previous location where exception was thrown ---\n   at System.Runtime.ExceptionServices.ExceptionDispatchInfo.Throw()\n   at System.Runtime.CompilerServices.TaskAwaiter.HandleNonSuccessAndDebuggerNotification(Task task)\n   at Microsoft.AspNetCore.Mvc.Internal.ControllerActionInvoker.<InvokeNextActionFilterAsync>d__10.MoveNext()\n--- End of stack trace from previous location where exception was thrown ---\n   at System.Runtime.ExceptionServices.ExceptionDispatchInfo.Throw()\n   at Microsoft.AspNetCore.Mvc.Internal.ControllerActionInvoker.Rethrow(ActionExecutedContext context)\n   at Microsoft.AspNetCore.Mvc.Internal.ControllerActionInvoker.Next(State& next, Scope& scope, Object& state, Boolean& isCompleted)\n   at Microsoft.AspNetCore.Mvc.Internal.ControllerActionInvoker.<InvokeInnerFilterAsync>d__14.MoveNext()\n--- End of stack trace from previous location where exception was thrown ---\n   at System.Runtime.ExceptionServices.ExceptionDispatchInfo.Throw()\n   at System.Runtime.CompilerServices.TaskAwaiter.HandleNonSuccessAndDebuggerNotification(Task task)\n   at Microsoft.AspNetCore.Mvc.Internal.ResourceInvoker.<InvokeNextExceptionFilterAsync>d__23.MoveNext()",
                "type": "Common.WebApi.Exceptions.ResourceNotFoundException"
            },
            "details": [],
            "innerError": null,
            "message": "Unable to find snapshot with id: 4eb7d8fa-4b2e-4c7c-99cc-37dd5695023d",
            "target": null
        }
    },
    "url": "https://eastus2.experiments.azureml.net/content/v1.0/subscriptions/fac34303-435d-4486-8c3f-7094d82a0b60/resourceGroups/aml-notebooks/providers/Microsoft.MachineLearningServices/workspaces/haieastus2ws3/snapshots/de6c71b7-9e96-428c-9f24-6bef57aa90e8?parentSnapshotId=4eb7d8fa-4b2e-4c7c-99cc-37dd5695023d"
}
Traceback (most recent call last):
  File "./05.spark.py", line 81, in <module>
    script_to_run = "train-spark.py")
  File "/home/ninghai/miniconda3/envs/preview/lib/python3.6/site-packages/azureml/core/run.py", line 64, in submit
    return _commands.start_run(project_object, run_config_object, telemetry_values=_telemetry_values)
  File "/home/ninghai/miniconda3/envs/preview/lib/python3.6/site-packages/azureml/execution/_commands.py", line 114, in start_run
    telemetry_values=telemetry_values)
  File "/home/ninghai/miniconda3/envs/preview/lib/python3.6/site-packages/azureml/execution/_commands.py", line 381, in _start_internal
    snapshot_id = snapshot_async.get() if snapshot_async else None
  File "/home/ninghai/miniconda3/envs/preview/lib/python3.6/multiprocessing/pool.py", line 644, in get
    raise self._value
  File "/home/ninghai/miniconda3/envs/preview/lib/python3.6/multiprocessing/pool.py", line 119, in worker
    result = (True, func(*args, **kwds))
  File "/home/ninghai/miniconda3/envs/preview/lib/python3.6/site-packages/azureml/base_sdk_common/create_snapshot.py", line 129, in create_snapshot
    raise SnapshotException(get_http_exception_response_string(response))
azureml.exceptions.azureml_exception.SnapshotException: {
    "status_code": 404,
    "text": {
        "correlation": {
            "operation": "a3873170-475176cfac6b28be",
            "request": "Uayn8U6d+DA="
        },
        "error": {
            "code": "UserError",
            "debugInfo": {
                "data": {},
                "errorResponse": null,
                "innerException": null,
                "message": "Unable to find snapshot with id: e9c619a7-7486-4eb3-8e27-4efdb021ec32",
                "stackTrace": "   at Microsoft.MachineLearning.Project.Services.SnapshotStore.<GetBlobAsStringOrFailNotFound>d__17.MoveNext() in /opt/vsts/work/1/s/src/azureml-api/src/ProjectContent/Services/SnapshotStore.cs:line 271\n--- End of stack trace from previous location where exception was thrown ---\n   at System.Runtime.ExceptionServices.ExceptionDispatchInfo.Throw()\n   at System.Runtime.CompilerServices.TaskAwaiter.HandleNonSuccessAndDebuggerNotification(Task task)\n   at Microsoft.MachineLearning.Project.Services.SnapshotStore.<GetSnapshot>d__7.MoveNext() in /opt/vsts/work/1/s/src/azureml-api/src/ProjectContent/Services/SnapshotStore.cs:line 113\n--- End of stack trace from previous location where exception was thrown ---\n   at System.Runtime.ExceptionServices.ExceptionDispatchInfo.Throw()\n   at System.Runtime.CompilerServices.TaskAwaiter.HandleNonSuccessAndDebuggerNotification(Task task)\n   at Microsoft.MachineLearning.ProjectContent.EntryPoints.Controllers.SnapshotController.<CreateSnapshot>d__12.MoveNext() in /opt/vsts/work/1/s/src/azureml-api/src/ProjectContent/EntryPoints/Controllers/SnapshotController.cs:line 212\n--- End of stack trace from previous location where exception was thrown ---\n   at System.Runtime.ExceptionServices.ExceptionDispatchInfo.Throw()\n   at System.Runtime.CompilerServices.TaskAwaiter.HandleNonSuccessAndDebuggerNotification(Task task)\n   at Microsoft.AspNetCore.Mvc.Internal.ControllerActionInvoker.<InvokeActionMethodAsync>d__12.MoveNext()\n--- End of stack trace from previous location where exception was thrown ---\n   at System.Runtime.ExceptionServices.ExceptionDispatchInfo.Throw()\n   at System.Runtime.CompilerServices.TaskAwaiter.HandleNonSuccessAndDebuggerNotification(Task task)\n   at Microsoft.AspNetCore.Mvc.Internal.ControllerActionInvoker.<InvokeNextActionFilterAsync>d__10.MoveNext()\n--- End of stack trace from previous location where exception was thrown ---\n   at System.Runtime.ExceptionServices.ExceptionDispatchInfo.Throw()\n   at Microsoft.AspNetCore.Mvc.Internal.ControllerActionInvoker.Rethrow(ActionExecutedContext context)\n   at Microsoft.AspNetCore.Mvc.Internal.ControllerActionInvoker.Next(State& next, Scope& scope, Object& state, Boolean& isCompleted)\n   at Microsoft.AspNetCore.Mvc.Internal.ControllerActionInvoker.<InvokeInnerFilterAsync>d__14.MoveNext()\n--- End of stack trace from previous location where exception was thrown ---\n   at System.Runtime.ExceptionServices.ExceptionDispatchInfo.Throw()\n   at System.Runtime.CompilerServices.TaskAwaiter.HandleNonSuccessAndDebuggerNotification(Task task)\n   at Microsoft.AspNetCore.Mvc.Internal.ResourceInvoker.<InvokeNextExceptionFilterAsync>d__23.MoveNext()",
                "type": "Common.WebApi.Exceptions.ResourceNotFoundException"
            },
            "details": [],
            "innerError": null,
            "message": "Unable to find snapshot with id: e9c619a7-7486-4eb3-8e27-4efdb021ec32",
            "target": null
        }
    },
    "url": "https://eastus2.experiments.azureml.net/content/v1.0/subscriptions/fac34303-435d-4486-8c3f-7094d82a0b60/resourceGroups/aml-notebooks/providers/Microsoft.MachineLearningServices/workspaces/haieastus2ws3/snapshots/d4b8603b-e9fe-475d-9618-3aa8316743d1?parentSnapshotId=e9c619a7-7486-4eb3-8e27-4efdb021ec32"
}
Traceback (most recent call last):
  File "./07.sklearn.hd.py", line 88, in <module>
    run = sk_est.fit()
  File "/home/ninghai/miniconda3/envs/preview/lib/python3.6/site-packages/azureml/train/estimator.py", line 421, in fit
    return super(Estimator, self).fit()
  File "/home/ninghai/miniconda3/envs/preview/lib/python3.6/site-packages/azureml/train/estimator.py", line 78, in fit
    _telemetry_values=telemetry_values)
  File "/home/ninghai/miniconda3/envs/preview/lib/python3.6/site-packages/azureml/core/run.py", line 64, in submit
    return _commands.start_run(project_object, run_config_object, telemetry_values=_telemetry_values)
  File "/home/ninghai/miniconda3/envs/preview/lib/python3.6/site-packages/azureml/execution/_commands.py", line 114, in start_run
    telemetry_values=telemetry_values)
  File "/home/ninghai/miniconda3/envs/preview/lib/python3.6/site-packages/azureml/execution/_commands.py", line 381, in _start_internal
    snapshot_id = snapshot_async.get() if snapshot_async else None
  File "/home/ninghai/miniconda3/envs/preview/lib/python3.6/multiprocessing/pool.py", line 644, in get
    raise self._value
  File "/home/ninghai/miniconda3/envs/preview/lib/python3.6/multiprocessing/pool.py", line 119, in worker
    result = (True, func(*args, **kwds))
  File "/home/ninghai/miniconda3/envs/preview/lib/python3.6/site-packages/azureml/base_sdk_common/create_snapshot.py", line 129, in create_snapshot
    raise SnapshotException(get_http_exception_response_string(response))
azureml.exceptions.azureml_exception.SnapshotException: {
    "status_code": 404,
    "text": {
        "correlation": {
            "operation": "a3873172-475176cfac6b28be",
            "request": "MgHMamlZJkE="
        },
        "error": {
            "code": "UserError",
            "debugInfo": {
                "data": {},
                "errorResponse": null,
                "innerException": null,
                "message": "Unable to find snapshot with id: 87311c3d-6b5f-4da6-a9ad-6d027c1096bc",
                "stackTrace": "   at Microsoft.MachineLearning.Project.Services.SnapshotStore.<GetBlobAsStringOrFailNotFound>d__17.MoveNext() in /opt/vsts/work/1/s/src/azureml-api/src/ProjectContent/Services/SnapshotStore.cs:line 271\n--- End of stack trace from previous location where exception was thrown ---\n   at System.Runtime.ExceptionServices.ExceptionDispatchInfo.Throw()\n   at System.Runtime.CompilerServices.TaskAwaiter.HandleNonSuccessAndDebuggerNotification(Task task)\n   at Microsoft.MachineLearning.Project.Services.SnapshotStore.<GetSnapshot>d__7.MoveNext() in /opt/vsts/work/1/s/src/azureml-api/src/ProjectContent/Services/SnapshotStore.cs:line 113\n--- End of stack trace from previous location where exception was thrown ---\n   at System.Runtime.ExceptionServices.ExceptionDispatchInfo.Throw()\n   at System.Runtime.CompilerServices.TaskAwaiter.HandleNonSuccessAndDebuggerNotification(Task task)\n   at Microsoft.MachineLearning.ProjectContent.EntryPoints.Controllers.SnapshotController.<CreateSnapshot>d__12.MoveNext() in /opt/vsts/work/1/s/src/azureml-api/src/ProjectContent/EntryPoints/Controllers/SnapshotController.cs:line 212\n--- End of stack trace from previous location where exception was thrown ---\n   at System.Runtime.ExceptionServices.ExceptionDispatchInfo.Throw()\n   at System.Runtime.CompilerServices.TaskAwaiter.HandleNonSuccessAndDebuggerNotification(Task task)\n   at Microsoft.AspNetCore.Mvc.Internal.ControllerActionInvoker.<InvokeActionMethodAsync>d__12.MoveNext()\n--- End of stack trace from previous location where exception was thrown ---\n   at System.Runtime.ExceptionServices.ExceptionDispatchInfo.Throw()\n   at System.Runtime.CompilerServices.TaskAwaiter.HandleNonSuccessAndDebuggerNotification(Task task)\n   at Microsoft.AspNetCore.Mvc.Internal.ControllerActionInvoker.<InvokeNextActionFilterAsync>d__10.MoveNext()\n--- End of stack trace from previous location where exception was thrown ---\n   at System.Runtime.ExceptionServices.ExceptionDispatchInfo.Throw()\n   at Microsoft.AspNetCore.Mvc.Internal.ControllerActionInvoker.Rethrow(ActionExecutedContext context)\n   at Microsoft.AspNetCore.Mvc.Internal.ControllerActionInvoker.Next(State& next, Scope& scope, Object& state, Boolean& isCompleted)\n   at Microsoft.AspNetCore.Mvc.Internal.ControllerActionInvoker.<InvokeInnerFilterAsync>d__14.MoveNext()\n--- End of stack trace from previous location where exception was thrown ---\n   at System.Runtime.ExceptionServices.ExceptionDispatchInfo.Throw()\n   at System.Runtime.CompilerServices.TaskAwaiter.HandleNonSuccessAndDebuggerNotification(Task task)\n   at Microsoft.AspNetCore.Mvc.Internal.ResourceInvoker.<InvokeNextExceptionFilterAsync>d__23.MoveNext()",
                "type": "Common.WebApi.Exceptions.ResourceNotFoundException"
            },
            "details": [],
            "innerError": null,
            "message": "Unable to find snapshot with id: 87311c3d-6b5f-4da6-a9ad-6d027c1096bc",
            "target": null
        }
    },
    "url": "https://eastus2.experiments.azureml.net/content/v1.0/subscriptions/fac34303-435d-4486-8c3f-7094d82a0b60/resourceGroups/aml-notebooks/providers/Microsoft.MachineLearningServices/workspaces/haieastus2ws3/snapshots/bd84e3d4-b217-466a-9246-6e2fc8411090?parentSnapshotId=87311c3d-6b5f-4da6-a9ad-6d027c1096bc"
}
Traceback (most recent call last):
  File "./08.tf.hd.py", line 92, in <module>
    run = tfe.fit()
  File "/home/ninghai/miniconda3/envs/preview/lib/python3.6/site-packages/azureml/train/dnn.py", line 332, in fit
    return super(TensorFlow, self).fit()
  File "/home/ninghai/miniconda3/envs/preview/lib/python3.6/site-packages/azureml/train/estimator.py", line 78, in fit
    _telemetry_values=telemetry_values)
  File "/home/ninghai/miniconda3/envs/preview/lib/python3.6/site-packages/azureml/core/run.py", line 64, in submit
    return _commands.start_run(project_object, run_config_object, telemetry_values=_telemetry_values)
  File "/home/ninghai/miniconda3/envs/preview/lib/python3.6/site-packages/azureml/execution/_commands.py", line 114, in start_run
    telemetry_values=telemetry_values)
  File "/home/ninghai/miniconda3/envs/preview/lib/python3.6/site-packages/azureml/execution/_commands.py", line 381, in _start_internal
    snapshot_id = snapshot_async.get() if snapshot_async else None
  File "/home/ninghai/miniconda3/envs/preview/lib/python3.6/multiprocessing/pool.py", line 644, in get
    raise self._value
  File "/home/ninghai/miniconda3/envs/preview/lib/python3.6/multiprocessing/pool.py", line 119, in worker
    result = (True, func(*args, **kwds))
  File "/home/ninghai/miniconda3/envs/preview/lib/python3.6/site-packages/azureml/base_sdk_common/create_snapshot.py", line 129, in create_snapshot
    raise SnapshotException(get_http_exception_response_string(response))
azureml.exceptions.azureml_exception.SnapshotException: {
    "status_code": 404,
    "text": {
        "correlation": {
            "operation": "e87db37e-4dafe5d5581f0658",
            "request": "NbeUNplYkc0="
        },
        "error": {
            "code": "UserError",
            "debugInfo": {
                "data": {},
                "errorResponse": null,
                "innerException": null,
                "message": "Unable to find snapshot with id: f2407d9f-2238-46f6-92ce-8f95174e96e7",
                "stackTrace": "   at Microsoft.MachineLearning.Project.Services.SnapshotStore.<GetBlobAsStringOrFailNotFound>d__17.MoveNext() in /opt/vsts/work/1/s/src/azureml-api/src/ProjectContent/Services/SnapshotStore.cs:line 271\n--- End of stack trace from previous location where exception was thrown ---\n   at System.Runtime.ExceptionServices.ExceptionDispatchInfo.Throw()\n   at System.Runtime.CompilerServices.TaskAwaiter.HandleNonSuccessAndDebuggerNotification(Task task)\n   at Microsoft.MachineLearning.Project.Services.SnapshotStore.<GetSnapshot>d__7.MoveNext() in /opt/vsts/work/1/s/src/azureml-api/src/ProjectContent/Services/SnapshotStore.cs:line 113\n--- End of stack trace from previous location where exception was thrown ---\n   at System.Runtime.ExceptionServices.ExceptionDispatchInfo.Throw()\n   at System.Runtime.CompilerServices.TaskAwaiter.HandleNonSuccessAndDebuggerNotification(Task task)\n   at Microsoft.MachineLearning.ProjectContent.EntryPoints.Controllers.SnapshotController.<CreateSnapshot>d__12.MoveNext() in /opt/vsts/work/1/s/src/azureml-api/src/ProjectContent/EntryPoints/Controllers/SnapshotController.cs:line 212\n--- End of stack trace from previous location where exception was thrown ---\n   at System.Runtime.ExceptionServices.ExceptionDispatchInfo.Throw()\n   at System.Runtime.CompilerServices.TaskAwaiter.HandleNonSuccessAndDebuggerNotification(Task task)\n   at Microsoft.AspNetCore.Mvc.Internal.ControllerActionInvoker.<InvokeActionMethodAsync>d__12.MoveNext()\n--- End of stack trace from previous location where exception was thrown ---\n   at System.Runtime.ExceptionServices.ExceptionDispatchInfo.Throw()\n   at System.Runtime.CompilerServices.TaskAwaiter.HandleNonSuccessAndDebuggerNotification(Task task)\n   at Microsoft.AspNetCore.Mvc.Internal.ControllerActionInvoker.<InvokeNextActionFilterAsync>d__10.MoveNext()\n--- End of stack trace from previous location where exception was thrown ---\n   at System.Runtime.ExceptionServices.ExceptionDispatchInfo.Throw()\n   at Microsoft.AspNetCore.Mvc.Internal.ControllerActionInvoker.Rethrow(ActionExecutedContext context)\n   at Microsoft.AspNetCore.Mvc.Internal.ControllerActionInvoker.Next(State& next, Scope& scope, Object& state, Boolean& isCompleted)\n   at Microsoft.AspNetCore.Mvc.Internal.ControllerActionInvoker.<InvokeInnerFilterAsync>d__14.MoveNext()\n--- End of stack trace from previous location where exception was thrown ---\n   at System.Runtime.ExceptionServices.ExceptionDispatchInfo.Throw()\n   at System.Runtime.CompilerServices.TaskAwaiter.HandleNonSuccessAndDebuggerNotification(Task task)\n   at Microsoft.AspNetCore.Mvc.Internal.ResourceInvoker.<InvokeNextExceptionFilterAsync>d__23.MoveNext()",
                "type": "Common.WebApi.Exceptions.ResourceNotFoundException"
            },
            "details": [],
            "innerError": null,
            "message": "Unable to find snapshot with id: f2407d9f-2238-46f6-92ce-8f95174e96e7",
            "target": null
        }
    },
    "url": "https://eastus2.experiments.azureml.net/content/v1.0/subscriptions/fac34303-435d-4486-8c3f-7094d82a0b60/resourceGroups/aml-notebooks/providers/Microsoft.MachineLearningServices/workspaces/haieastus2ws3/snapshots/c8ca51d7-7ec1-4418-b395-959724b73533?parentSnapshotId=f2407d9f-2238-46f6-92ce-8f95174e96e7"
}
ERROR:azure.storage.common.storageclient:Client-Request-ID=e44cfd9a-77a7-11e8-9288-000d3a71b7c3 Retry policy did not allow for a retry: Server-Timestamp=Sun, 24 Jun 2018 12:12:40 GMT, Server-Request-ID=eb3098d5-701e-0093-4bb4-0bcd2f000000, HTTP status code=409, Exception=The specified container already exists.ErrorCode: ContainerAlreadyExists<?xml version="1.0" encoding="utf-8"?><Error><Code>ContainerAlreadyExists</Code><Message>The specified container already exists.RequestId:eb3098d5-701e-0093-4bb4-0bcd2f000000Time:2018-06-24T12:12:40.9425255Z</Message></Error>.
ERROR:azure.storage.common.storageclient:Client-Request-ID=e44cfd9c-77a7-11e8-9288-000d3a71b7c3 Retry policy did not allow for a retry: Server-Timestamp=Sun, 24 Jun 2018 12:12:40 GMT, Server-Request-ID=3ebc7e7f-d01e-00f8-43b4-0b9079000000, HTTP status code=409, Exception=The specified container already exists.ErrorCode: ContainerAlreadyExists<?xml version="1.0" encoding="utf-8"?><Error><Code>ContainerAlreadyExists</Code><Message>The specified container already exists.RequestId:3ebc7e7f-d01e-00f8-43b4-0b9079000000Time:2018-06-24T12:12:41.1616470Z</Message></Error>.
ERROR:azure.storage.common.storageclient:Client-Request-ID=e44cfd9e-77a7-11e8-9288-000d3a71b7c3 Retry policy did not allow for a retry: Server-Timestamp=Sun, 24 Jun 2018 12:12:41 GMT, Server-Request-ID=c8e46c3c-501e-00ad-7eb4-0b7b0e000000, HTTP status code=409, Exception=The specified container already exists.ErrorCode: ContainerAlreadyExists<?xml version="1.0" encoding="utf-8"?><Error><Code>ContainerAlreadyExists</Code><Message>The specified container already exists.RequestId:c8e46c3c-501e-00ad-7eb4-0b7b0e000000Time:2018-06-24T12:12:41.3552144Z</Message></Error>.
ERROR:azure.storage.common.storageclient:Client-Request-ID=e44cfda0-77a7-11e8-9288-000d3a71b7c3 Retry policy did not allow for a retry: Server-Timestamp=Sun, 24 Jun 2018 12:12:40 GMT, Server-Request-ID=01b50124-301e-013a-12b4-0b5e92000000, HTTP status code=409, Exception=The specified container already exists.ErrorCode: ContainerAlreadyExists<?xml version="1.0" encoding="utf-8"?><Error><Code>ContainerAlreadyExists</Code><Message>The specified container already exists.RequestId:01b50124-301e-013a-12b4-0b5e92000000Time:2018-06-24T12:12:41.5539684Z</Message></Error>.
Traceback (most recent call last):
  File "/home/ninghai/miniconda3/envs/preview/lib/python3.6/site-packages/azureml/core/webservice/webservice.py", line 268, in _deploy_webservice
    resp.raise_for_status()
  File "/home/ninghai/miniconda3/envs/preview/lib/python3.6/site-packages/requests/models.py", line 939, in raise_for_status
    raise HTTPError(http_error_msg, response=self)
requests.exceptions.HTTPError: 409 Client Error: Conflict for url: https://eastus2.modelmanagement.azureml.net/api/subscriptions/fac34303-435d-4486-8c3f-7094d82a0b60/resourceGroups/aml-notebooks/providers/Microsoft.MachineLearningServices/workspaces/haieastus2ws3/services?api-version=2018-03-01-preview

During handling of the above exception, another exception occurred:

Traceback (most recent call last):
  File "./10.o16n.py", line 65, in <module>
    service = Webservice.deploy_from_image(workspace = ws, name = web_service_name, image = image, deployment_config = aciconfig)
  File "/home/ninghai/miniconda3/envs/preview/lib/python3.6/site-packages/azureml/core/webservice/webservice.py", line 230, in deploy_from_image
    return child._deploy(workspace, name, image, deployment_config)
  File "/home/ninghai/miniconda3/envs/preview/lib/python3.6/site-packages/azureml/core/webservice/aci.py", line 88, in _deploy
    return Webservice._deploy_webservice(workspace, name, create_payload, AciWebservice)
  File "/home/ninghai/miniconda3/envs/preview/lib/python3.6/site-packages/azureml/core/webservice/webservice.py", line 273, in _deploy_webservice
    'Content: {}'.format(resp.status_code, resp.headers, resp.content))
azureml.exceptions.azureml_exception.WebserviceException: Received bad response from Model Management Service:
Response Code: 409
Headers: {'Date': 'Sun, 24 Jun 2018 12:14:57 GMT', 'Content-Type': 'application/json', 'Transfer-Encoding': 'chunked', 'Connection': 'keep-alive', 'api-supported-versions': '2018-03-01-preview', 'x-ms-client-request-id': '1125257a70c24e0d89d1ea02dbda2ce0', 'x-ms-client-session-id': '', 'Strict-Transport-Security': 'max-age=15724800; includeSubDomains; preload'}
Content: b'{"code":"Conflict","statusCode":409,"message":"Conflict","details":[{"code":"ServiceWithNameExists","message":"Workspace haieastus2ws3 already contains a Service with name: rrs02-preview"}]}'
Already on 'master'
