Switched to branch 'candidate'
Client-Request-ID=8eb970a1-68c2-11e8-9288-000d3a71b7c3 Retry policy did not allow for a retry: Server-Timestamp=Tue, 05 Jun 2018 13:15:46 GMT, Server-Request-ID=aa8dc45d-f01e-008a-45cf-fcee12000000, HTTP status code=409, Exception=The specified container already exists.ErrorCode: ContainerAlreadyExists<?xml version="1.0" encoding="utf-8"?><Error><Code>ContainerAlreadyExists</Code><Message>The specified container already exists.RequestId:aa8dc45d-f01e-008a-45cf-fcee12000000Time:2018-06-05T13:15:47.0266343Z</Message></Error>.
Client-Request-ID=8eb970a3-68c2-11e8-9288-000d3a71b7c3 Retry policy did not allow for a retry: Server-Timestamp=Tue, 05 Jun 2018 13:15:46 GMT, Server-Request-ID=546a1b66-d01e-0073-15cf-fc24f2000000, HTTP status code=409, Exception=The specified container already exists.ErrorCode: ContainerAlreadyExists<?xml version="1.0" encoding="utf-8"?><Error><Code>ContainerAlreadyExists</Code><Message>The specified container already exists.RequestId:546a1b66-d01e-0073-15cf-fc24f2000000Time:2018-06-05T13:15:47.1896904Z</Message></Error>.
Client-Request-ID=8eb970a5-68c2-11e8-9288-000d3a71b7c3 Retry policy did not allow for a retry: Server-Timestamp=Tue, 05 Jun 2018 13:15:46 GMT, Server-Request-ID=b61f38f0-401e-0098-55cf-fcda0e000000, HTTP status code=409, Exception=The specified container already exists.ErrorCode: ContainerAlreadyExists<?xml version="1.0" encoding="utf-8"?><Error><Code>ContainerAlreadyExists</Code><Message>The specified container already exists.RequestId:b61f38f0-401e-0098-55cf-fcda0e000000Time:2018-06-05T13:15:47.3532856Z</Message></Error>.
Client-Request-ID=8eb970a7-68c2-11e8-9288-000d3a71b7c3 Retry policy did not allow for a retry: Server-Timestamp=Tue, 05 Jun 2018 13:15:47 GMT, Server-Request-ID=cf0c76e2-e01e-0095-18cf-fc3502000000, HTTP status code=409, Exception=The specified container already exists.ErrorCode: ContainerAlreadyExists<?xml version="1.0" encoding="utf-8"?><Error><Code>ContainerAlreadyExists</Code><Message>The specified container already exists.RequestId:cf0c76e2-e01e-0095-18cf-fc3502000000Time:2018-06-05T13:15:47.5387616Z</Message></Error>.
Traceback (most recent call last):
  File "./01.interactive.e2e.py", line 139, in <module>
    driver = 'score.py')
  File "/home/ninghai/miniconda3/envs/candidate/lib/python3.6/site-packages/azureml/core/workspace.py", line 783, in deploy_webservice
    raise WebserviceException('Error occurred creating image {} for service.'.format(image.id))
azureml.exceptions.azureml_exception.WebserviceException: Error occurred creating image rrs01a:27 for service.
Traceback (most recent call last):
  File "./02.local.py", line 51, in <module>
    script_to_run = train_script)
  File "/home/ninghai/miniconda3/envs/candidate/lib/python3.6/site-packages/azureml/core/run.py", line 66, in submit
    execute_with_zip=_execute_with_zip)
  File "/home/ninghai/miniconda3/envs/candidate/lib/python3.6/site-packages/azureml/execution/_commands.py", line 110, in start_run
    telemetry_values=telemetry_values)
  File "/home/ninghai/miniconda3/envs/candidate/lib/python3.6/site-packages/azureml/execution/_commands.py", line 258, in _start_internal_local_cloud
    _raise_request_error(response, "starting run")
  File "/home/ninghai/miniconda3/envs/candidate/lib/python3.6/site-packages/azureml/execution/_commands.py", line 729, in _raise_request_error
    raise ExperimentExecutionException(get_http_exception_response_string(response))
azureml.exceptions.azureml_exception.ExperimentExecutionException: {
    "url": "https://eastus2.experiments.azureml.net/execution/v1.0/subscriptions/fac34303-435d-4486-8c3f-7094d82a0b60/resourceGroups/aml-notebooks/providers/Microsoft.MachineLearningServices/workspaces/haieastus2ws3/projects/e2e-02/localrun?runId=e2e-02_1528204819",
    "status_code": 502,
    "text": "<html>\r\n<head><title>502 Bad Gateway</title></head>\r\n<body bgcolor=\"white\">\r\n<center><h1>502 Bad Gateway</h1></center>\r\n<hr><center>nginx</center>\r\n</body>\r\n</html>\r\n"
}
Traceback (most recent call last):
  File "./03.aci.py", line 85, in <module>
    script_to_run = train_script)
  File "/home/ninghai/miniconda3/envs/candidate/lib/python3.6/site-packages/azureml/core/run.py", line 66, in submit
    execute_with_zip=_execute_with_zip)
  File "/home/ninghai/miniconda3/envs/candidate/lib/python3.6/site-packages/azureml/execution/_commands.py", line 116, in start_run
    execute_with_zip=execute_with_zip)
  File "/home/ninghai/miniconda3/envs/candidate/lib/python3.6/site-packages/azureml/execution/_commands.py", line 383, in _start_internal
    _raise_request_error(response, "starting run")
  File "/home/ninghai/miniconda3/envs/candidate/lib/python3.6/site-packages/azureml/execution/_commands.py", line 729, in _raise_request_error
    raise ExperimentExecutionException(get_http_exception_response_string(response))
azureml.exceptions.azureml_exception.ExperimentExecutionException: {
    "url": "https://eastus2.experiments.azureml.net/execution/v1.0/subscriptions/fac34303-435d-4486-8c3f-7094d82a0b60/resourceGroups/aml-notebooks/providers/Microsoft.MachineLearningServices/workspaces/haieastus2ws3/projects/e2e-03/run",
    "status_code": 500,
    "text": "{\n  \"error\": {\n    \"code\": \"ServiceError\",\n    \"message\": \"Received 500 from a service request\",\n    \"target\": \"POST https://eastus2.experiments.azureml.net/artifact/v1.0/subscriptions/fac34303-435d-4486-8c3f-7094d82a0b60/resourceGroups/aml-notebooks/providers/Microsoft.MachineLearningServices/workspaces/haieastus2ws3/projects/e2e-03/artifacts/batch/metadata/ExperimentRun/e2e-03_1528204940194\",\n    \"details\": [\n      {\n        \"code\": \"InternalServerError\",\n        \"message\": \"{\\n  \\\"error\\\": {\\n    \\\"code\\\": \\\"ServiceError\\\",\\n    \\\"message\\\": \\\"InternalServerError\\\",\\n    \\\"target\\\": null,\\n    \\\"details\\\": [],\\n    \\\"innerError\\\": null,\\n    \\\"debugInfo\\\": {\\n      \\\"type\\\": \\\"System.Net.Http.HttpRequestException\\\",\\n      \\\"message\\\": \\\"An error occurred while sending the request.\\\",\\n      \\\"stackTrace\\\": \\\"   at System.Runtime.ExceptionServices.ExceptionDispatchInfo.Throw()\\\\n   at System.Runtime.CompilerServices.TaskAwaiter.HandleNonSuccessAndDebuggerNotification(Task task)\\\\n   at System.Runtime.CompilerServices.ConfiguredTaskAwaitable`1.ConfiguredTaskAwaiter.GetResult()\\\\n   at System.Net.Http.DiagnosticsHandler.<SendAsync>d__2.MoveNext()\\\\n--- End of stack trace from previous location where exception was thrown ---\\\\n   at System.Runtime.ExceptionServices.ExceptionDispatchInfo.Throw()\\\\n   at System.Runtime.CompilerServices.TaskAwaiter.HandleNonSuccessAndDebuggerNotification(Task task)\\\\n   at System.Runtime.CompilerServices.ConfiguredTaskAwaitable`1.ConfiguredTaskAwaiter.GetResult()\\\\n   at System.Net.Http.HttpClient.<FinishSendAsyncBuffered>d__58.MoveNext()\\\\n--- End of stack trace from previous location where exception was thrown ---\\\\n   at System.Runtime.ExceptionServices.ExceptionDispatchInfo.Throw()\\\\n   at System.Runtime.CompilerServices.TaskAwaiter.HandleNonSuccessAndDebuggerNotification(Task task)\\\\n   at Microsoft.MachineLearning.Common.WebApi.Client.ServiceInvoker.<_Invoke>d__18`1.MoveNext() in /opt/vsts/work/1/s/src/azureml-api/src/Common/WebApi.Client/ServiceInvoker.cs:line 247\\\\n--- End of stack trace from previous location where exception was thrown ---\\\\n   at System.Runtime.ExceptionServices.ExceptionDispatchInfo.Throw()\\\\n   at System.Runtime.CompilerServices.TaskAwaiter.HandleNonSuccessAndDebuggerNotification(Task task)\\\\n   at Microsoft.MachineLearning.Common.WebApi.TeamAccounts.WorkspaceControllerBase.<GetWorkspace>d__21.MoveNext() in /opt/vsts/work/1/s/src/azureml-api/src/Common/WebApi.TeamAccounts/WorkspaceControllerBase.cs:line 153\\\\n--- End of stack trace from previous location where exception was thrown ---\\\\n   at System.Runtime.ExceptionServices.ExceptionDispatchInfo.Throw()\\\\n   at System.Runtime.CompilerServices.TaskAwaiter.HandleNonSuccessAndDebuggerNotification(Task task)\\\\n   at Microsoft.MachineLearning.Common.WebApi.TeamAccounts.WorkspaceControllerBase.<LoadWorkspaceAsync>d__19.MoveNext() in /opt/vsts/work/1/s/src/azureml-api/src/Common/WebApi.TeamAccounts/WorkspaceControllerBase.cs:line 100\\\\n--- End of stack trace from previous location where exception was thrown ---\\\\n   at System.Runtime.ExceptionServices.ExceptionDispatchInfo.Throw()\\\\n   at System.Runtime.CompilerServices.TaskAwaiter.HandleNonSuccessAndDebuggerNotification(Task task)\\\\n   at Microsoft.MachineLearning.Common.WebApi.TeamAccounts.WorkspaceControllerBase.<OnActionExecutionAsync>d__18.MoveNext() in /opt/vsts/work/1/s/src/azureml-api/src/Common/WebApi.TeamAccounts/WorkspaceControllerBase.cs:line 89\\\\n--- End of stack trace from previous location where exception was thrown ---\\\\n   at System.Runtime.ExceptionServices.ExceptionDispatchInfo.Throw()\\\\n   at System.Runtime.CompilerServices.TaskAwaiter.HandleNonSuccessAndDebuggerNotification(Task task)\\\\n   at Microsoft.AspNetCore.Mvc.Internal.ControllerActionFilter.<OnActionExecutionAsync>d__4.MoveNext()\\\\n--- End of stack trace from previous location where exception was thrown ---\\\\n   at System.Runtime.ExceptionServices.ExceptionDispatchInfo.Throw()\\\\n   at System.Runtime.CompilerServices.TaskAwaiter.HandleNonSuccessAndDebuggerNotification(Task task)\\\\n   at Microsoft.AspNetCore.Mvc.Internal.ControllerActionInvoker.<InvokeInnerFilterAsync>d__14.MoveNext()\\\\n--- End of stack trace from previous location where exception was thrown ---\\\\n   at System.Runtime.ExceptionServices.ExceptionDispatchInfo.Throw()\\\\n   at System.Runtime.CompilerServices.TaskAwaiter.HandleNonSuccessAndDebuggerNotification(Task task)\\\\n   at Microsoft.AspNetCore.Mvc.Internal.ResourceInvoker.<InvokeNextExceptionFilterAsync>d__23.MoveNext()\\\",\\n      \\\"innerException\\\": {\\n        \\\"type\\\": \\\"System.Net.Http.CurlException\\\",\\n        \\\"message\\\": \\\"Couldn't resolve host name\\\",\\n        \\\"stackTrace\\\": \\\"   at System.Net.Http.CurlHandler.ThrowIfCURLEError(CURLcode error)\\\\n   at System.Net.Http.CurlHandler.MultiAgent.FinishRequest(StrongToWeakReference`1 easyWrapper, CURLcode messageResult)\\\",\\n        \\\"innerException\\\": null,\\n        \\\"data\\\": {},\\n        \\\"errorResponse\\\": null\\n      },\\n      \\\"data\\\": {},\\n      \\\"errorResponse\\\": null\\n    }\\n  },\\n  \\\"correlation\\\": {\\n    \\\"operation\\\": \\\"15364f66-4dbe7a3d9a7bb369\\\",\\n    \\\"request\\\": \\\"K5mYcl7P4Ao=\\\"\\n  }\\n}\",\n        \"target\": null\n      }\n    ],\n    \"innerError\": null,\n    \"debugInfo\": {\n      \"type\": \"Microsoft.MachineLearning.Common.Core.ServiceInvocationException\",\n      \"message\": \"Service invocation failed!\\r\\nRequest: POST https://eastus2.experiments.azureml.net/artifact/v1.0/subscriptions/fac34303-435d-4486-8c3f-7094d82a0b60/resourceGroups/aml-notebooks/providers/Microsoft.MachineLearningServices/workspaces/haieastus2ws3/projects/e2e-03/artifacts/batch/metadata/ExperimentRun/e2e-03_1528204940194\\r\\nStatus Code: 500 InternalServerError\\r\\nReason Phrase: InternalServerError\\r\\nResponse Body: {\\n  \\\"error\\\": {\\n    \\\"code\\\": \\\"ServiceError\\\",\\n    \\\"message\\\": \\\"InternalServerError\\\",\\n    \\\"target\\\": null,\\n    \\\"details\\\": [],\\n    \\\"innerError\\\": null,\\n    \\\"debugInfo\\\": {\\n      \\\"type\\\": \\\"System.Net.Http.HttpRequestException\\\",\\n      \\\"message\\\": \\\"An error occurred while sending the request.\\\",\\n      \\\"stackTrace\\\": \\\"   at System.Runtime.ExceptionServices.ExceptionDispatchInfo.Throw()\\\\n   at System.Runtime.CompilerServices.TaskAwaiter.HandleNonSuccessAndDebuggerNotification(Task task)\\\\n   at System.Runtime.CompilerServices.ConfiguredTaskAwaitable`1.ConfiguredTaskAwaiter.GetResult()\\\\n   at System.Net.Http.DiagnosticsHandler.<SendAsync>d__2.MoveNext()\\\\n--- End of stack trace from previous location where exception was thrown ---\\\\n   at System.Runtime.ExceptionServices.ExceptionDispatchInfo.Throw()\\\\n   at System.Runtime.CompilerServices.TaskAwaiter.HandleNonSuccessAndDebuggerNotification(Task task)\\\\n   at System.Runtime.CompilerServices.ConfiguredTaskAwaitable`1.ConfiguredTaskAwaiter.GetResult()\\\\n   at System.Net.Http.HttpClient.<FinishSendAsyncBuffered>d__58.MoveNext()\\\\n--- End of stack trace from previous location where exception was thrown ---\\\\n   at System.Runtime.ExceptionServices.ExceptionDispatchInfo.Throw()\\\\n   at System.Runtime.CompilerServices.TaskAwaiter.HandleNonSuccessAndDebuggerNotification(Task task)\\\\n   at Microsoft.MachineLearning.Common.WebApi.Client.ServiceInvoker.<_Invoke>d__18`1.MoveNext() in /opt/vsts/work/1/s/src/azureml-api/src/Common/WebApi.Client/ServiceInvoker.cs:line 247\\\\n--- End of stack trace from previous location where exception was thrown ---\\\\n   at System.Runtime.ExceptionServices.ExceptionDispatchInfo.Throw()\\\\n   at System.Runtime.CompilerServices.TaskAwaiter.HandleNonSuccessAndDebuggerNotification(Task task)\\\\n   at Microsoft.MachineLearning.Common.WebApi.TeamAccounts.WorkspaceControllerBase.<GetWorkspace>d__21.MoveNext() in /opt/vsts/work/1/s/src/azureml-api/src/Common/WebApi.TeamAccounts/WorkspaceControllerBase.cs:line 153\\\\n--- End of stack trace from previous location where exception was thrown ---\\\\n   at System.Runtime.ExceptionServices.ExceptionDispatchInfo.Throw()\\\\n   at System.Runtime.CompilerServices.TaskAwaiter.HandleNonSuccessAndDebuggerNotification(Task task)\\\\n   at Microsoft.MachineLearning.Common.WebApi.TeamAccounts.WorkspaceControllerBase.<LoadWorkspaceAsync>d__19.MoveNext() in /opt/vsts/work/1/s/src/azureml-api/src/Common/WebApi.TeamAccounts/WorkspaceControllerBase.cs:line 100\\\\n--- End of stack trace from previous location where exception was thrown ---\\\\n   at System.Runtime.ExceptionServices.ExceptionDispatchInfo.Throw()\\\\n   at System.Runtime.CompilerServices.TaskAwaiter.HandleNonSuccessAndDebuggerNotification(Task task)\\\\n   at Microsoft.MachineLearning.Common.WebApi.TeamAccounts.WorkspaceControllerBase.<OnActionExecutionAsync>d__18.MoveNext() in /opt/vsts/work/1/s/src/azureml-api/src/Common/WebApi.TeamAccounts/WorkspaceControllerBase.cs:line 89\\\\n--- End of stack trace from previous location where exception was thrown ---\\\\n   at System.Runtime.ExceptionServices.ExceptionDispatchInfo.Throw()\\\\n   at System.Runtime.CompilerServices.TaskAwaiter.HandleNonSuccessAndDebuggerNotification(Task task)\\\\n   at Microsoft.AspNetCore.Mvc.Internal.ControllerActionFilter.<OnActionExecutionAsync>d__4.MoveNext()\\\\n--- End of stack trace from previous location where exception was thrown ---\\\\n   at System.Runtime.ExceptionServices.ExceptionDispatchInfo.Throw()\\\\n   at System.Runtime.CompilerServices.TaskAwaiter.HandleNonSuccessAndDebuggerNotification(Task task)\\\\n   at Microsoft.AspNetCore.Mvc.Internal.ControllerActionInvoker.<InvokeInnerFilterAsync>d__14.MoveNext()\\\\n--- End of stack trace from previous location where exception was thrown ---\\\\n   at System.Runtime.ExceptionServices.ExceptionDispatchInfo.Throw()\\\\n   at System.Runtime.CompilerServices.TaskAwaiter.HandleNonSuccessAndDebuggerNotification(Task task)\\\\n   at Microsoft.AspNetCore.Mvc.Internal.ResourceInvoker.<InvokeNextExceptionFilterAsync>d__23.MoveNext()\\\",\\n      \\\"innerException\\\": {\\n        \\\"type\\\": \\\"System.Net.Http.CurlException\\\",\\n        \\\"message\\\": \\\"Couldn't resolve host name\\\",\\n        \\\"stackTrace\\\": \\\"   at System.Net.Http.CurlHandler.ThrowIfCURLEError(CURLcode error)\\\\n   at System.Net.Http.CurlHandler.MultiAgent.FinishRequest(StrongToWeakReference`1 easyWrapper, CURLcode messageResult)\\\",\\n        \\\"innerException\\\": null,\\n        \\\"data\\\": {},\\n        \\\"errorResponse\\\": null\\n      },\\n      \\\"data\\\": {},\\n      \\\"errorResponse\\\": null\\n    }\\n  },\\n  \\\"correlation\\\": {\\n    \\\"operation\\\": \\\"15364f66-4dbe7a3d9a7bb369\\\",\\n    \\\"request\\\": \\\"K5mYcl7P4Ao=\\\"\\n  }\\n}\",\n      \"stackTrace\": \"   at Microsoft.MachineLearning.Common.WebApi.Client.ServiceInvoker.<_Invoke>d__18`1.MoveNext()\\n--- End of stack trace from previous location where exception was thrown ---\\n   at System.Runtime.ExceptionServices.ExceptionDispatchInfo.Throw()\\n   at System.Runtime.CompilerServices.TaskAwaiter.HandleNonSuccessAndDebuggerNotification(Task task)\\n   at Microsoft.MachineLearning.Execution.Services.ProxyClients.ArtifactServiceProxy.<BatchCreateEmptyArtifacts>d__4.MoveNext() in /opt/vsts/work/1/s/src/azureml-api/src/Execution/Services/ProxyClients/ArtifactServiceProxy.cs:line 56\\n--- End of stack trace from previous location where exception was thrown ---\\n   at System.Runtime.ExceptionServices.ExceptionDispatchInfo.Throw()\\n   at System.Runtime.CompilerServices.TaskAwaiter.HandleNonSuccessAndDebuggerNotification(Task task)\\n   at Microsoft.MachineLearning.Execution.Services.HistoryManager.<CreateArtifactWithWriteSas>d__9.MoveNext() in /opt/vsts/work/1/s/src/azureml-api/src/Execution/Services/HistoryManager.cs:line 155\\n--- End of stack trace from previous location where exception was thrown ---\\n   at System.Runtime.ExceptionServices.ExceptionDispatchInfo.Throw()\\n   at System.Runtime.CompilerServices.TaskAwaiter.HandleNonSuccessAndDebuggerNotification(Task task)\\n   at Microsoft.MachineLearning.Execution.Services.DynamicStrategy.<CreateIceLogsStructure>d__31.MoveNext() in /opt/vsts/work/1/s/src/azureml-api/src/Execution/Services/DynamicStrategy.cs:line 481\\n--- End of stack trace from previous location where exception was thrown ---\\n   at System.Runtime.ExceptionServices.ExceptionDispatchInfo.Throw()\\n   at System.Runtime.CompilerServices.TaskAwaiter.HandleNonSuccessAndDebuggerNotification(Task task)\\n   at Microsoft.MachineLearning.Execution.Services.DynamicStrategy.<StartRun>d__20.MoveNext() in /opt/vsts/work/1/s/src/azureml-api/src/Execution/Services/DynamicStrategy.cs:line 207\\n--- End of stack trace from previous location where exception was thrown ---\\n   at System.Runtime.ExceptionServices.ExceptionDispatchInfo.Throw()\\n   at System.Runtime.CompilerServices.TaskAwaiter.HandleNonSuccessAndDebuggerNotification(Task task)\\n   at Microsoft.MachineLearning.Execution.EntryPoints.Api.Controllers.ExecutionController.<StartRun>d__26.MoveNext() in /opt/vsts/work/1/s/src/azureml-api/src/Execution/EntryPoints/Api/Controllers/ExecutionController.cs:line 336\\n--- End of stack trace from previous location where exception was thrown ---\\n   at System.Runtime.ExceptionServices.ExceptionDispatchInfo.Throw()\\n   at Microsoft.MachineLearning.Execution.EntryPoints.Api.Controllers.ExecutionController.<StartRun>d__26.MoveNext() in /opt/vsts/work/1/s/src/azureml-api/src/Execution/EntryPoints/Api/Controllers/ExecutionController.cs:line 343\\n--- End of stack trace from previous location where exception was thrown ---\\n   at System.Runtime.ExceptionServices.ExceptionDispatchInfo.Throw()\\n   at System.Runtime.CompilerServices.TaskAwaiter.HandleNonSuccessAndDebuggerNotification(Task task)\\n   at Microsoft.MachineLearning.Execution.EntryPoints.Api.Controllers.ExecutionController.<StartRun>d__22.MoveNext() in /opt/vsts/work/1/s/src/azureml-api/src/Execution/EntryPoints/Api/Controllers/ExecutionController.cs:line 215\\n--- End of stack trace from previous location where exception was thrown ---\\n   at System.Runtime.ExceptionServices.ExceptionDispatchInfo.Throw()\\n   at System.Runtime.CompilerServices.TaskAwaiter.HandleNonSuccessAndDebuggerNotification(Task task)\\n   at lambda_method(Closure , Object )\\n   at Microsoft.AspNetCore.Mvc.Internal.ControllerActionInvoker.<InvokeActionMethodAsync>d__12.MoveNext()\\n--- End of stack trace from previous location where exception was thrown ---\\n   at System.Runtime.ExceptionServices.ExceptionDispatchInfo.Throw()\\n   at System.Runtime.CompilerServices.TaskAwaiter.HandleNonSuccessAndDebuggerNotification(Task task)\\n   at Microsoft.AspNetCore.Mvc.Internal.ControllerActionInvoker.<InvokeNextActionFilterAsync>d__10.MoveNext()\\n--- End of stack trace from previous location where exception was thrown ---\\n   at System.Runtime.ExceptionServices.ExceptionDispatchInfo.Throw()\\n   at Microsoft.AspNetCore.Mvc.Internal.ControllerActionInvoker.Rethrow(ActionExecutedContext context)\\n   at Microsoft.AspNetCore.Mvc.Internal.ControllerActionInvoker.Next(State& next, Scope& scope, Object& state, Boolean& isCompleted)\\n   at Microsoft.AspNetCore.Mvc.Internal.ControllerActionInvoker.<InvokeInnerFilterAsync>d__14.MoveNext()\\n--- End of stack trace from previous location where exception was thrown ---\\n   at System.Runtime.ExceptionServices.ExceptionDispatchInfo.Throw()\\n   at System.Runtime.CompilerServices.TaskAwaiter.HandleNonSuccessAndDebuggerNotification(Task task)\\n   at Microsoft.AspNetCore.Mvc.Internal.ResourceInvoker.<InvokeNextExceptionFilterAsync>d__23.MoveNext()\",\n      \"innerException\": null,\n      \"data\": {},\n      \"errorResponse\": {\n        \"error\": {\n          \"code\": \"ServiceError\",\n          \"message\": \"InternalServerError\",\n          \"target\": null,\n          \"details\": [],\n          \"innerError\": null,\n          \"debugInfo\": {\n            \"type\": \"System.Net.Http.HttpRequestException\",\n            \"message\": \"An error occurred while sending the request.\",\n            \"stackTrace\": \"   at System.Runtime.ExceptionServices.ExceptionDispatchInfo.Throw()\\n   at System.Runtime.CompilerServices.TaskAwaiter.HandleNonSuccessAndDebuggerNotification(Task task)\\n   at System.Runtime.CompilerServices.ConfiguredTaskAwaitable`1.ConfiguredTaskAwaiter.GetResult()\\n   at System.Net.Http.DiagnosticsHandler.<SendAsync>d__2.MoveNext()\\n--- End of stack trace from previous location where exception was thrown ---\\n   at System.Runtime.ExceptionServices.ExceptionDispatchInfo.Throw()\\n   at System.Runtime.CompilerServices.TaskAwaiter.HandleNonSuccessAndDebuggerNotification(Task task)\\n   at System.Runtime.CompilerServices.ConfiguredTaskAwaitable`1.ConfiguredTaskAwaiter.GetResult()\\n   at System.Net.Http.HttpClient.<FinishSendAsyncBuffered>d__58.MoveNext()\\n--- End of stack trace from previous location where exception was thrown ---\\n   at System.Runtime.ExceptionServices.ExceptionDispatchInfo.Throw()\\n   at System.Runtime.CompilerServices.TaskAwaiter.HandleNonSuccessAndDebuggerNotification(Task task)\\n   at Microsoft.MachineLearning.Common.WebApi.Client.ServiceInvoker.<_Invoke>d__18`1.MoveNext() in /opt/vsts/work/1/s/src/azureml-api/src/Common/WebApi.Client/ServiceInvoker.cs:line 247\\n--- End of stack trace from previous location where exception was thrown ---\\n   at System.Runtime.ExceptionServices.ExceptionDispatchInfo.Throw()\\n   at System.Runtime.CompilerServices.TaskAwaiter.HandleNonSuccessAndDebuggerNotification(Task task)\\n   at Microsoft.MachineLearning.Common.WebApi.TeamAccounts.WorkspaceControllerBase.<GetWorkspace>d__21.MoveNext() in /opt/vsts/work/1/s/src/azureml-api/src/Common/WebApi.TeamAccounts/WorkspaceControllerBase.cs:line 153\\n--- End of stack trace from previous location where exception was thrown ---\\n   at System.Runtime.ExceptionServices.ExceptionDispatchInfo.Throw()\\n   at System.Runtime.CompilerServices.TaskAwaiter.HandleNonSuccessAndDebuggerNotification(Task task)\\n   at Microsoft.MachineLearning.Common.WebApi.TeamAccounts.WorkspaceControllerBase.<LoadWorkspaceAsync>d__19.MoveNext() in /opt/vsts/work/1/s/src/azureml-api/src/Common/WebApi.TeamAccounts/WorkspaceControllerBase.cs:line 100\\n--- End of stack trace from previous location where exception was thrown ---\\n   at System.Runtime.ExceptionServices.ExceptionDispatchInfo.Throw()\\n   at System.Runtime.CompilerServices.TaskAwaiter.HandleNonSuccessAndDebuggerNotification(Task task)\\n   at Microsoft.MachineLearning.Common.WebApi.TeamAccounts.WorkspaceControllerBase.<OnActionExecutionAsync>d__18.MoveNext() in /opt/vsts/work/1/s/src/azureml-api/src/Common/WebApi.TeamAccounts/WorkspaceControllerBase.cs:line 89\\n--- End of stack trace from previous location where exception was thrown ---\\n   at System.Runtime.ExceptionServices.ExceptionDispatchInfo.Throw()\\n   at System.Runtime.CompilerServices.TaskAwaiter.HandleNonSuccessAndDebuggerNotification(Task task)\\n   at Microsoft.AspNetCore.Mvc.Internal.ControllerActionFilter.<OnActionExecutionAsync>d__4.MoveNext()\\n--- End of stack trace from previous location where exception was thrown ---\\n   at System.Runtime.ExceptionServices.ExceptionDispatchInfo.Throw()\\n   at System.Runtime.CompilerServices.TaskAwaiter.HandleNonSuccessAndDebuggerNotification(Task task)\\n   at Microsoft.AspNetCore.Mvc.Internal.ControllerActionInvoker.<InvokeInnerFilterAsync>d__14.MoveNext()\\n--- End of stack trace from previous location where exception was thrown ---\\n   at System.Runtime.ExceptionServices.ExceptionDispatchInfo.Throw()\\n   at System.Runtime.CompilerServices.TaskAwaiter.HandleNonSuccessAndDebuggerNotification(Task task)\\n   at Microsoft.AspNetCore.Mvc.Internal.ResourceInvoker.<InvokeNextExceptionFilterAsync>d__23.MoveNext()\",\n            \"innerException\": {\n              \"type\": \"System.Net.Http.CurlException\",\n              \"message\": \"Couldn't resolve host name\",\n              \"stackTrace\": \"   at System.Net.Http.CurlHandler.ThrowIfCURLEError(CURLcode error)\\n   at System.Net.Http.CurlHandler.MultiAgent.FinishRequest(StrongToWeakReference`1 easyWrapper, CURLcode messageResult)\",\n              \"innerException\": null,\n              \"data\": {},\n              \"errorResponse\": null\n            },\n            \"data\": {},\n            \"errorResponse\": null\n          }\n        },\n        \"correlation\": {\n          \"operation\": \"15364f66-4dbe7a3d9a7bb369\",\n          \"request\": \"K5mYcl7P4Ao=\"\n        }\n      }\n    }\n  },\n  \"correlation\": {\n    \"operation\": \"15364f66-4dbe7a3d9a7bb369\",\n    \"request\": \"szRLfzFcUK4=\"\n  }\n}"
}
Traceback (most recent call last):
  File "./04.dsvm.py", line 70, in <module>
    script_to_run = train_script)
  File "/home/ninghai/miniconda3/envs/candidate/lib/python3.6/site-packages/azureml/core/run.py", line 66, in submit
    execute_with_zip=_execute_with_zip)
  File "/home/ninghai/miniconda3/envs/candidate/lib/python3.6/site-packages/azureml/execution/_commands.py", line 116, in start_run
    execute_with_zip=execute_with_zip)
  File "/home/ninghai/miniconda3/envs/candidate/lib/python3.6/site-packages/azureml/execution/_commands.py", line 365, in _start_internal
    snapshot_id = snapshot_async.get()
  File "/home/ninghai/miniconda3/envs/candidate/lib/python3.6/multiprocessing/pool.py", line 644, in get
    raise self._value
  File "/home/ninghai/miniconda3/envs/candidate/lib/python3.6/multiprocessing/pool.py", line 119, in worker
    result = (True, func(*args, **kwds))
  File "/home/ninghai/miniconda3/envs/candidate/lib/python3.6/site-packages/azureml/base_sdk_common/create_snapshot.py", line 102, in create_snapshot
    raise ExperimentExecutionException(get_http_exception_response_string(response))
azureml.exceptions.azureml_exception.ExperimentExecutionException: {
    "url": "https://eastus2.experiments.azureml.net/content/v1.0/subscriptions/fac34303-435d-4486-8c3f-7094d82a0b60/resourceGroups/aml-notebooks/providers/Microsoft.MachineLearningServices/workspaces/haieastus2ws3/snapshots/cfec0c46-9c85-46a6-bfd4-2dea959e2abd?parentSnapshotId=f280d4e2-29db-4cc3-8922-24cfb322a5c1",
    "status_code": 504,
    "text": "<html>\r\n<head><title>504 Gateway Time-out</title></head>\r\n<body bgcolor=\"white\">\r\n<center><h1>504 Gateway Time-out</h1></center>\r\n<hr><center>nginx</center>\r\n</body>\r\n</html>\r\n"
}
Traceback (most recent call last):
  File "./05.spark.py", line 132, in <module>
    script_to_run = train_script)
  File "/home/ninghai/miniconda3/envs/candidate/lib/python3.6/site-packages/azureml/core/run.py", line 66, in submit
    execute_with_zip=_execute_with_zip)
  File "/home/ninghai/miniconda3/envs/candidate/lib/python3.6/site-packages/azureml/execution/_commands.py", line 116, in start_run
    execute_with_zip=execute_with_zip)
  File "/home/ninghai/miniconda3/envs/candidate/lib/python3.6/site-packages/azureml/execution/_commands.py", line 383, in _start_internal
    _raise_request_error(response, "starting run")
  File "/home/ninghai/miniconda3/envs/candidate/lib/python3.6/site-packages/azureml/execution/_commands.py", line 729, in _raise_request_error
    raise ExperimentExecutionException(get_http_exception_response_string(response))
azureml.exceptions.azureml_exception.ExperimentExecutionException: {
    "url": "https://eastus2.experiments.azureml.net/execution/v1.0/subscriptions/fac34303-435d-4486-8c3f-7094d82a0b60/resourceGroups/aml-notebooks/providers/Microsoft.MachineLearningServices/workspaces/haieastus2ws3/projects/e2e-05/run",
    "status_code": 500,
    "text": "{\n  \"error\": {\n    \"code\": \"ServiceError\",\n    \"message\": \"InternalServerError\",\n    \"target\": null,\n    \"details\": [],\n    \"innerError\": null,\n    \"debugInfo\": {\n      \"type\": \"System.Net.Http.HttpRequestException\",\n      \"message\": \"An error occurred while sending the request.\",\n      \"stackTrace\": \"   at System.Runtime.ExceptionServices.ExceptionDispatchInfo.Throw()\\n   at System.Runtime.CompilerServices.TaskAwaiter.HandleNonSuccessAndDebuggerNotification(Task task)\\n   at System.Runtime.CompilerServices.ConfiguredTaskAwaitable`1.ConfiguredTaskAwaiter.GetResult()\\n   at System.Net.Http.DiagnosticsHandler.<SendAsync>d__2.MoveNext()\\n--- End of stack trace from previous location where exception was thrown ---\\n   at System.Runtime.ExceptionServices.ExceptionDispatchInfo.Throw()\\n   at System.Runtime.CompilerServices.TaskAwaiter.HandleNonSuccessAndDebuggerNotification(Task task)\\n   at System.Runtime.CompilerServices.ConfiguredTaskAwaitable`1.ConfiguredTaskAwaiter.GetResult()\\n   at System.Net.Http.HttpClient.<FinishSendAsyncBuffered>d__58.MoveNext()\\n--- End of stack trace from previous location where exception was thrown ---\\n   at System.Runtime.ExceptionServices.ExceptionDispatchInfo.Throw()\\n   at System.Runtime.CompilerServices.TaskAwaiter.HandleNonSuccessAndDebuggerNotification(Task task)\\n   at Microsoft.MachineLearning.Common.WebApi.Client.ServiceInvoker.<_Invoke>d__18`1.MoveNext() in /opt/vsts/work/1/s/src/azureml-api/src/Common/WebApi.Client/ServiceInvoker.cs:line 247\\n--- End of stack trace from previous location where exception was thrown ---\\n   at System.Runtime.ExceptionServices.ExceptionDispatchInfo.Throw()\\n   at System.Runtime.CompilerServices.TaskAwaiter.HandleNonSuccessAndDebuggerNotification(Task task)\\n   at Microsoft.MachineLearning.Execution.Services.ProxyClients.CredentialServiceProxy.<GetCredentialsBatch>d__4.MoveNext() in /opt/vsts/work/1/s/src/azureml-api/src/Execution/Services/ProxyClients/CredentialServiceProxy.cs:line 64\\n--- End of stack trace from previous location where exception was thrown ---\\n   at System.Runtime.ExceptionServices.ExceptionDispatchInfo.Throw()\\n   at System.Runtime.CompilerServices.TaskAwaiter.HandleNonSuccessAndDebuggerNotification(Task task)\\n   at Microsoft.MachineLearning.Execution.EntryPoints.Security.ExecutionCredentialsProvider.<LookupCredentialsUsingCredentialsKeys>d__3.MoveNext() in /opt/vsts/work/1/s/src/azureml-api/src/Execution/Services/ExecutionCredentialsProvider.cs:line 61\\n--- End of stack trace from previous location where exception was thrown ---\\n   at System.Runtime.ExceptionServices.ExceptionDispatchInfo.Throw()\\n   at System.Runtime.CompilerServices.TaskAwaiter.HandleNonSuccessAndDebuggerNotification(Task task)\\n   at Microsoft.MachineLearning.Execution.Services.SecretsManager.<RetrieveSecrets>d__3.MoveNext() in /opt/vsts/work/1/s/src/azureml-api/src/Execution/Services/SecretsManager.cs:line 59\\n--- End of stack trace from previous location where exception was thrown ---\\n   at System.Runtime.ExceptionServices.ExceptionDispatchInfo.Throw()\\n   at System.Runtime.CompilerServices.TaskAwaiter.HandleNonSuccessAndDebuggerNotification(Task task)\\n   at Microsoft.MachineLearning.Execution.Services.StrategyState.<Hydrate>d__59.MoveNext() in /opt/vsts/work/1/s/src/azureml-api/src/Execution/Services/StrategyState.cs:line 142\\n--- End of stack trace from previous location where exception was thrown ---\\n   at System.Runtime.ExceptionServices.ExceptionDispatchInfo.Throw()\\n   at System.Runtime.CompilerServices.TaskAwaiter.HandleNonSuccessAndDebuggerNotification(Task task)\\n   at Microsoft.MachineLearning.Execution.EntryPoints.Api.Controllers.ExecutionController.<MakeStrategyState>d__40.MoveNext() in /opt/vsts/work/1/s/src/azureml-api/src/Execution/EntryPoints/Api/Controllers/ExecutionController.cs:line 691\\n--- End of stack trace from previous location where exception was thrown ---\\n   at System.Runtime.ExceptionServices.ExceptionDispatchInfo.Throw()\\n   at System.Runtime.CompilerServices.TaskAwaiter.HandleNonSuccessAndDebuggerNotification(Task task)\\n   at Microsoft.MachineLearning.Execution.EntryPoints.Api.Controllers.ExecutionController.<StartRun>d__26.MoveNext() in /opt/vsts/work/1/s/src/azureml-api/src/Execution/EntryPoints/Api/Controllers/ExecutionController.cs:line 315\\n--- End of stack trace from previous location where exception was thrown ---\\n   at System.Runtime.ExceptionServices.ExceptionDispatchInfo.Throw()\\n   at System.Runtime.CompilerServices.TaskAwaiter.HandleNonSuccessAndDebuggerNotification(Task task)\\n   at Microsoft.MachineLearning.Execution.EntryPoints.Api.Controllers.ExecutionController.<StartRun>d__22.MoveNext() in /opt/vsts/work/1/s/src/azureml-api/src/Execution/EntryPoints/Api/Controllers/ExecutionController.cs:line 215\\n--- End of stack trace from previous location where exception was thrown ---\\n   at System.Runtime.ExceptionServices.ExceptionDispatchInfo.Throw()\\n   at System.Runtime.CompilerServices.TaskAwaiter.HandleNonSuccessAndDebuggerNotification(Task task)\\n   at lambda_method(Closure , Object )\\n   at Microsoft.AspNetCore.Mvc.Internal.ControllerActionInvoker.<InvokeActionMethodAsync>d__12.MoveNext()\\n--- End of stack trace from previous location where exception was thrown ---\\n   at System.Runtime.ExceptionServices.ExceptionDispatchInfo.Throw()\\n   at System.Runtime.CompilerServices.TaskAwaiter.HandleNonSuccessAndDebuggerNotification(Task task)\\n   at Microsoft.AspNetCore.Mvc.Internal.ControllerActionInvoker.<InvokeNextActionFilterAsync>d__10.MoveNext()\\n--- End of stack trace from previous location where exception was thrown ---\\n   at System.Runtime.ExceptionServices.ExceptionDispatchInfo.Throw()\\n   at Microsoft.AspNetCore.Mvc.Internal.ControllerActionInvoker.Rethrow(ActionExecutedContext context)\\n   at Microsoft.AspNetCore.Mvc.Internal.ControllerActionInvoker.Next(State& next, Scope& scope, Object& state, Boolean& isCompleted)\\n   at Microsoft.AspNetCore.Mvc.Internal.ControllerActionInvoker.<InvokeInnerFilterAsync>d__14.MoveNext()\\n--- End of stack trace from previous location where exception was thrown ---\\n   at System.Runtime.ExceptionServices.ExceptionDispatchInfo.Throw()\\n   at System.Runtime.CompilerServices.TaskAwaiter.HandleNonSuccessAndDebuggerNotification(Task task)\\n   at Microsoft.AspNetCore.Mvc.Internal.ResourceInvoker.<InvokeNextExceptionFilterAsync>d__23.MoveNext()\",\n      \"innerException\": {\n        \"type\": \"System.Net.Http.CurlException\",\n        \"message\": \"Couldn't resolve host name\",\n        \"stackTrace\": \"   at System.Net.Http.CurlHandler.ThrowIfCURLEError(CURLcode error)\\n   at System.Net.Http.CurlHandler.MultiAgent.FinishRequest(StrongToWeakReference`1 easyWrapper, CURLcode messageResult)\",\n        \"innerException\": null,\n        \"data\": {},\n        \"errorResponse\": null\n      },\n      \"data\": {},\n      \"errorResponse\": null\n    }\n  },\n  \"correlation\": {\n    \"operation\": \"15364fd1-4dbe7a3d9a7bb369\",\n    \"request\": \"VLGbBQX01xU=\"\n  }\n}"
}
Traceback (most recent call last):
  File "./07.sklearn.hd.py", line 88, in <module>
    run = sk_est.fit()
  File "/home/ninghai/miniconda3/envs/candidate/lib/python3.6/site-packages/azureml/train/estimator.py", line 438, in fit
    return super(Estimator, self).fit()
  File "/home/ninghai/miniconda3/envs/candidate/lib/python3.6/site-packages/azureml/train/estimator.py", line 78, in fit
    _telemetry_values=telemetry_values)
  File "/home/ninghai/miniconda3/envs/candidate/lib/python3.6/site-packages/azureml/core/run.py", line 66, in submit
    execute_with_zip=_execute_with_zip)
  File "/home/ninghai/miniconda3/envs/candidate/lib/python3.6/site-packages/azureml/execution/_commands.py", line 116, in start_run
    execute_with_zip=execute_with_zip)
  File "/home/ninghai/miniconda3/envs/candidate/lib/python3.6/site-packages/azureml/execution/_commands.py", line 383, in _start_internal
    _raise_request_error(response, "starting run")
  File "/home/ninghai/miniconda3/envs/candidate/lib/python3.6/site-packages/azureml/execution/_commands.py", line 729, in _raise_request_error
    raise ExperimentExecutionException(get_http_exception_response_string(response))
azureml.exceptions.azureml_exception.ExperimentExecutionException: {
    "url": "https://eastus2.experiments.azureml.net/execution/v1.0/subscriptions/fac34303-435d-4486-8c3f-7094d82a0b60/resourceGroups/aml-notebooks/providers/Microsoft.MachineLearningServices/workspaces/haieastus2ws3/projects/e2e-07/run",
    "status_code": 500,
    "text": "{\n  \"error\": {\n    \"code\": \"ServiceError\",\n    \"message\": \"InternalServerError\",\n    \"target\": null,\n    \"details\": [],\n    \"innerError\": null,\n    \"debugInfo\": {\n      \"type\": \"System.Net.Http.HttpRequestException\",\n      \"message\": \"An error occurred while sending the request.\",\n      \"stackTrace\": \"   at System.Runtime.ExceptionServices.ExceptionDispatchInfo.Throw()\\n   at System.Runtime.CompilerServices.TaskAwaiter.HandleNonSuccessAndDebuggerNotification(Task task)\\n   at System.Runtime.CompilerServices.ConfiguredTaskAwaitable`1.ConfiguredTaskAwaiter.GetResult()\\n   at System.Net.Http.DiagnosticsHandler.<SendAsync>d__2.MoveNext()\\n--- End of stack trace from previous location where exception was thrown ---\\n   at System.Runtime.ExceptionServices.ExceptionDispatchInfo.Throw()\\n   at System.Runtime.CompilerServices.TaskAwaiter.HandleNonSuccessAndDebuggerNotification(Task task)\\n   at System.Runtime.CompilerServices.ConfiguredTaskAwaitable`1.ConfiguredTaskAwaiter.GetResult()\\n   at System.Net.Http.HttpClient.<FinishSendAsyncBuffered>d__58.MoveNext()\\n--- End of stack trace from previous location where exception was thrown ---\\n   at System.Runtime.ExceptionServices.ExceptionDispatchInfo.Throw()\\n   at System.Runtime.CompilerServices.TaskAwaiter.HandleNonSuccessAndDebuggerNotification(Task task)\\n   at Microsoft.MachineLearning.Common.WebApi.Client.ServiceInvoker.<_Invoke>d__18`1.MoveNext() in /opt/vsts/work/1/s/src/azureml-api/src/Common/WebApi.Client/ServiceInvoker.cs:line 247\\n--- End of stack trace from previous location where exception was thrown ---\\n   at System.Runtime.ExceptionServices.ExceptionDispatchInfo.Throw()\\n   at System.Runtime.CompilerServices.TaskAwaiter.HandleNonSuccessAndDebuggerNotification(Task task)\\n   at Microsoft.MachineLearning.Execution.Services.WorkspaceResourcesRetriever.<GetComputeResourceAndSecrets>d__6.MoveNext() in /opt/vsts/work/1/s/src/azureml-api/src/Execution/Services/WorkspaceResourcesRetriever.cs:line 88\\n--- End of stack trace from previous location where exception was thrown ---\\n   at System.Runtime.ExceptionServices.ExceptionDispatchInfo.Throw()\\n   at System.Runtime.CompilerServices.TaskAwaiter.HandleNonSuccessAndDebuggerNotification(Task task)\\n   at Microsoft.MachineLearning.Execution.Services.StrategyState.<Hydrate>d__59.MoveNext() in /opt/vsts/work/1/s/src/azureml-api/src/Execution/Services/StrategyState.cs:line 156\\n--- End of stack trace from previous location where exception was thrown ---\\n   at System.Runtime.ExceptionServices.ExceptionDispatchInfo.Throw()\\n   at System.Runtime.CompilerServices.TaskAwaiter.HandleNonSuccessAndDebuggerNotification(Task task)\\n   at Microsoft.MachineLearning.Execution.EntryPoints.Api.Controllers.ExecutionController.<MakeStrategyState>d__40.MoveNext() in /opt/vsts/work/1/s/src/azureml-api/src/Execution/EntryPoints/Api/Controllers/ExecutionController.cs:line 691\\n--- End of stack trace from previous location where exception was thrown ---\\n   at System.Runtime.ExceptionServices.ExceptionDispatchInfo.Throw()\\n   at System.Runtime.CompilerServices.TaskAwaiter.HandleNonSuccessAndDebuggerNotification(Task task)\\n   at Microsoft.MachineLearning.Execution.EntryPoints.Api.Controllers.ExecutionController.<StartRun>d__26.MoveNext() in /opt/vsts/work/1/s/src/azureml-api/src/Execution/EntryPoints/Api/Controllers/ExecutionController.cs:line 315\\n--- End of stack trace from previous location where exception was thrown ---\\n   at System.Runtime.ExceptionServices.ExceptionDispatchInfo.Throw()\\n   at System.Runtime.CompilerServices.TaskAwaiter.HandleNonSuccessAndDebuggerNotification(Task task)\\n   at Microsoft.MachineLearning.Execution.EntryPoints.Api.Controllers.ExecutionController.<StartRun>d__22.MoveNext() in /opt/vsts/work/1/s/src/azureml-api/src/Execution/EntryPoints/Api/Controllers/ExecutionController.cs:line 215\\n--- End of stack trace from previous location where exception was thrown ---\\n   at System.Runtime.ExceptionServices.ExceptionDispatchInfo.Throw()\\n   at System.Runtime.CompilerServices.TaskAwaiter.HandleNonSuccessAndDebuggerNotification(Task task)\\n   at lambda_method(Closure , Object )\\n   at Microsoft.AspNetCore.Mvc.Internal.ControllerActionInvoker.<InvokeActionMethodAsync>d__12.MoveNext()\\n--- End of stack trace from previous location where exception was thrown ---\\n   at System.Runtime.ExceptionServices.ExceptionDispatchInfo.Throw()\\n   at System.Runtime.CompilerServices.TaskAwaiter.HandleNonSuccessAndDebuggerNotification(Task task)\\n   at Microsoft.AspNetCore.Mvc.Internal.ControllerActionInvoker.<InvokeNextActionFilterAsync>d__10.MoveNext()\\n--- End of stack trace from previous location where exception was thrown ---\\n   at System.Runtime.ExceptionServices.ExceptionDispatchInfo.Throw()\\n   at Microsoft.AspNetCore.Mvc.Internal.ControllerActionInvoker.Rethrow(ActionExecutedContext context)\\n   at Microsoft.AspNetCore.Mvc.Internal.ControllerActionInvoker.Next(State& next, Scope& scope, Object& state, Boolean& isCompleted)\\n   at Microsoft.AspNetCore.Mvc.Internal.ControllerActionInvoker.<InvokeInnerFilterAsync>d__14.MoveNext()\\n--- End of stack trace from previous location where exception was thrown ---\\n   at System.Runtime.ExceptionServices.ExceptionDispatchInfo.Throw()\\n   at System.Runtime.CompilerServices.TaskAwaiter.HandleNonSuccessAndDebuggerNotification(Task task)\\n   at Microsoft.AspNetCore.Mvc.Internal.ResourceInvoker.<InvokeNextExceptionFilterAsync>d__23.MoveNext()\",\n      \"innerException\": {\n        \"type\": \"System.Net.Http.CurlException\",\n        \"message\": \"Couldn't resolve host name\",\n        \"stackTrace\": \"   at System.Net.Http.CurlHandler.ThrowIfCURLEError(CURLcode error)\\n   at System.Net.Http.CurlHandler.MultiAgent.FinishRequest(StrongToWeakReference`1 easyWrapper, CURLcode messageResult)\",\n        \"innerException\": null,\n        \"data\": {},\n        \"errorResponse\": null\n      },\n      \"data\": {},\n      \"errorResponse\": null\n    }\n  },\n  \"correlation\": {\n    \"operation\": \"d1ba0b62-497ef97aa3f562c4\",\n    \"request\": \"Kg+zzcoXqQE=\"\n  }\n}"
}
Traceback (most recent call last):
  File "./08.tf.hd.py", line 92, in <module>
    run = tfe.fit()
  File "/home/ninghai/miniconda3/envs/candidate/lib/python3.6/site-packages/azureml/train/dnn.py", line 320, in fit
    return super(TensorFlow, self).fit()
  File "/home/ninghai/miniconda3/envs/candidate/lib/python3.6/site-packages/azureml/train/estimator.py", line 78, in fit
    _telemetry_values=telemetry_values)
  File "/home/ninghai/miniconda3/envs/candidate/lib/python3.6/site-packages/azureml/core/run.py", line 66, in submit
    execute_with_zip=_execute_with_zip)
  File "/home/ninghai/miniconda3/envs/candidate/lib/python3.6/site-packages/azureml/execution/_commands.py", line 116, in start_run
    execute_with_zip=execute_with_zip)
  File "/home/ninghai/miniconda3/envs/candidate/lib/python3.6/site-packages/azureml/execution/_commands.py", line 383, in _start_internal
    _raise_request_error(response, "starting run")
  File "/home/ninghai/miniconda3/envs/candidate/lib/python3.6/site-packages/azureml/execution/_commands.py", line 729, in _raise_request_error
    raise ExperimentExecutionException(get_http_exception_response_string(response))
azureml.exceptions.azureml_exception.ExperimentExecutionException: {
    "url": "https://eastus2.experiments.azureml.net/execution/v1.0/subscriptions/fac34303-435d-4486-8c3f-7094d82a0b60/resourceGroups/aml-notebooks/providers/Microsoft.MachineLearningServices/workspaces/haieastus2ws3/projects/e2e-08/run",
    "status_code": 500,
    "text": "{\n  \"error\": {\n    \"code\": \"ServiceError\",\n    \"message\": \"Received 500 from a service request\",\n    \"target\": \"GET https://cert-eastus2.experiments.azureml.net/rp/workspaces/subscriptions/fac34303-435d-4486-8c3f-7094d82a0b60/resourceGroups/aml-notebooks/providers/Microsoft.MachineLearningServices/workspaces/haieastus2ws3/computes/gpucluster\",\n    \"details\": [\n      {\n        \"code\": \"InternalServerError\",\n        \"message\": \"{\\n  \\\"error\\\": {\\n    \\\"code\\\": \\\"ServiceError\\\",\\n    \\\"message\\\": \\\"InternalServerError\\\",\\n    \\\"target\\\": null,\\n    \\\"details\\\": [],\\n    \\\"innerError\\\": null,\\n    \\\"debugInfo\\\": {\\n      \\\"type\\\": \\\"System.Net.Http.HttpRequestException\\\",\\n      \\\"message\\\": \\\"An error occurred while sending the request.\\\",\\n      \\\"stackTrace\\\": \\\"   at System.Runtime.ExceptionServices.ExceptionDispatchInfo.Throw()\\\\n   at System.Runtime.CompilerServices.TaskAwaiter.HandleNonSuccessAndDebuggerNotification(Task task)\\\\n   at System.Runtime.CompilerServices.ConfiguredTaskAwaitable`1.ConfiguredTaskAwaiter.GetResult()\\\\n   at System.Net.Http.DiagnosticsHandler.<SendAsync>d__2.MoveNext()\\\\n--- End of stack trace from previous location where exception was thrown ---\\\\n   at System.Runtime.ExceptionServices.ExceptionDispatchInfo.Throw()\\\\n   at System.Runtime.CompilerServices.TaskAwaiter.HandleNonSuccessAndDebuggerNotification(Task task)\\\\n   at System.Runtime.CompilerServices.ConfiguredTaskAwaitable`1.ConfiguredTaskAwaiter.GetResult()\\\\n   at System.Net.Http.HttpClient.<FinishSendAsyncBuffered>d__58.MoveNext()\\\\n--- End of stack trace from previous location where exception was thrown ---\\\\n   at System.Runtime.ExceptionServices.ExceptionDispatchInfo.Throw()\\\\n   at System.Runtime.CompilerServices.TaskAwaiter.HandleNonSuccessAndDebuggerNotification(Task task)\\\\n   at Microsoft.MachineLearning.AccountRP.Services.ComputeResourceClient.<GetComputeAsync>d__19.MoveNext() in /opt/vsts/work/1/s/src/azureml-api/src/AccountResourceProvider/Services/ComputeResourceClient.cs:line 161\\\\n--- End of stack trace from previous location where exception was thrown ---\\\\n   at System.Runtime.ExceptionServices.ExceptionDispatchInfo.Throw()\\\\n   at System.Runtime.CompilerServices.TaskAwaiter.HandleNonSuccessAndDebuggerNotification(Task task)\\\\n   at Microsoft.MachineLearning.AccountRP.EntryPoints.Api.Controllers.ComputeResourceController.<GetComputeAsync>d__5.MoveNext() in /opt/vsts/work/1/s/src/azureml-api/src/AccountResourceProvider/EntryPoints/Api/Controller/ComputeResourceController.cs:line 63\\\\n--- End of stack trace from previous location where exception was thrown ---\\\\n   at System.Runtime.ExceptionServices.ExceptionDispatchInfo.Throw()\\\\n   at System.Runtime.CompilerServices.TaskAwaiter.HandleNonSuccessAndDebuggerNotification(Task task)\\\\n   at Microsoft.AspNetCore.Mvc.Internal.ControllerActionInvoker.<InvokeActionMethodAsync>d__12.MoveNext()\\\\n--- End of stack trace from previous location where exception was thrown ---\\\\n   at System.Runtime.ExceptionServices.ExceptionDispatchInfo.Throw()\\\\n   at System.Runtime.CompilerServices.TaskAwaiter.HandleNonSuccessAndDebuggerNotification(Task task)\\\\n   at Microsoft.AspNetCore.Mvc.Internal.ControllerActionInvoker.<InvokeNextActionFilterAsync>d__10.MoveNext()\\\\n--- End of stack trace from previous location where exception was thrown ---\\\\n   at System.Runtime.ExceptionServices.ExceptionDispatchInfo.Throw()\\\\n   at Microsoft.AspNetCore.Mvc.Internal.ControllerActionInvoker.Rethrow(ActionExecutedContext context)\\\\n   at Microsoft.AspNetCore.Mvc.Internal.ControllerActionInvoker.Next(State& next, Scope& scope, Object& state, Boolean& isCompleted)\\\\n   at Microsoft.AspNetCore.Mvc.Internal.ControllerActionInvoker.<InvokeInnerFilterAsync>d__14.MoveNext()\\\\n--- End of stack trace from previous location where exception was thrown ---\\\\n   at System.Runtime.ExceptionServices.ExceptionDispatchInfo.Throw()\\\\n   at System.Runtime.CompilerServices.TaskAwaiter.HandleNonSuccessAndDebuggerNotification(Task task)\\\\n   at Microsoft.AspNetCore.Mvc.Internal.ResourceInvoker.<InvokeNextExceptionFilterAsync>d__23.MoveNext()\\\",\\n      \\\"innerException\\\": {\\n        \\\"type\\\": \\\"System.Net.Http.CurlException\\\",\\n        \\\"message\\\": \\\"Couldn't resolve host name\\\",\\n        \\\"stackTrace\\\": \\\"   at System.Net.Http.CurlHandler.ThrowIfCURLEError(CURLcode error)\\\\n   at System.Net.Http.CurlHandler.MultiAgent.FinishRequest(StrongToWeakReference`1 easyWrapper, CURLcode messageResult)\\\",\\n        \\\"innerException\\\": null,\\n        \\\"data\\\": {},\\n        \\\"errorResponse\\\": null\\n      },\\n      \\\"data\\\": {},\\n      \\\"errorResponse\\\": null\\n    }\\n  },\\n  \\\"correlation\\\": {\\n    \\\"operation\\\": \\\"30a97879-4406832514f354ce\\\",\\n    \\\"request\\\": \\\"mOXIrnss5eY=\\\"\\n  }\\n}\",\n        \"target\": null\n      }\n    ],\n    \"innerError\": null,\n    \"debugInfo\": {\n      \"type\": \"Microsoft.MachineLearning.Common.Core.ServiceInvocationException\",\n      \"message\": \"Service invocation failed!\\r\\nRequest: GET https://cert-eastus2.experiments.azureml.net/rp/workspaces/subscriptions/fac34303-435d-4486-8c3f-7094d82a0b60/resourceGroups/aml-notebooks/providers/Microsoft.MachineLearningServices/workspaces/haieastus2ws3/computes/gpucluster\\r\\nStatus Code: 500 InternalServerError\\r\\nReason Phrase: InternalServerError\\r\\nResponse Body: {\\n  \\\"error\\\": {\\n    \\\"code\\\": \\\"ServiceError\\\",\\n    \\\"message\\\": \\\"InternalServerError\\\",\\n    \\\"target\\\": null,\\n    \\\"details\\\": [],\\n    \\\"innerError\\\": null,\\n    \\\"debugInfo\\\": {\\n      \\\"type\\\": \\\"System.Net.Http.HttpRequestException\\\",\\n      \\\"message\\\": \\\"An error occurred while sending the request.\\\",\\n      \\\"stackTrace\\\": \\\"   at System.Runtime.ExceptionServices.ExceptionDispatchInfo.Throw()\\\\n   at System.Runtime.CompilerServices.TaskAwaiter.HandleNonSuccessAndDebuggerNotification(Task task)\\\\n   at System.Runtime.CompilerServices.ConfiguredTaskAwaitable`1.ConfiguredTaskAwaiter.GetResult()\\\\n   at System.Net.Http.DiagnosticsHandler.<SendAsync>d__2.MoveNext()\\\\n--- End of stack trace from previous location where exception was thrown ---\\\\n   at System.Runtime.ExceptionServices.ExceptionDispatchInfo.Throw()\\\\n   at System.Runtime.CompilerServices.TaskAwaiter.HandleNonSuccessAndDebuggerNotification(Task task)\\\\n   at System.Runtime.CompilerServices.ConfiguredTaskAwaitable`1.ConfiguredTaskAwaiter.GetResult()\\\\n   at System.Net.Http.HttpClient.<FinishSendAsyncBuffered>d__58.MoveNext()\\\\n--- End of stack trace from previous location where exception was thrown ---\\\\n   at System.Runtime.ExceptionServices.ExceptionDispatchInfo.Throw()\\\\n   at System.Runtime.CompilerServices.TaskAwaiter.HandleNonSuccessAndDebuggerNotification(Task task)\\\\n   at Microsoft.MachineLearning.AccountRP.Services.ComputeResourceClient.<GetComputeAsync>d__19.MoveNext() in /opt/vsts/work/1/s/src/azureml-api/src/AccountResourceProvider/Services/ComputeResourceClient.cs:line 161\\\\n--- End of stack trace from previous location where exception was thrown ---\\\\n   at System.Runtime.ExceptionServices.ExceptionDispatchInfo.Throw()\\\\n   at System.Runtime.CompilerServices.TaskAwaiter.HandleNonSuccessAndDebuggerNotification(Task task)\\\\n   at Microsoft.MachineLearning.AccountRP.EntryPoints.Api.Controllers.ComputeResourceController.<GetComputeAsync>d__5.MoveNext() in /opt/vsts/work/1/s/src/azureml-api/src/AccountResourceProvider/EntryPoints/Api/Controller/ComputeResourceController.cs:line 63\\\\n--- End of stack trace from previous location where exception was thrown ---\\\\n   at System.Runtime.ExceptionServices.ExceptionDispatchInfo.Throw()\\\\n   at System.Runtime.CompilerServices.TaskAwaiter.HandleNonSuccessAndDebuggerNotification(Task task)\\\\n   at Microsoft.AspNetCore.Mvc.Internal.ControllerActionInvoker.<InvokeActionMethodAsync>d__12.MoveNext()\\\\n--- End of stack trace from previous location where exception was thrown ---\\\\n   at System.Runtime.ExceptionServices.ExceptionDispatchInfo.Throw()\\\\n   at System.Runtime.CompilerServices.TaskAwaiter.HandleNonSuccessAndDebuggerNotification(Task task)\\\\n   at Microsoft.AspNetCore.Mvc.Internal.ControllerActionInvoker.<InvokeNextActionFilterAsync>d__10.MoveNext()\\\\n--- End of stack trace from previous location where exception was thrown ---\\\\n   at System.Runtime.ExceptionServices.ExceptionDispatchInfo.Throw()\\\\n   at Microsoft.AspNetCore.Mvc.Internal.ControllerActionInvoker.Rethrow(ActionExecutedContext context)\\\\n   at Microsoft.AspNetCore.Mvc.Internal.ControllerActionInvoker.Next(State& next, Scope& scope, Object& state, Boolean& isCompleted)\\\\n   at Microsoft.AspNetCore.Mvc.Internal.ControllerActionInvoker.<InvokeInnerFilterAsync>d__14.MoveNext()\\\\n--- End of stack trace from previous location where exception was thrown ---\\\\n   at System.Runtime.ExceptionServices.ExceptionDispatchInfo.Throw()\\\\n   at System.Runtime.CompilerServices.TaskAwaiter.HandleNonSuccessAndDebuggerNotification(Task task)\\\\n   at Microsoft.AspNetCore.Mvc.Internal.ResourceInvoker.<InvokeNextExceptionFilterAsync>d__23.MoveNext()\\\",\\n      \\\"innerException\\\": {\\n        \\\"type\\\": \\\"System.Net.Http.CurlException\\\",\\n        \\\"message\\\": \\\"Couldn't resolve host name\\\",\\n        \\\"stackTrace\\\": \\\"   at System.Net.Http.CurlHandler.ThrowIfCURLEError(CURLcode error)\\\\n   at System.Net.Http.CurlHandler.MultiAgent.FinishRequest(StrongToWeakReference`1 easyWrapper, CURLcode messageResult)\\\",\\n        \\\"innerException\\\": null,\\n        \\\"data\\\": {},\\n        \\\"errorResponse\\\": null\\n      },\\n      \\\"data\\\": {},\\n      \\\"errorResponse\\\": null\\n    }\\n  },\\n  \\\"correlation\\\": {\\n    \\\"operation\\\": \\\"30a97879-4406832514f354ce\\\",\\n    \\\"request\\\": \\\"mOXIrnss5eY=\\\"\\n  }\\n}\",\n      \"stackTrace\": \"   at Microsoft.MachineLearning.Common.WebApi.Client.ServiceInvoker.<_Invoke>d__18`1.MoveNext()\\n--- End of stack trace from previous location where exception was thrown ---\\n   at System.Runtime.ExceptionServices.ExceptionDispatchInfo.Throw()\\n   at System.Runtime.CompilerServices.TaskAwaiter.HandleNonSuccessAndDebuggerNotification(Task task)\\n   at Microsoft.MachineLearning.Execution.Services.WorkspaceResourcesRetriever.<GetComputeResourceAndSecrets>d__6.MoveNext() in /opt/vsts/work/1/s/src/azureml-api/src/Execution/Services/WorkspaceResourcesRetriever.cs:line 88\\n--- End of stack trace from previous location where exception was thrown ---\\n   at System.Runtime.ExceptionServices.ExceptionDispatchInfo.Throw()\\n   at System.Runtime.CompilerServices.TaskAwaiter.HandleNonSuccessAndDebuggerNotification(Task task)\\n   at Microsoft.MachineLearning.Execution.Services.StrategyState.<Hydrate>d__59.MoveNext() in /opt/vsts/work/1/s/src/azureml-api/src/Execution/Services/StrategyState.cs:line 156\\n--- End of stack trace from previous location where exception was thrown ---\\n   at System.Runtime.ExceptionServices.ExceptionDispatchInfo.Throw()\\n   at System.Runtime.CompilerServices.TaskAwaiter.HandleNonSuccessAndDebuggerNotification(Task task)\\n   at Microsoft.MachineLearning.Execution.EntryPoints.Api.Controllers.ExecutionController.<MakeStrategyState>d__40.MoveNext() in /opt/vsts/work/1/s/src/azureml-api/src/Execution/EntryPoints/Api/Controllers/ExecutionController.cs:line 691\\n--- End of stack trace from previous location where exception was thrown ---\\n   at System.Runtime.ExceptionServices.ExceptionDispatchInfo.Throw()\\n   at System.Runtime.CompilerServices.TaskAwaiter.HandleNonSuccessAndDebuggerNotification(Task task)\\n   at Microsoft.MachineLearning.Execution.EntryPoints.Api.Controllers.ExecutionController.<StartRun>d__26.MoveNext() in /opt/vsts/work/1/s/src/azureml-api/src/Execution/EntryPoints/Api/Controllers/ExecutionController.cs:line 315\\n--- End of stack trace from previous location where exception was thrown ---\\n   at System.Runtime.ExceptionServices.ExceptionDispatchInfo.Throw()\\n   at System.Runtime.CompilerServices.TaskAwaiter.HandleNonSuccessAndDebuggerNotification(Task task)\\n   at Microsoft.MachineLearning.Execution.EntryPoints.Api.Controllers.ExecutionController.<StartRun>d__22.MoveNext() in /opt/vsts/work/1/s/src/azureml-api/src/Execution/EntryPoints/Api/Controllers/ExecutionController.cs:line 215\\n--- End of stack trace from previous location where exception was thrown ---\\n   at System.Runtime.ExceptionServices.ExceptionDispatchInfo.Throw()\\n   at System.Runtime.CompilerServices.TaskAwaiter.HandleNonSuccessAndDebuggerNotification(Task task)\\n   at lambda_method(Closure , Object )\\n   at Microsoft.AspNetCore.Mvc.Internal.ControllerActionInvoker.<InvokeActionMethodAsync>d__12.MoveNext()\\n--- End of stack trace from previous location where exception was thrown ---\\n   at System.Runtime.ExceptionServices.ExceptionDispatchInfo.Throw()\\n   at System.Runtime.CompilerServices.TaskAwaiter.HandleNonSuccessAndDebuggerNotification(Task task)\\n   at Microsoft.AspNetCore.Mvc.Internal.ControllerActionInvoker.<InvokeNextActionFilterAsync>d__10.MoveNext()\\n--- End of stack trace from previous location where exception was thrown ---\\n   at System.Runtime.ExceptionServices.ExceptionDispatchInfo.Throw()\\n   at Microsoft.AspNetCore.Mvc.Internal.ControllerActionInvoker.Rethrow(ActionExecutedContext context)\\n   at Microsoft.AspNetCore.Mvc.Internal.ControllerActionInvoker.Next(State& next, Scope& scope, Object& state, Boolean& isCompleted)\\n   at Microsoft.AspNetCore.Mvc.Internal.ControllerActionInvoker.<InvokeInnerFilterAsync>d__14.MoveNext()\\n--- End of stack trace from previous location where exception was thrown ---\\n   at System.Runtime.ExceptionServices.ExceptionDispatchInfo.Throw()\\n   at System.Runtime.CompilerServices.TaskAwaiter.HandleNonSuccessAndDebuggerNotification(Task task)\\n   at Microsoft.AspNetCore.Mvc.Internal.ResourceInvoker.<InvokeNextExceptionFilterAsync>d__23.MoveNext()\",\n      \"innerException\": null,\n      \"data\": {},\n      \"errorResponse\": {\n        \"error\": {\n          \"code\": \"ServiceError\",\n          \"message\": \"InternalServerError\",\n          \"target\": null,\n          \"details\": [],\n          \"innerError\": null,\n          \"debugInfo\": {\n            \"type\": \"System.Net.Http.HttpRequestException\",\n            \"message\": \"An error occurred while sending the request.\",\n            \"stackTrace\": \"   at System.Runtime.ExceptionServices.ExceptionDispatchInfo.Throw()\\n   at System.Runtime.CompilerServices.TaskAwaiter.HandleNonSuccessAndDebuggerNotification(Task task)\\n   at System.Runtime.CompilerServices.ConfiguredTaskAwaitable`1.ConfiguredTaskAwaiter.GetResult()\\n   at System.Net.Http.DiagnosticsHandler.<SendAsync>d__2.MoveNext()\\n--- End of stack trace from previous location where exception was thrown ---\\n   at System.Runtime.ExceptionServices.ExceptionDispatchInfo.Throw()\\n   at System.Runtime.CompilerServices.TaskAwaiter.HandleNonSuccessAndDebuggerNotification(Task task)\\n   at System.Runtime.CompilerServices.ConfiguredTaskAwaitable`1.ConfiguredTaskAwaiter.GetResult()\\n   at System.Net.Http.HttpClient.<FinishSendAsyncBuffered>d__58.MoveNext()\\n--- End of stack trace from previous location where exception was thrown ---\\n   at System.Runtime.ExceptionServices.ExceptionDispatchInfo.Throw()\\n   at System.Runtime.CompilerServices.TaskAwaiter.HandleNonSuccessAndDebuggerNotification(Task task)\\n   at Microsoft.MachineLearning.AccountRP.Services.ComputeResourceClient.<GetComputeAsync>d__19.MoveNext() in /opt/vsts/work/1/s/src/azureml-api/src/AccountResourceProvider/Services/ComputeResourceClient.cs:line 161\\n--- End of stack trace from previous location where exception was thrown ---\\n   at System.Runtime.ExceptionServices.ExceptionDispatchInfo.Throw()\\n   at System.Runtime.CompilerServices.TaskAwaiter.HandleNonSuccessAndDebuggerNotification(Task task)\\n   at Microsoft.MachineLearning.AccountRP.EntryPoints.Api.Controllers.ComputeResourceController.<GetComputeAsync>d__5.MoveNext() in /opt/vsts/work/1/s/src/azureml-api/src/AccountResourceProvider/EntryPoints/Api/Controller/ComputeResourceController.cs:line 63\\n--- End of stack trace from previous location where exception was thrown ---\\n   at System.Runtime.ExceptionServices.ExceptionDispatchInfo.Throw()\\n   at System.Runtime.CompilerServices.TaskAwaiter.HandleNonSuccessAndDebuggerNotification(Task task)\\n   at Microsoft.AspNetCore.Mvc.Internal.ControllerActionInvoker.<InvokeActionMethodAsync>d__12.MoveNext()\\n--- End of stack trace from previous location where exception was thrown ---\\n   at System.Runtime.ExceptionServices.ExceptionDispatchInfo.Throw()\\n   at System.Runtime.CompilerServices.TaskAwaiter.HandleNonSuccessAndDebuggerNotification(Task task)\\n   at Microsoft.AspNetCore.Mvc.Internal.ControllerActionInvoker.<InvokeNextActionFilterAsync>d__10.MoveNext()\\n--- End of stack trace from previous location where exception was thrown ---\\n   at System.Runtime.ExceptionServices.ExceptionDispatchInfo.Throw()\\n   at Microsoft.AspNetCore.Mvc.Internal.ControllerActionInvoker.Rethrow(ActionExecutedContext context)\\n   at Microsoft.AspNetCore.Mvc.Internal.ControllerActionInvoker.Next(State& next, Scope& scope, Object& state, Boolean& isCompleted)\\n   at Microsoft.AspNetCore.Mvc.Internal.ControllerActionInvoker.<InvokeInnerFilterAsync>d__14.MoveNext()\\n--- End of stack trace from previous location where exception was thrown ---\\n   at System.Runtime.ExceptionServices.ExceptionDispatchInfo.Throw()\\n   at System.Runtime.CompilerServices.TaskAwaiter.HandleNonSuccessAndDebuggerNotification(Task task)\\n   at Microsoft.AspNetCore.Mvc.Internal.ResourceInvoker.<InvokeNextExceptionFilterAsync>d__23.MoveNext()\",\n            \"innerException\": {\n              \"type\": \"System.Net.Http.CurlException\",\n              \"message\": \"Couldn't resolve host name\",\n              \"stackTrace\": \"   at System.Net.Http.CurlHandler.ThrowIfCURLEError(CURLcode error)\\n   at System.Net.Http.CurlHandler.MultiAgent.FinishRequest(StrongToWeakReference`1 easyWrapper, CURLcode messageResult)\",\n              \"innerException\": null,\n              \"data\": {},\n              \"errorResponse\": null\n            },\n            \"data\": {},\n            \"errorResponse\": null\n          }\n        },\n        \"correlation\": {\n          \"operation\": \"30a97879-4406832514f354ce\",\n          \"request\": \"mOXIrnss5eY=\"\n        }\n      }\n    }\n  },\n  \"correlation\": {\n    \"operation\": \"30a97879-4406832514f354ce\",\n    \"request\": \"osKIJBC9Qjk=\"\n  }\n}"
}
Client-Request-ID=60c87fa8-68c5-11e8-9288-000d3a71b7c3 Retry policy did not allow for a retry: Server-Timestamp=Tue, 05 Jun 2018 13:35:57 GMT, Server-Request-ID=de6df14a-901e-011d-0dd2-fccb8e000000, HTTP status code=409, Exception=The specified container already exists.ErrorCode: ContainerAlreadyExists<?xml version="1.0" encoding="utf-8"?><Error><Code>ContainerAlreadyExists</Code><Message>The specified container already exists.RequestId:de6df14a-901e-011d-0dd2-fccb8e000000Time:2018-06-05T13:35:57.7450734Z</Message></Error>.
Client-Request-ID=60c87faa-68c5-11e8-9288-000d3a71b7c3 Retry policy did not allow for a retry: Server-Timestamp=Tue, 05 Jun 2018 13:35:57 GMT, Server-Request-ID=75905a77-501e-00c8-24d2-fcc506000000, HTTP status code=409, Exception=The specified container already exists.ErrorCode: ContainerAlreadyExists<?xml version="1.0" encoding="utf-8"?><Error><Code>ContainerAlreadyExists</Code><Message>The specified container already exists.RequestId:75905a77-501e-00c8-24d2-fcc506000000Time:2018-06-05T13:35:57.9153421Z</Message></Error>.
Client-Request-ID=60c87fac-68c5-11e8-9288-000d3a71b7c3 Retry policy did not allow for a retry: Server-Timestamp=Tue, 05 Jun 2018 13:35:58 GMT, Server-Request-ID=4c681a72-a01e-00d6-69d2-fc1feb000000, HTTP status code=409, Exception=The specified container already exists.ErrorCode: ContainerAlreadyExists<?xml version="1.0" encoding="utf-8"?><Error><Code>ContainerAlreadyExists</Code><Message>The specified container already exists.RequestId:4c681a72-a01e-00d6-69d2-fc1feb000000Time:2018-06-05T13:35:58.5656995Z</Message></Error>.
Client-Request-ID=60c87fae-68c5-11e8-9288-000d3a71b7c3 Retry policy did not allow for a retry: Server-Timestamp=Tue, 05 Jun 2018 13:35:58 GMT, Server-Request-ID=edbf2ffa-601e-0025-0ad2-fccc82000000, HTTP status code=409, Exception=The specified container already exists.ErrorCode: ContainerAlreadyExists<?xml version="1.0" encoding="utf-8"?><Error><Code>ContainerAlreadyExists</Code><Message>The specified container already exists.RequestId:edbf2ffa-601e-0025-0ad2-fccc82000000Time:2018-06-05T13:35:58.8119042Z</Message></Error>.
Traceback (most recent call last):
  File "./10.o16n.py", line 64, in <module>
    image = image)
  File "/home/ninghai/miniconda3/envs/candidate/lib/python3.6/site-packages/azureml/core/workspace.py", line 786, in deploy_webservice
    'creation state.'.format(image.id))
azureml.exceptions.azureml_exception.WebserviceException: Unable to create service with image myimage:26 in non "Succeeded" creation state.
error: Your local changes to the following files would be overwritten by checkout:
	e2e_test/aml_config/config.json
Please, commit your changes or stash them before you can switch branches.
Aborting
