Already on 'master'
ERROR:azure.storage.common.storageclient:Client-Request-ID=1a3b5b60-7508-11e8-9288-000d3a71b7c3 Retry policy did not allow for a retry: Server-Timestamp=Thu, 21 Jun 2018 04:03:49 GMT, Server-Request-ID=34ba31db-401e-0117-2714-09dd52000000, HTTP status code=409, Exception=The specified container already exists.ErrorCode: ContainerAlreadyExists<?xml version="1.0" encoding="utf-8"?><Error><Code>ContainerAlreadyExists</Code><Message>The specified container already exists.RequestId:34ba31db-401e-0117-2714-09dd52000000Time:2018-06-21T04:03:49.6215003Z</Message></Error>.
ERROR:azure.storage.common.storageclient:Client-Request-ID=1a3b5b62-7508-11e8-9288-000d3a71b7c3 Retry policy did not allow for a retry: Server-Timestamp=Thu, 21 Jun 2018 04:03:49 GMT, Server-Request-ID=d34ee938-301e-009f-2314-0923de000000, HTTP status code=409, Exception=The specified container already exists.ErrorCode: ContainerAlreadyExists<?xml version="1.0" encoding="utf-8"?><Error><Code>ContainerAlreadyExists</Code><Message>The specified container already exists.RequestId:d34ee938-301e-009f-2314-0923de000000Time:2018-06-21T04:03:49.8049409Z</Message></Error>.
ERROR:azure.storage.common.storageclient:Client-Request-ID=1a3b5b64-7508-11e8-9288-000d3a71b7c3 Retry policy did not allow for a retry: Server-Timestamp=Thu, 21 Jun 2018 04:03:49 GMT, Server-Request-ID=76767803-201e-00a2-6914-0996f8000000, HTTP status code=409, Exception=The specified container already exists.ErrorCode: ContainerAlreadyExists<?xml version="1.0" encoding="utf-8"?><Error><Code>ContainerAlreadyExists</Code><Message>The specified container already exists.RequestId:76767803-201e-00a2-6914-0996f8000000Time:2018-06-21T04:03:49.9691365Z</Message></Error>.
ERROR:azure.storage.common.storageclient:Client-Request-ID=1a3b5b66-7508-11e8-9288-000d3a71b7c3 Retry policy did not allow for a retry: Server-Timestamp=Thu, 21 Jun 2018 04:03:49 GMT, Server-Request-ID=3c9b04e0-201e-002a-0a14-092e21000000, HTTP status code=409, Exception=The specified container already exists.ErrorCode: ContainerAlreadyExists<?xml version="1.0" encoding="utf-8"?><Error><Code>ContainerAlreadyExists</Code><Message>The specified container already exists.RequestId:3c9b04e0-201e-002a-0a14-092e21000000Time:2018-06-21T04:03:50.1340446Z</Message></Error>.
Traceback (most recent call last):
  File "./02.local.py", line 51, in <module>
    script_to_run = train_script)
  File "/home/ninghai/miniconda3/envs/preview/lib/python3.6/site-packages/azureml/core/run.py", line 64, in submit
    return _commands.start_run(project_object, run_config_object, telemetry_values=_telemetry_values)
  File "/home/ninghai/miniconda3/envs/preview/lib/python3.6/site-packages/azureml/execution/_commands.py", line 109, in start_run
    telemetry_values=telemetry_values)
  File "/home/ninghai/miniconda3/envs/preview/lib/python3.6/site-packages/azureml/execution/_commands.py", line 272, in _start_internal_local_cloud
    snapshot_id = snapshot_async.get() if snapshot_async else None
  File "/home/ninghai/miniconda3/envs/preview/lib/python3.6/multiprocessing/pool.py", line 644, in get
    raise self._value
  File "/home/ninghai/miniconda3/envs/preview/lib/python3.6/multiprocessing/pool.py", line 119, in worker
    result = (True, func(*args, **kwds))
  File "/home/ninghai/miniconda3/envs/preview/lib/python3.6/site-packages/azureml/base_sdk_common/create_snapshot.py", line 129, in create_snapshot
    raise SnapshotException(get_http_exception_response_string(response))
azureml.exceptions.azureml_exception.SnapshotException: {
    "status_code": 404,
    "text": {
        "correlation": {
            "operation": "e87ca6d4-4dafe5d5581f0658",
            "request": "HZElTXZSXJI="
        },
        "error": {
            "code": "UserError",
            "debugInfo": {
                "data": {},
                "errorResponse": null,
                "innerException": null,
                "message": "Unable to find snapshot with id: 2bd3167f-0978-42bd-9795-6c89fc1e31b2",
                "stackTrace": "   at Microsoft.MachineLearning.Project.Services.SnapshotStore.<GetBlobAsStringOrFailNotFound>d__17.MoveNext() in /opt/vsts/work/1/s/src/azureml-api/src/ProjectContent/Services/SnapshotStore.cs:line 271\n--- End of stack trace from previous location where exception was thrown ---\n   at System.Runtime.ExceptionServices.ExceptionDispatchInfo.Throw()\n   at System.Runtime.CompilerServices.TaskAwaiter.HandleNonSuccessAndDebuggerNotification(Task task)\n   at Microsoft.MachineLearning.Project.Services.SnapshotStore.<GetSnapshot>d__7.MoveNext() in /opt/vsts/work/1/s/src/azureml-api/src/ProjectContent/Services/SnapshotStore.cs:line 113\n--- End of stack trace from previous location where exception was thrown ---\n   at System.Runtime.ExceptionServices.ExceptionDispatchInfo.Throw()\n   at System.Runtime.CompilerServices.TaskAwaiter.HandleNonSuccessAndDebuggerNotification(Task task)\n   at Microsoft.MachineLearning.ProjectContent.EntryPoints.Controllers.SnapshotController.<CreateSnapshot>d__12.MoveNext() in /opt/vsts/work/1/s/src/azureml-api/src/ProjectContent/EntryPoints/Controllers/SnapshotController.cs:line 212\n--- End of stack trace from previous location where exception was thrown ---\n   at System.Runtime.ExceptionServices.ExceptionDispatchInfo.Throw()\n   at System.Runtime.CompilerServices.TaskAwaiter.HandleNonSuccessAndDebuggerNotification(Task task)\n   at Microsoft.AspNetCore.Mvc.Internal.ControllerActionInvoker.<InvokeActionMethodAsync>d__12.MoveNext()\n--- End of stack trace from previous location where exception was thrown ---\n   at System.Runtime.ExceptionServices.ExceptionDispatchInfo.Throw()\n   at System.Runtime.CompilerServices.TaskAwaiter.HandleNonSuccessAndDebuggerNotification(Task task)\n   at Microsoft.AspNetCore.Mvc.Internal.ControllerActionInvoker.<InvokeNextActionFilterAsync>d__10.MoveNext()\n--- End of stack trace from previous location where exception was thrown ---\n   at System.Runtime.ExceptionServices.ExceptionDispatchInfo.Throw()\n   at Microsoft.AspNetCore.Mvc.Internal.ControllerActionInvoker.Rethrow(ActionExecutedContext context)\n   at Microsoft.AspNetCore.Mvc.Internal.ControllerActionInvoker.Next(State& next, Scope& scope, Object& state, Boolean& isCompleted)\n   at Microsoft.AspNetCore.Mvc.Internal.ControllerActionInvoker.<InvokeInnerFilterAsync>d__14.MoveNext()\n--- End of stack trace from previous location where exception was thrown ---\n   at System.Runtime.ExceptionServices.ExceptionDispatchInfo.Throw()\n   at System.Runtime.CompilerServices.TaskAwaiter.HandleNonSuccessAndDebuggerNotification(Task task)\n   at Microsoft.AspNetCore.Mvc.Internal.ResourceInvoker.<InvokeNextExceptionFilterAsync>d__23.MoveNext()",
                "type": "Common.WebApi.Exceptions.ResourceNotFoundException"
            },
            "details": [],
            "innerError": null,
            "message": "Unable to find snapshot with id: 2bd3167f-0978-42bd-9795-6c89fc1e31b2",
            "target": null
        }
    },
    "url": "https://eastus2.experiments.azureml.net/content/v1.0/subscriptions/fac34303-435d-4486-8c3f-7094d82a0b60/resourceGroups/aml-notebooks/providers/Microsoft.MachineLearningServices/workspaces/haieastus2ws3/snapshots/97ca69a1-1843-4cf0-ab00-94aadebbe7d4?parentSnapshotId=2bd3167f-0978-42bd-9795-6c89fc1e31b2"
}
Traceback (most recent call last):
  File "./03.aci.py", line 85, in <module>
    script_to_run = train_script)
  File "/home/ninghai/miniconda3/envs/preview/lib/python3.6/site-packages/azureml/core/run.py", line 64, in submit
    return _commands.start_run(project_object, run_config_object, telemetry_values=_telemetry_values)
  File "/home/ninghai/miniconda3/envs/preview/lib/python3.6/site-packages/azureml/execution/_commands.py", line 114, in start_run
    telemetry_values=telemetry_values)
  File "/home/ninghai/miniconda3/envs/preview/lib/python3.6/site-packages/azureml/execution/_commands.py", line 381, in _start_internal
    snapshot_id = snapshot_async.get() if snapshot_async else None
  File "/home/ninghai/miniconda3/envs/preview/lib/python3.6/multiprocessing/pool.py", line 644, in get
    raise self._value
  File "/home/ninghai/miniconda3/envs/preview/lib/python3.6/multiprocessing/pool.py", line 119, in worker
    result = (True, func(*args, **kwds))
  File "/home/ninghai/miniconda3/envs/preview/lib/python3.6/site-packages/azureml/base_sdk_common/create_snapshot.py", line 129, in create_snapshot
    raise SnapshotException(get_http_exception_response_string(response))
azureml.exceptions.azureml_exception.SnapshotException: {
    "status_code": 404,
    "text": {
        "correlation": {
            "operation": "48bafd28-4152fc13217d2006",
            "request": "zfn5qC5tLh8="
        },
        "error": {
            "code": "UserError",
            "debugInfo": {
                "data": {},
                "errorResponse": null,
                "innerException": null,
                "message": "Unable to find snapshot with id: b8317c26-6671-44a6-9859-67a0a7be6afa",
                "stackTrace": "   at Microsoft.MachineLearning.Project.Services.SnapshotStore.<GetBlobAsStringOrFailNotFound>d__17.MoveNext() in /opt/vsts/work/1/s/src/azureml-api/src/ProjectContent/Services/SnapshotStore.cs:line 271\n--- End of stack trace from previous location where exception was thrown ---\n   at System.Runtime.ExceptionServices.ExceptionDispatchInfo.Throw()\n   at System.Runtime.CompilerServices.TaskAwaiter.HandleNonSuccessAndDebuggerNotification(Task task)\n   at Microsoft.MachineLearning.Project.Services.SnapshotStore.<GetSnapshot>d__7.MoveNext() in /opt/vsts/work/1/s/src/azureml-api/src/ProjectContent/Services/SnapshotStore.cs:line 113\n--- End of stack trace from previous location where exception was thrown ---\n   at System.Runtime.ExceptionServices.ExceptionDispatchInfo.Throw()\n   at System.Runtime.CompilerServices.TaskAwaiter.HandleNonSuccessAndDebuggerNotification(Task task)\n   at Microsoft.MachineLearning.ProjectContent.EntryPoints.Controllers.SnapshotController.<CreateSnapshot>d__12.MoveNext() in /opt/vsts/work/1/s/src/azureml-api/src/ProjectContent/EntryPoints/Controllers/SnapshotController.cs:line 212\n--- End of stack trace from previous location where exception was thrown ---\n   at System.Runtime.ExceptionServices.ExceptionDispatchInfo.Throw()\n   at System.Runtime.CompilerServices.TaskAwaiter.HandleNonSuccessAndDebuggerNotification(Task task)\n   at Microsoft.AspNetCore.Mvc.Internal.ControllerActionInvoker.<InvokeActionMethodAsync>d__12.MoveNext()\n--- End of stack trace from previous location where exception was thrown ---\n   at System.Runtime.ExceptionServices.ExceptionDispatchInfo.Throw()\n   at System.Runtime.CompilerServices.TaskAwaiter.HandleNonSuccessAndDebuggerNotification(Task task)\n   at Microsoft.AspNetCore.Mvc.Internal.ControllerActionInvoker.<InvokeNextActionFilterAsync>d__10.MoveNext()\n--- End of stack trace from previous location where exception was thrown ---\n   at System.Runtime.ExceptionServices.ExceptionDispatchInfo.Throw()\n   at Microsoft.AspNetCore.Mvc.Internal.ControllerActionInvoker.Rethrow(ActionExecutedContext context)\n   at Microsoft.AspNetCore.Mvc.Internal.ControllerActionInvoker.Next(State& next, Scope& scope, Object& state, Boolean& isCompleted)\n   at Microsoft.AspNetCore.Mvc.Internal.ControllerActionInvoker.<InvokeInnerFilterAsync>d__14.MoveNext()\n--- End of stack trace from previous location where exception was thrown ---\n   at System.Runtime.ExceptionServices.ExceptionDispatchInfo.Throw()\n   at System.Runtime.CompilerServices.TaskAwaiter.HandleNonSuccessAndDebuggerNotification(Task task)\n   at Microsoft.AspNetCore.Mvc.Internal.ResourceInvoker.<InvokeNextExceptionFilterAsync>d__23.MoveNext()",
                "type": "Common.WebApi.Exceptions.ResourceNotFoundException"
            },
            "details": [],
            "innerError": null,
            "message": "Unable to find snapshot with id: b8317c26-6671-44a6-9859-67a0a7be6afa",
            "target": null
        }
    },
    "url": "https://eastus2.experiments.azureml.net/content/v1.0/subscriptions/fac34303-435d-4486-8c3f-7094d82a0b60/resourceGroups/aml-notebooks/providers/Microsoft.MachineLearningServices/workspaces/haieastus2ws3/snapshots/c0a897d1-75b2-4982-8ab6-ba9a3dd140d4?parentSnapshotId=b8317c26-6671-44a6-9859-67a0a7be6afa"
}
Traceback (most recent call last):
  File "./04.dsvm.py", line 70, in <module>
    script_to_run = train_script)
  File "/home/ninghai/miniconda3/envs/preview/lib/python3.6/site-packages/azureml/core/run.py", line 64, in submit
    return _commands.start_run(project_object, run_config_object, telemetry_values=_telemetry_values)
  File "/home/ninghai/miniconda3/envs/preview/lib/python3.6/site-packages/azureml/execution/_commands.py", line 114, in start_run
    telemetry_values=telemetry_values)
  File "/home/ninghai/miniconda3/envs/preview/lib/python3.6/site-packages/azureml/execution/_commands.py", line 381, in _start_internal
    snapshot_id = snapshot_async.get() if snapshot_async else None
  File "/home/ninghai/miniconda3/envs/preview/lib/python3.6/multiprocessing/pool.py", line 644, in get
    raise self._value
  File "/home/ninghai/miniconda3/envs/preview/lib/python3.6/multiprocessing/pool.py", line 119, in worker
    result = (True, func(*args, **kwds))
  File "/home/ninghai/miniconda3/envs/preview/lib/python3.6/site-packages/azureml/base_sdk_common/create_snapshot.py", line 129, in create_snapshot
    raise SnapshotException(get_http_exception_response_string(response))
azureml.exceptions.azureml_exception.SnapshotException: {
    "status_code": 404,
    "text": {
        "correlation": {
            "operation": "a386248a-475176cfac6b28be",
            "request": "8Z6Kdc/qD6Y="
        },
        "error": {
            "code": "UserError",
            "debugInfo": {
                "data": {},
                "errorResponse": null,
                "innerException": null,
                "message": "Unable to find snapshot with id: 4eb7d8fa-4b2e-4c7c-99cc-37dd5695023d",
                "stackTrace": "   at Microsoft.MachineLearning.Project.Services.SnapshotStore.<GetBlobAsStringOrFailNotFound>d__17.MoveNext() in /opt/vsts/work/1/s/src/azureml-api/src/ProjectContent/Services/SnapshotStore.cs:line 271\n--- End of stack trace from previous location where exception was thrown ---\n   at System.Runtime.ExceptionServices.ExceptionDispatchInfo.Throw()\n   at System.Runtime.CompilerServices.TaskAwaiter.HandleNonSuccessAndDebuggerNotification(Task task)\n   at Microsoft.MachineLearning.Project.Services.SnapshotStore.<GetSnapshot>d__7.MoveNext() in /opt/vsts/work/1/s/src/azureml-api/src/ProjectContent/Services/SnapshotStore.cs:line 113\n--- End of stack trace from previous location where exception was thrown ---\n   at System.Runtime.ExceptionServices.ExceptionDispatchInfo.Throw()\n   at System.Runtime.CompilerServices.TaskAwaiter.HandleNonSuccessAndDebuggerNotification(Task task)\n   at Microsoft.MachineLearning.ProjectContent.EntryPoints.Controllers.SnapshotController.<CreateSnapshot>d__12.MoveNext() in /opt/vsts/work/1/s/src/azureml-api/src/ProjectContent/EntryPoints/Controllers/SnapshotController.cs:line 212\n--- End of stack trace from previous location where exception was thrown ---\n   at System.Runtime.ExceptionServices.ExceptionDispatchInfo.Throw()\n   at System.Runtime.CompilerServices.TaskAwaiter.HandleNonSuccessAndDebuggerNotification(Task task)\n   at Microsoft.AspNetCore.Mvc.Internal.ControllerActionInvoker.<InvokeActionMethodAsync>d__12.MoveNext()\n--- End of stack trace from previous location where exception was thrown ---\n   at System.Runtime.ExceptionServices.ExceptionDispatchInfo.Throw()\n   at System.Runtime.CompilerServices.TaskAwaiter.HandleNonSuccessAndDebuggerNotification(Task task)\n   at Microsoft.AspNetCore.Mvc.Internal.ControllerActionInvoker.<InvokeNextActionFilterAsync>d__10.MoveNext()\n--- End of stack trace from previous location where exception was thrown ---\n   at System.Runtime.ExceptionServices.ExceptionDispatchInfo.Throw()\n   at Microsoft.AspNetCore.Mvc.Internal.ControllerActionInvoker.Rethrow(ActionExecutedContext context)\n   at Microsoft.AspNetCore.Mvc.Internal.ControllerActionInvoker.Next(State& next, Scope& scope, Object& state, Boolean& isCompleted)\n   at Microsoft.AspNetCore.Mvc.Internal.ControllerActionInvoker.<InvokeInnerFilterAsync>d__14.MoveNext()\n--- End of stack trace from previous location where exception was thrown ---\n   at System.Runtime.ExceptionServices.ExceptionDispatchInfo.Throw()\n   at System.Runtime.CompilerServices.TaskAwaiter.HandleNonSuccessAndDebuggerNotification(Task task)\n   at Microsoft.AspNetCore.Mvc.Internal.ResourceInvoker.<InvokeNextExceptionFilterAsync>d__23.MoveNext()",
                "type": "Common.WebApi.Exceptions.ResourceNotFoundException"
            },
            "details": [],
            "innerError": null,
            "message": "Unable to find snapshot with id: 4eb7d8fa-4b2e-4c7c-99cc-37dd5695023d",
            "target": null
        }
    },
    "url": "https://eastus2.experiments.azureml.net/content/v1.0/subscriptions/fac34303-435d-4486-8c3f-7094d82a0b60/resourceGroups/aml-notebooks/providers/Microsoft.MachineLearningServices/workspaces/haieastus2ws3/snapshots/93fd3717-66bf-4a46-af7d-12cdfe6c1379?parentSnapshotId=4eb7d8fa-4b2e-4c7c-99cc-37dd5695023d"
}
Traceback (most recent call last):
  File "./05.spark.py", line 81, in <module>
    script_to_run = "train-spark.py")
  File "/home/ninghai/miniconda3/envs/preview/lib/python3.6/site-packages/azureml/core/run.py", line 64, in submit
    return _commands.start_run(project_object, run_config_object, telemetry_values=_telemetry_values)
  File "/home/ninghai/miniconda3/envs/preview/lib/python3.6/site-packages/azureml/execution/_commands.py", line 114, in start_run
    telemetry_values=telemetry_values)
  File "/home/ninghai/miniconda3/envs/preview/lib/python3.6/site-packages/azureml/execution/_commands.py", line 381, in _start_internal
    snapshot_id = snapshot_async.get() if snapshot_async else None
  File "/home/ninghai/miniconda3/envs/preview/lib/python3.6/multiprocessing/pool.py", line 644, in get
    raise self._value
  File "/home/ninghai/miniconda3/envs/preview/lib/python3.6/multiprocessing/pool.py", line 119, in worker
    result = (True, func(*args, **kwds))
  File "/home/ninghai/miniconda3/envs/preview/lib/python3.6/site-packages/azureml/base_sdk_common/create_snapshot.py", line 129, in create_snapshot
    raise SnapshotException(get_http_exception_response_string(response))
azureml.exceptions.azureml_exception.SnapshotException: {
    "status_code": 404,
    "text": {
        "correlation": {
            "operation": "70eb62de-4fa154d2e7b3b1f2",
            "request": "R0p5K7VSHqA="
        },
        "error": {
            "code": "UserError",
            "debugInfo": {
                "data": {},
                "errorResponse": null,
                "innerException": null,
                "message": "Unable to find snapshot with id: e9c619a7-7486-4eb3-8e27-4efdb021ec32",
                "stackTrace": "   at Microsoft.MachineLearning.Project.Services.SnapshotStore.<GetBlobAsStringOrFailNotFound>d__17.MoveNext() in /opt/vsts/work/1/s/src/azureml-api/src/ProjectContent/Services/SnapshotStore.cs:line 271\n--- End of stack trace from previous location where exception was thrown ---\n   at System.Runtime.ExceptionServices.ExceptionDispatchInfo.Throw()\n   at System.Runtime.CompilerServices.TaskAwaiter.HandleNonSuccessAndDebuggerNotification(Task task)\n   at Microsoft.MachineLearning.Project.Services.SnapshotStore.<GetSnapshot>d__7.MoveNext() in /opt/vsts/work/1/s/src/azureml-api/src/ProjectContent/Services/SnapshotStore.cs:line 113\n--- End of stack trace from previous location where exception was thrown ---\n   at System.Runtime.ExceptionServices.ExceptionDispatchInfo.Throw()\n   at System.Runtime.CompilerServices.TaskAwaiter.HandleNonSuccessAndDebuggerNotification(Task task)\n   at Microsoft.MachineLearning.ProjectContent.EntryPoints.Controllers.SnapshotController.<CreateSnapshot>d__12.MoveNext() in /opt/vsts/work/1/s/src/azureml-api/src/ProjectContent/EntryPoints/Controllers/SnapshotController.cs:line 212\n--- End of stack trace from previous location where exception was thrown ---\n   at System.Runtime.ExceptionServices.ExceptionDispatchInfo.Throw()\n   at System.Runtime.CompilerServices.TaskAwaiter.HandleNonSuccessAndDebuggerNotification(Task task)\n   at Microsoft.AspNetCore.Mvc.Internal.ControllerActionInvoker.<InvokeActionMethodAsync>d__12.MoveNext()\n--- End of stack trace from previous location where exception was thrown ---\n   at System.Runtime.ExceptionServices.ExceptionDispatchInfo.Throw()\n   at System.Runtime.CompilerServices.TaskAwaiter.HandleNonSuccessAndDebuggerNotification(Task task)\n   at Microsoft.AspNetCore.Mvc.Internal.ControllerActionInvoker.<InvokeNextActionFilterAsync>d__10.MoveNext()\n--- End of stack trace from previous location where exception was thrown ---\n   at System.Runtime.ExceptionServices.ExceptionDispatchInfo.Throw()\n   at Microsoft.AspNetCore.Mvc.Internal.ControllerActionInvoker.Rethrow(ActionExecutedContext context)\n   at Microsoft.AspNetCore.Mvc.Internal.ControllerActionInvoker.Next(State& next, Scope& scope, Object& state, Boolean& isCompleted)\n   at Microsoft.AspNetCore.Mvc.Internal.ControllerActionInvoker.<InvokeInnerFilterAsync>d__14.MoveNext()\n--- End of stack trace from previous location where exception was thrown ---\n   at System.Runtime.ExceptionServices.ExceptionDispatchInfo.Throw()\n   at System.Runtime.CompilerServices.TaskAwaiter.HandleNonSuccessAndDebuggerNotification(Task task)\n   at Microsoft.AspNetCore.Mvc.Internal.ResourceInvoker.<InvokeNextExceptionFilterAsync>d__23.MoveNext()",
                "type": "Common.WebApi.Exceptions.ResourceNotFoundException"
            },
            "details": [],
            "innerError": null,
            "message": "Unable to find snapshot with id: e9c619a7-7486-4eb3-8e27-4efdb021ec32",
            "target": null
        }
    },
    "url": "https://eastus2.experiments.azureml.net/content/v1.0/subscriptions/fac34303-435d-4486-8c3f-7094d82a0b60/resourceGroups/aml-notebooks/providers/Microsoft.MachineLearningServices/workspaces/haieastus2ws3/snapshots/838c34ff-b2d6-4993-86b9-54ff4bd79c83?parentSnapshotId=e9c619a7-7486-4eb3-8e27-4efdb021ec32"
}
Traceback (most recent call last):
  File "./07.sklearn.hd.py", line 88, in <module>
    run = sk_est.fit()
  File "/home/ninghai/miniconda3/envs/preview/lib/python3.6/site-packages/azureml/train/estimator.py", line 421, in fit
    return super(Estimator, self).fit()
  File "/home/ninghai/miniconda3/envs/preview/lib/python3.6/site-packages/azureml/train/estimator.py", line 78, in fit
    _telemetry_values=telemetry_values)
  File "/home/ninghai/miniconda3/envs/preview/lib/python3.6/site-packages/azureml/core/run.py", line 64, in submit
    return _commands.start_run(project_object, run_config_object, telemetry_values=_telemetry_values)
  File "/home/ninghai/miniconda3/envs/preview/lib/python3.6/site-packages/azureml/execution/_commands.py", line 114, in start_run
    telemetry_values=telemetry_values)
  File "/home/ninghai/miniconda3/envs/preview/lib/python3.6/site-packages/azureml/execution/_commands.py", line 381, in _start_internal
    snapshot_id = snapshot_async.get() if snapshot_async else None
  File "/home/ninghai/miniconda3/envs/preview/lib/python3.6/multiprocessing/pool.py", line 644, in get
    raise self._value
  File "/home/ninghai/miniconda3/envs/preview/lib/python3.6/multiprocessing/pool.py", line 119, in worker
    result = (True, func(*args, **kwds))
  File "/home/ninghai/miniconda3/envs/preview/lib/python3.6/site-packages/azureml/base_sdk_common/create_snapshot.py", line 129, in create_snapshot
    raise SnapshotException(get_http_exception_response_string(response))
azureml.exceptions.azureml_exception.SnapshotException: {
    "status_code": 404,
    "text": {
        "correlation": {
            "operation": "e87ca6d7-4dafe5d5581f0658",
            "request": "e8+hED/1tmA="
        },
        "error": {
            "code": "UserError",
            "debugInfo": {
                "data": {},
                "errorResponse": null,
                "innerException": null,
                "message": "Unable to find snapshot with id: 87311c3d-6b5f-4da6-a9ad-6d027c1096bc",
                "stackTrace": "   at Microsoft.MachineLearning.Project.Services.SnapshotStore.<GetBlobAsStringOrFailNotFound>d__17.MoveNext() in /opt/vsts/work/1/s/src/azureml-api/src/ProjectContent/Services/SnapshotStore.cs:line 271\n--- End of stack trace from previous location where exception was thrown ---\n   at System.Runtime.ExceptionServices.ExceptionDispatchInfo.Throw()\n   at System.Runtime.CompilerServices.TaskAwaiter.HandleNonSuccessAndDebuggerNotification(Task task)\n   at Microsoft.MachineLearning.Project.Services.SnapshotStore.<GetSnapshot>d__7.MoveNext() in /opt/vsts/work/1/s/src/azureml-api/src/ProjectContent/Services/SnapshotStore.cs:line 113\n--- End of stack trace from previous location where exception was thrown ---\n   at System.Runtime.ExceptionServices.ExceptionDispatchInfo.Throw()\n   at System.Runtime.CompilerServices.TaskAwaiter.HandleNonSuccessAndDebuggerNotification(Task task)\n   at Microsoft.MachineLearning.ProjectContent.EntryPoints.Controllers.SnapshotController.<CreateSnapshot>d__12.MoveNext() in /opt/vsts/work/1/s/src/azureml-api/src/ProjectContent/EntryPoints/Controllers/SnapshotController.cs:line 212\n--- End of stack trace from previous location where exception was thrown ---\n   at System.Runtime.ExceptionServices.ExceptionDispatchInfo.Throw()\n   at System.Runtime.CompilerServices.TaskAwaiter.HandleNonSuccessAndDebuggerNotification(Task task)\n   at Microsoft.AspNetCore.Mvc.Internal.ControllerActionInvoker.<InvokeActionMethodAsync>d__12.MoveNext()\n--- End of stack trace from previous location where exception was thrown ---\n   at System.Runtime.ExceptionServices.ExceptionDispatchInfo.Throw()\n   at System.Runtime.CompilerServices.TaskAwaiter.HandleNonSuccessAndDebuggerNotification(Task task)\n   at Microsoft.AspNetCore.Mvc.Internal.ControllerActionInvoker.<InvokeNextActionFilterAsync>d__10.MoveNext()\n--- End of stack trace from previous location where exception was thrown ---\n   at System.Runtime.ExceptionServices.ExceptionDispatchInfo.Throw()\n   at Microsoft.AspNetCore.Mvc.Internal.ControllerActionInvoker.Rethrow(ActionExecutedContext context)\n   at Microsoft.AspNetCore.Mvc.Internal.ControllerActionInvoker.Next(State& next, Scope& scope, Object& state, Boolean& isCompleted)\n   at Microsoft.AspNetCore.Mvc.Internal.ControllerActionInvoker.<InvokeInnerFilterAsync>d__14.MoveNext()\n--- End of stack trace from previous location where exception was thrown ---\n   at System.Runtime.ExceptionServices.ExceptionDispatchInfo.Throw()\n   at System.Runtime.CompilerServices.TaskAwaiter.HandleNonSuccessAndDebuggerNotification(Task task)\n   at Microsoft.AspNetCore.Mvc.Internal.ResourceInvoker.<InvokeNextExceptionFilterAsync>d__23.MoveNext()",
                "type": "Common.WebApi.Exceptions.ResourceNotFoundException"
            },
            "details": [],
            "innerError": null,
            "message": "Unable to find snapshot with id: 87311c3d-6b5f-4da6-a9ad-6d027c1096bc",
            "target": null
        }
    },
    "url": "https://eastus2.experiments.azureml.net/content/v1.0/subscriptions/fac34303-435d-4486-8c3f-7094d82a0b60/resourceGroups/aml-notebooks/providers/Microsoft.MachineLearningServices/workspaces/haieastus2ws3/snapshots/bfd19786-1d05-4ed9-b7a8-88bcdbdfe8e8?parentSnapshotId=87311c3d-6b5f-4da6-a9ad-6d027c1096bc"
}
Traceback (most recent call last):
  File "./08.tf.hd.py", line 92, in <module>
    run = tfe.fit()
  File "/home/ninghai/miniconda3/envs/preview/lib/python3.6/site-packages/azureml/train/dnn.py", line 332, in fit
    return super(TensorFlow, self).fit()
  File "/home/ninghai/miniconda3/envs/preview/lib/python3.6/site-packages/azureml/train/estimator.py", line 78, in fit
    _telemetry_values=telemetry_values)
  File "/home/ninghai/miniconda3/envs/preview/lib/python3.6/site-packages/azureml/core/run.py", line 64, in submit
    return _commands.start_run(project_object, run_config_object, telemetry_values=_telemetry_values)
  File "/home/ninghai/miniconda3/envs/preview/lib/python3.6/site-packages/azureml/execution/_commands.py", line 114, in start_run
    telemetry_values=telemetry_values)
  File "/home/ninghai/miniconda3/envs/preview/lib/python3.6/site-packages/azureml/execution/_commands.py", line 381, in _start_internal
    snapshot_id = snapshot_async.get() if snapshot_async else None
  File "/home/ninghai/miniconda3/envs/preview/lib/python3.6/multiprocessing/pool.py", line 644, in get
    raise self._value
  File "/home/ninghai/miniconda3/envs/preview/lib/python3.6/multiprocessing/pool.py", line 119, in worker
    result = (True, func(*args, **kwds))
  File "/home/ninghai/miniconda3/envs/preview/lib/python3.6/site-packages/azureml/base_sdk_common/create_snapshot.py", line 129, in create_snapshot
    raise SnapshotException(get_http_exception_response_string(response))
azureml.exceptions.azureml_exception.SnapshotException: {
    "status_code": 404,
    "text": {
        "correlation": {
            "operation": "3549b7d-422e9e60cd6d6304",
            "request": "/z1Tmi2MOgg="
        },
        "error": {
            "code": "UserError",
            "debugInfo": {
                "data": {},
                "errorResponse": null,
                "innerException": null,
                "message": "Unable to find snapshot with id: f2407d9f-2238-46f6-92ce-8f95174e96e7",
                "stackTrace": "   at Microsoft.MachineLearning.Project.Services.SnapshotStore.<GetBlobAsStringOrFailNotFound>d__17.MoveNext() in /opt/vsts/work/1/s/src/azureml-api/src/ProjectContent/Services/SnapshotStore.cs:line 271\n--- End of stack trace from previous location where exception was thrown ---\n   at System.Runtime.ExceptionServices.ExceptionDispatchInfo.Throw()\n   at System.Runtime.CompilerServices.TaskAwaiter.HandleNonSuccessAndDebuggerNotification(Task task)\n   at Microsoft.MachineLearning.Project.Services.SnapshotStore.<GetSnapshot>d__7.MoveNext() in /opt/vsts/work/1/s/src/azureml-api/src/ProjectContent/Services/SnapshotStore.cs:line 113\n--- End of stack trace from previous location where exception was thrown ---\n   at System.Runtime.ExceptionServices.ExceptionDispatchInfo.Throw()\n   at System.Runtime.CompilerServices.TaskAwaiter.HandleNonSuccessAndDebuggerNotification(Task task)\n   at Microsoft.MachineLearning.ProjectContent.EntryPoints.Controllers.SnapshotController.<CreateSnapshot>d__12.MoveNext() in /opt/vsts/work/1/s/src/azureml-api/src/ProjectContent/EntryPoints/Controllers/SnapshotController.cs:line 212\n--- End of stack trace from previous location where exception was thrown ---\n   at System.Runtime.ExceptionServices.ExceptionDispatchInfo.Throw()\n   at System.Runtime.CompilerServices.TaskAwaiter.HandleNonSuccessAndDebuggerNotification(Task task)\n   at Microsoft.AspNetCore.Mvc.Internal.ControllerActionInvoker.<InvokeActionMethodAsync>d__12.MoveNext()\n--- End of stack trace from previous location where exception was thrown ---\n   at System.Runtime.ExceptionServices.ExceptionDispatchInfo.Throw()\n   at System.Runtime.CompilerServices.TaskAwaiter.HandleNonSuccessAndDebuggerNotification(Task task)\n   at Microsoft.AspNetCore.Mvc.Internal.ControllerActionInvoker.<InvokeNextActionFilterAsync>d__10.MoveNext()\n--- End of stack trace from previous location where exception was thrown ---\n   at System.Runtime.ExceptionServices.ExceptionDispatchInfo.Throw()\n   at Microsoft.AspNetCore.Mvc.Internal.ControllerActionInvoker.Rethrow(ActionExecutedContext context)\n   at Microsoft.AspNetCore.Mvc.Internal.ControllerActionInvoker.Next(State& next, Scope& scope, Object& state, Boolean& isCompleted)\n   at Microsoft.AspNetCore.Mvc.Internal.ControllerActionInvoker.<InvokeInnerFilterAsync>d__14.MoveNext()\n--- End of stack trace from previous location where exception was thrown ---\n   at System.Runtime.ExceptionServices.ExceptionDispatchInfo.Throw()\n   at System.Runtime.CompilerServices.TaskAwaiter.HandleNonSuccessAndDebuggerNotification(Task task)\n   at Microsoft.AspNetCore.Mvc.Internal.ResourceInvoker.<InvokeNextExceptionFilterAsync>d__23.MoveNext()",
                "type": "Common.WebApi.Exceptions.ResourceNotFoundException"
            },
            "details": [],
            "innerError": null,
            "message": "Unable to find snapshot with id: f2407d9f-2238-46f6-92ce-8f95174e96e7",
            "target": null
        }
    },
    "url": "https://eastus2.experiments.azureml.net/content/v1.0/subscriptions/fac34303-435d-4486-8c3f-7094d82a0b60/resourceGroups/aml-notebooks/providers/Microsoft.MachineLearningServices/workspaces/haieastus2ws3/snapshots/f35e0bc4-9084-4853-8ab4-2761321c097d?parentSnapshotId=f2407d9f-2238-46f6-92ce-8f95174e96e7"
}
ERROR:azure.storage.common.storageclient:Client-Request-ID=2701fc9a-7509-11e8-9288-000d3a71b7c3 Retry policy did not allow for a retry: Server-Timestamp=Thu, 21 Jun 2018 04:11:20 GMT, Server-Request-ID=f988623e-001e-0036-2415-09f636000000, HTTP status code=409, Exception=The specified container already exists.ErrorCode: ContainerAlreadyExists<?xml version="1.0" encoding="utf-8"?><Error><Code>ContainerAlreadyExists</Code><Message>The specified container already exists.RequestId:f988623e-001e-0036-2415-09f636000000Time:2018-06-21T04:11:20.5521837Z</Message></Error>.
ERROR:azure.storage.common.storageclient:Client-Request-ID=2701fc9c-7509-11e8-9288-000d3a71b7c3 Retry policy did not allow for a retry: Server-Timestamp=Thu, 21 Jun 2018 04:11:19 GMT, Server-Request-ID=c1758ce4-e01e-0037-1715-09f7cb000000, HTTP status code=409, Exception=The specified container already exists.ErrorCode: ContainerAlreadyExists<?xml version="1.0" encoding="utf-8"?><Error><Code>ContainerAlreadyExists</Code><Message>The specified container already exists.RequestId:c1758ce4-e01e-0037-1715-09f7cb000000Time:2018-06-21T04:11:20.7817455Z</Message></Error>.
ERROR:azure.storage.common.storageclient:Client-Request-ID=2701fc9e-7509-11e8-9288-000d3a71b7c3 Retry policy did not allow for a retry: Server-Timestamp=Thu, 21 Jun 2018 04:11:20 GMT, Server-Request-ID=4e6421e9-701e-00d7-2115-091143000000, HTTP status code=409, Exception=The specified container already exists.ErrorCode: ContainerAlreadyExists<?xml version="1.0" encoding="utf-8"?><Error><Code>ContainerAlreadyExists</Code><Message>The specified container already exists.RequestId:4e6421e9-701e-00d7-2115-091143000000Time:2018-06-21T04:11:20.9544350Z</Message></Error>.
ERROR:azure.storage.common.storageclient:Client-Request-ID=2701fca0-7509-11e8-9288-000d3a71b7c3 Retry policy did not allow for a retry: Server-Timestamp=Thu, 21 Jun 2018 04:11:20 GMT, Server-Request-ID=af63cb90-901e-013c-7115-09a9ea000000, HTTP status code=409, Exception=The specified container already exists.ErrorCode: ContainerAlreadyExists<?xml version="1.0" encoding="utf-8"?><Error><Code>ContainerAlreadyExists</Code><Message>The specified container already exists.RequestId:af63cb90-901e-013c-7115-09a9ea000000Time:2018-06-21T04:11:21.1208182Z</Message></Error>.
Traceback (most recent call last):
  File "/home/ninghai/miniconda3/envs/preview/lib/python3.6/site-packages/azureml/core/webservice/webservice.py", line 268, in _deploy_webservice
    resp.raise_for_status()
  File "/home/ninghai/miniconda3/envs/preview/lib/python3.6/site-packages/requests/models.py", line 939, in raise_for_status
    raise HTTPError(http_error_msg, response=self)
requests.exceptions.HTTPError: 409 Client Error: Conflict for url: https://eastus2.modelmanagement.azureml.net/api/subscriptions/fac34303-435d-4486-8c3f-7094d82a0b60/resourceGroups/aml-notebooks/providers/Microsoft.MachineLearningServices/workspaces/haieastus2ws3/services?api-version=2018-03-01-preview

During handling of the above exception, another exception occurred:

Traceback (most recent call last):
  File "./10.o16n.py", line 65, in <module>
    service = Webservice.deploy_from_image(workspace = ws, name = web_service_name, image = image, deployment_config = aciconfig)
  File "/home/ninghai/miniconda3/envs/preview/lib/python3.6/site-packages/azureml/core/webservice/webservice.py", line 230, in deploy_from_image
    return child._deploy(workspace, name, image, deployment_config)
  File "/home/ninghai/miniconda3/envs/preview/lib/python3.6/site-packages/azureml/core/webservice/aci.py", line 88, in _deploy
    return Webservice._deploy_webservice(workspace, name, create_payload, AciWebservice)
  File "/home/ninghai/miniconda3/envs/preview/lib/python3.6/site-packages/azureml/core/webservice/webservice.py", line 273, in _deploy_webservice
    'Content: {}'.format(resp.status_code, resp.headers, resp.content))
azureml.exceptions.azureml_exception.WebserviceException: Received bad response from Model Management Service:
Response Code: 409
Headers: {'Date': 'Thu, 21 Jun 2018 04:13:25 GMT', 'Content-Type': 'application/json', 'Transfer-Encoding': 'chunked', 'Connection': 'keep-alive', 'api-supported-versions': '2018-03-01-preview', 'x-ms-client-request-id': 'e962bf513ed44057890470a49e59d7f1', 'x-ms-client-session-id': '', 'Strict-Transport-Security': 'max-age=15724800; includeSubDomains; preload'}
Content: b'{"code":"Conflict","statusCode":409,"message":"Conflict","details":[{"code":"ServiceWithNameExists","message":"Workspace haieastus2ws3 already contains a Service with name: rrs02-preview"}]}'
Already on 'master'
