Already on 'master'
Client-Request-ID=2ae03b19-6e17-11e8-9288-000d3a71b7c3 Retry policy did not allow for a retry: Server-Timestamp=Tue, 12 Jun 2018 08:04:01 GMT, Server-Request-ID=8ad97320-e01e-0070-2c23-0227f5000000, HTTP status code=409, Exception=The specified container already exists.ErrorCode: ContainerAlreadyExists<?xml version="1.0" encoding="utf-8"?><Error><Code>ContainerAlreadyExists</Code><Message>The specified container already exists.RequestId:8ad97320-e01e-0070-2c23-0227f5000000Time:2018-06-12T08:04:02.3434436Z</Message></Error>.
Client-Request-ID=2ae03b1b-6e17-11e8-9288-000d3a71b7c3 Retry policy did not allow for a retry: Server-Timestamp=Tue, 12 Jun 2018 08:04:01 GMT, Server-Request-ID=e6b4963c-001e-00bd-7e23-0242bd000000, HTTP status code=409, Exception=The specified container already exists.ErrorCode: ContainerAlreadyExists<?xml version="1.0" encoding="utf-8"?><Error><Code>ContainerAlreadyExists</Code><Message>The specified container already exists.RequestId:e6b4963c-001e-00bd-7e23-0242bd000000Time:2018-06-12T08:04:02.5537209Z</Message></Error>.
Client-Request-ID=2ae03b1d-6e17-11e8-9288-000d3a71b7c3 Retry policy did not allow for a retry: Server-Timestamp=Tue, 12 Jun 2018 08:04:02 GMT, Server-Request-ID=d124e4d0-a01e-001a-6523-027b5e000000, HTTP status code=409, Exception=The specified container already exists.ErrorCode: ContainerAlreadyExists<?xml version="1.0" encoding="utf-8"?><Error><Code>ContainerAlreadyExists</Code><Message>The specified container already exists.RequestId:d124e4d0-a01e-001a-6523-027b5e000000Time:2018-06-12T08:04:02.7174350Z</Message></Error>.
Client-Request-ID=2ae03b1f-6e17-11e8-9288-000d3a71b7c3 Retry policy did not allow for a retry: Server-Timestamp=Tue, 12 Jun 2018 08:04:02 GMT, Server-Request-ID=b9fa5083-f01e-002b-4a23-022089000000, HTTP status code=409, Exception=The specified container already exists.ErrorCode: ContainerAlreadyExists<?xml version="1.0" encoding="utf-8"?><Error><Code>ContainerAlreadyExists</Code><Message>The specified container already exists.RequestId:b9fa5083-f01e-002b-4a23-022089000000Time:2018-06-12T08:04:02.9231939Z</Message></Error>.
Traceback (most recent call last):
  File "./02.local.py", line 92, in <module>
    min(metrics['mse']), 
KeyError: 'mse'
Traceback (most recent call last):
  File "./07.sklearn.hd.py", line 88, in <module>
    run = sk_est.fit()
  File "/home/ninghai/miniconda3/envs/preview/lib/python3.6/site-packages/azureml/train/estimator.py", line 438, in fit
    return super(Estimator, self).fit()
  File "/home/ninghai/miniconda3/envs/preview/lib/python3.6/site-packages/azureml/train/estimator.py", line 78, in fit
    _telemetry_values=telemetry_values)
  File "/home/ninghai/miniconda3/envs/preview/lib/python3.6/site-packages/azureml/core/run.py", line 66, in submit
    execute_with_zip=_execute_with_zip)
  File "/home/ninghai/miniconda3/envs/preview/lib/python3.6/site-packages/azureml/execution/_commands.py", line 116, in start_run
    execute_with_zip=execute_with_zip)
  File "/home/ninghai/miniconda3/envs/preview/lib/python3.6/site-packages/azureml/execution/_commands.py", line 383, in _start_internal
    _raise_request_error(response, "starting run")
  File "/home/ninghai/miniconda3/envs/preview/lib/python3.6/site-packages/azureml/execution/_commands.py", line 729, in _raise_request_error
    raise ExperimentExecutionException(get_http_exception_response_string(response))
azureml.exceptions.azureml_exception.ExperimentExecutionException: {
    "url": "https://eastus2.experiments.azureml.net/execution/v1.0/subscriptions/fac34303-435d-4486-8c3f-7094d82a0b60/resourceGroups/aml-notebooks/providers/Microsoft.MachineLearningServices/workspaces/haieastus2ws3/projects/e2e-07/run",
    "status_code": 502,
    "text": "<html>\r\n<head><title>502 Bad Gateway</title></head>\r\n<body bgcolor=\"white\">\r\n<center><h1>502 Bad Gateway</h1></center>\r\n<hr><center>nginx</center>\r\n</body>\r\n</html>\r\n"
}
Client-Request-ID=3204df7b-6e1c-11e8-9288-000d3a71b7c3 Retry policy did not allow for a retry: Server-Timestamp=Tue, 12 Jun 2018 08:40:02 GMT, Server-Request-ID=56a310bc-801e-0042-6528-027f25000000, HTTP status code=409, Exception=The specified container already exists.ErrorCode: ContainerAlreadyExists<?xml version="1.0" encoding="utf-8"?><Error><Code>ContainerAlreadyExists</Code><Message>The specified container already exists.RequestId:56a310bc-801e-0042-6528-027f25000000Time:2018-06-12T08:40:02.3598320Z</Message></Error>.
Client-Request-ID=3204df7d-6e1c-11e8-9288-000d3a71b7c3 Retry policy did not allow for a retry: Server-Timestamp=Tue, 12 Jun 2018 08:40:02 GMT, Server-Request-ID=2cd33d8f-201e-0066-0f28-02e66b000000, HTTP status code=409, Exception=The specified container already exists.ErrorCode: ContainerAlreadyExists<?xml version="1.0" encoding="utf-8"?><Error><Code>ContainerAlreadyExists</Code><Message>The specified container already exists.RequestId:2cd33d8f-201e-0066-0f28-02e66b000000Time:2018-06-12T08:40:02.6071312Z</Message></Error>.
Client-Request-ID=3204df7f-6e1c-11e8-9288-000d3a71b7c3 Retry policy did not allow for a retry: Server-Timestamp=Tue, 12 Jun 2018 08:40:02 GMT, Server-Request-ID=81f4fd68-101e-00cf-1d28-023383000000, HTTP status code=409, Exception=The specified container already exists.ErrorCode: ContainerAlreadyExists<?xml version="1.0" encoding="utf-8"?><Error><Code>ContainerAlreadyExists</Code><Message>The specified container already exists.RequestId:81f4fd68-101e-00cf-1d28-023383000000Time:2018-06-12T08:40:02.8030481Z</Message></Error>.
Client-Request-ID=3204df81-6e1c-11e8-9288-000d3a71b7c3 Retry policy did not allow for a retry: Server-Timestamp=Tue, 12 Jun 2018 08:40:02 GMT, Server-Request-ID=8bb338a0-c01e-010e-5f28-02fe6f000000, HTTP status code=409, Exception=The specified container already exists.ErrorCode: ContainerAlreadyExists<?xml version="1.0" encoding="utf-8"?><Error><Code>ContainerAlreadyExists</Code><Message>The specified container already exists.RequestId:8bb338a0-c01e-010e-5f28-02fe6f000000Time:2018-06-12T08:40:02.9800062Z</Message></Error>.
Traceback (most recent call last):
  File "./10.o16n.py", line 88, in <module>
    model.delete()
  File "/home/ninghai/miniconda3/envs/preview/lib/python3.6/site-packages/azureml/core/model.py", line 313, in delete
    'Content: {}'.format(resp.status_code, resp.headers, resp.content))
azureml.exceptions.azureml_exception.WebserviceException: Received bad response from Model Management Service:
Response Code: 412
Headers: {'Date': 'Tue, 12 Jun 2018 08:47:40 GMT', 'Content-Type': 'application/json', 'Transfer-Encoding': 'chunked', 'Connection': 'keep-alive', 'api-supported-versions': '2018-03-01-preview', 'x-ms-client-request-id': '39337f3e19404d72b2f95b492c7163b1', 'x-ms-client-session-id': '', 'Strict-Transport-Security': 'max-age=15724800; includeSubDomains; preload'}
Content: b'{"code":"PreconditionFailed","statusCode":412,"message":"PreconditionFailed","details":[{"code":"DeletionRequired","message":"The model with id best_model.pkl:189 can not be deleted because it is currently being used in one or more images"}]}'
Already on 'master'
