Already on 'master'
Traceback (most recent call last):
  File "/home/ninghai/miniconda3/envs/preview/lib/python3.6/site-packages/azureml/core/webservice/webservice.py", line 268, in _deploy_webservice
    resp.raise_for_status()
  File "/home/ninghai/miniconda3/envs/preview/lib/python3.6/site-packages/requests/models.py", line 939, in raise_for_status
    raise HTTPError(http_error_msg, response=self)
requests.exceptions.HTTPError: 409 Client Error: Conflict for url: https://eastus2.modelmanagement.azureml.net/api/subscriptions/fac34303-435d-4486-8c3f-7094d82a0b60/resourceGroups/aml-notebooks/providers/Microsoft.MachineLearningServices/workspaces/haieastus2ws3/services?api-version=2018-03-01-preview

During handling of the above exception, another exception occurred:

Traceback (most recent call last):
  File "./01.interactive.e2e.py", line 142, in <module>
    execution_script = 'score.py')
  File "/home/ninghai/miniconda3/envs/preview/lib/python3.6/site-packages/azureml/core/webservice/webservice.py", line 165, in deploy
    deployment_target)
  File "/home/ninghai/miniconda3/envs/preview/lib/python3.6/site-packages/azureml/core/webservice/webservice.py", line 204, in deploy_from_model
    return Webservice.deploy_from_image(workspace, name, image, deployment_config, deployment_target)
  File "/home/ninghai/miniconda3/envs/preview/lib/python3.6/site-packages/azureml/core/webservice/webservice.py", line 230, in deploy_from_image
    return child._deploy(workspace, name, image, deployment_config)
  File "/home/ninghai/miniconda3/envs/preview/lib/python3.6/site-packages/azureml/core/webservice/aci.py", line 88, in _deploy
    return Webservice._deploy_webservice(workspace, name, create_payload, AciWebservice)
  File "/home/ninghai/miniconda3/envs/preview/lib/python3.6/site-packages/azureml/core/webservice/webservice.py", line 273, in _deploy_webservice
    'Content: {}'.format(resp.status_code, resp.headers, resp.content))
azureml.exceptions.azureml_exception.WebserviceException: Received bad response from Model Management Service:
Response Code: 409
Headers: {'Date': 'Fri, 29 Jun 2018 16:05:45 GMT', 'Content-Type': 'application/json', 'Transfer-Encoding': 'chunked', 'Connection': 'keep-alive', 'api-supported-versions': '2018-03-01-preview', 'x-ms-client-request-id': '25632bfa47f24b3d9f2463657e142786', 'x-ms-client-session-id': '', 'Strict-Transport-Security': 'max-age=15724800; includeSubDomains; preload'}
Content: b'{"code":"Conflict","statusCode":409,"message":"Conflict","details":[{"code":"ServiceWithNameExists","message":"Workspace haieastus2ws3 already contains a Service with name: rrs01-preview"}]}'
Traceback (most recent call last):
  File "./02.local.py", line 51, in <module>
    script_to_run = train_script)
  File "/home/ninghai/miniconda3/envs/preview/lib/python3.6/site-packages/azureml/core/run.py", line 70, in submit
    return _commands.start_run(project_object, run_config_object, telemetry_values=_telemetry_values)
  File "/home/ninghai/miniconda3/envs/preview/lib/python3.6/site-packages/azureml/execution/_commands.py", line 110, in start_run
    telemetry_values=telemetry_values)
  File "/home/ninghai/miniconda3/envs/preview/lib/python3.6/site-packages/azureml/execution/_commands.py", line 274, in _start_internal_local_cloud
    snapshot_id = snapshot_async.get() if snapshot_async else None
  File "/home/ninghai/miniconda3/envs/preview/lib/python3.6/multiprocessing/pool.py", line 644, in get
    raise self._value
  File "/home/ninghai/miniconda3/envs/preview/lib/python3.6/multiprocessing/pool.py", line 119, in worker
    result = (True, func(*args, **kwds))
  File "/home/ninghai/miniconda3/envs/preview/lib/python3.6/site-packages/azureml/base_sdk_common/create_snapshot.py", line 120, in create_snapshot
    raise SnapshotException(get_http_exception_response_string(response))
azureml.exceptions.azureml_exception.SnapshotException: {
    "status_code": 404,
    "text": {
        "correlation": {
            "operation": "967e187f-45d8bb7ace980f9f",
            "request": "vz0msb+Tey8="
        },
        "error": {
            "code": "UserError",
            "debugInfo": {
                "data": {},
                "errorResponse": null,
                "innerException": null,
                "message": "Unable to find snapshot with id: 2bd3167f-0978-42bd-9795-6c89fc1e31b2",
                "stackTrace": "   at Microsoft.MachineLearning.Project.Services.SnapshotStore.<GetBlobAsStringOrFailNotFound>d__17.MoveNext() in /opt/vsts/work/1/s/src/azureml-api/src/ProjectContent/Services/SnapshotStore.cs:line 271\n--- End of stack trace from previous location where exception was thrown ---\n   at System.Runtime.ExceptionServices.ExceptionDispatchInfo.Throw()\n   at System.Runtime.CompilerServices.TaskAwaiter.HandleNonSuccessAndDebuggerNotification(Task task)\n   at Microsoft.MachineLearning.Project.Services.SnapshotStore.<GetSnapshot>d__7.MoveNext() in /opt/vsts/work/1/s/src/azureml-api/src/ProjectContent/Services/SnapshotStore.cs:line 113\n--- End of stack trace from previous location where exception was thrown ---\n   at System.Runtime.ExceptionServices.ExceptionDispatchInfo.Throw()\n   at System.Runtime.CompilerServices.TaskAwaiter.HandleNonSuccessAndDebuggerNotification(Task task)\n   at Microsoft.MachineLearning.ProjectContent.EntryPoints.Controllers.SnapshotController.<CreateSnapshot>d__12.MoveNext() in /opt/vsts/work/1/s/src/azureml-api/src/ProjectContent/EntryPoints/Controllers/SnapshotController.cs:line 212\n--- End of stack trace from previous location where exception was thrown ---\n   at System.Runtime.ExceptionServices.ExceptionDispatchInfo.Throw()\n   at System.Runtime.CompilerServices.TaskAwaiter.HandleNonSuccessAndDebuggerNotification(Task task)\n   at Microsoft.AspNetCore.Mvc.Internal.ControllerActionInvoker.<InvokeActionMethodAsync>d__12.MoveNext()\n--- End of stack trace from previous location where exception was thrown ---\n   at System.Runtime.ExceptionServices.ExceptionDispatchInfo.Throw()\n   at System.Runtime.CompilerServices.TaskAwaiter.HandleNonSuccessAndDebuggerNotification(Task task)\n   at Microsoft.AspNetCore.Mvc.Internal.ControllerActionInvoker.<InvokeNextActionFilterAsync>d__10.MoveNext()\n--- End of stack trace from previous location where exception was thrown ---\n   at System.Runtime.ExceptionServices.ExceptionDispatchInfo.Throw()\n   at Microsoft.AspNetCore.Mvc.Internal.ControllerActionInvoker.Rethrow(ActionExecutedContext context)\n   at Microsoft.AspNetCore.Mvc.Internal.ControllerActionInvoker.Next(State& next, Scope& scope, Object& state, Boolean& isCompleted)\n   at Microsoft.AspNetCore.Mvc.Internal.ControllerActionInvoker.<InvokeInnerFilterAsync>d__14.MoveNext()\n--- End of stack trace from previous location where exception was thrown ---\n   at System.Runtime.ExceptionServices.ExceptionDispatchInfo.Throw()\n   at System.Runtime.CompilerServices.TaskAwaiter.HandleNonSuccessAndDebuggerNotification(Task task)\n   at Microsoft.AspNetCore.Mvc.Internal.ResourceInvoker.<InvokeNextExceptionFilterAsync>d__23.MoveNext()",
                "type": "Common.WebApi.Exceptions.ResourceNotFoundException"
            },
            "details": [],
            "innerError": null,
            "message": "Unable to find snapshot with id: 2bd3167f-0978-42bd-9795-6c89fc1e31b2",
            "target": null
        }
    },
    "url": "https://eastus2.experiments.azureml.net/content/v1.0/subscriptions/fac34303-435d-4486-8c3f-7094d82a0b60/resourceGroups/aml-notebooks/providers/Microsoft.MachineLearningServices/workspaces/haieastus2ws3/snapshots/8cc89667-87cb-4431-80a2-751638522dac?parentSnapshotId=2bd3167f-0978-42bd-9795-6c89fc1e31b2"
}
Traceback (most recent call last):
  File "./03.aci.py", line 85, in <module>
    script_to_run = train_script)
  File "/home/ninghai/miniconda3/envs/preview/lib/python3.6/site-packages/azureml/core/run.py", line 70, in submit
    return _commands.start_run(project_object, run_config_object, telemetry_values=_telemetry_values)
  File "/home/ninghai/miniconda3/envs/preview/lib/python3.6/site-packages/azureml/execution/_commands.py", line 115, in start_run
    telemetry_values=telemetry_values)
  File "/home/ninghai/miniconda3/envs/preview/lib/python3.6/site-packages/azureml/execution/_commands.py", line 384, in _start_internal
    snapshot_id = snapshot_async.get() if snapshot_async else None
  File "/home/ninghai/miniconda3/envs/preview/lib/python3.6/multiprocessing/pool.py", line 644, in get
    raise self._value
  File "/home/ninghai/miniconda3/envs/preview/lib/python3.6/multiprocessing/pool.py", line 119, in worker
    result = (True, func(*args, **kwds))
  File "/home/ninghai/miniconda3/envs/preview/lib/python3.6/site-packages/azureml/base_sdk_common/create_snapshot.py", line 120, in create_snapshot
    raise SnapshotException(get_http_exception_response_string(response))
azureml.exceptions.azureml_exception.SnapshotException: {
    "status_code": 404,
    "text": {
        "correlation": {
            "operation": "967e1881-45d8bb7ace980f9f",
            "request": "MCK+hY4VXY8="
        },
        "error": {
            "code": "UserError",
            "debugInfo": {
                "data": {},
                "errorResponse": null,
                "innerException": null,
                "message": "Unable to find snapshot with id: b8317c26-6671-44a6-9859-67a0a7be6afa",
                "stackTrace": "   at Microsoft.MachineLearning.Project.Services.SnapshotStore.<GetBlobAsStringOrFailNotFound>d__17.MoveNext() in /opt/vsts/work/1/s/src/azureml-api/src/ProjectContent/Services/SnapshotStore.cs:line 271\n--- End of stack trace from previous location where exception was thrown ---\n   at System.Runtime.ExceptionServices.ExceptionDispatchInfo.Throw()\n   at System.Runtime.CompilerServices.TaskAwaiter.HandleNonSuccessAndDebuggerNotification(Task task)\n   at Microsoft.MachineLearning.Project.Services.SnapshotStore.<GetSnapshot>d__7.MoveNext() in /opt/vsts/work/1/s/src/azureml-api/src/ProjectContent/Services/SnapshotStore.cs:line 113\n--- End of stack trace from previous location where exception was thrown ---\n   at System.Runtime.ExceptionServices.ExceptionDispatchInfo.Throw()\n   at System.Runtime.CompilerServices.TaskAwaiter.HandleNonSuccessAndDebuggerNotification(Task task)\n   at Microsoft.MachineLearning.ProjectContent.EntryPoints.Controllers.SnapshotController.<CreateSnapshot>d__12.MoveNext() in /opt/vsts/work/1/s/src/azureml-api/src/ProjectContent/EntryPoints/Controllers/SnapshotController.cs:line 212\n--- End of stack trace from previous location where exception was thrown ---\n   at System.Runtime.ExceptionServices.ExceptionDispatchInfo.Throw()\n   at System.Runtime.CompilerServices.TaskAwaiter.HandleNonSuccessAndDebuggerNotification(Task task)\n   at Microsoft.AspNetCore.Mvc.Internal.ControllerActionInvoker.<InvokeActionMethodAsync>d__12.MoveNext()\n--- End of stack trace from previous location where exception was thrown ---\n   at System.Runtime.ExceptionServices.ExceptionDispatchInfo.Throw()\n   at System.Runtime.CompilerServices.TaskAwaiter.HandleNonSuccessAndDebuggerNotification(Task task)\n   at Microsoft.AspNetCore.Mvc.Internal.ControllerActionInvoker.<InvokeNextActionFilterAsync>d__10.MoveNext()\n--- End of stack trace from previous location where exception was thrown ---\n   at System.Runtime.ExceptionServices.ExceptionDispatchInfo.Throw()\n   at Microsoft.AspNetCore.Mvc.Internal.ControllerActionInvoker.Rethrow(ActionExecutedContext context)\n   at Microsoft.AspNetCore.Mvc.Internal.ControllerActionInvoker.Next(State& next, Scope& scope, Object& state, Boolean& isCompleted)\n   at Microsoft.AspNetCore.Mvc.Internal.ControllerActionInvoker.<InvokeInnerFilterAsync>d__14.MoveNext()\n--- End of stack trace from previous location where exception was thrown ---\n   at System.Runtime.ExceptionServices.ExceptionDispatchInfo.Throw()\n   at System.Runtime.CompilerServices.TaskAwaiter.HandleNonSuccessAndDebuggerNotification(Task task)\n   at Microsoft.AspNetCore.Mvc.Internal.ResourceInvoker.<InvokeNextExceptionFilterAsync>d__23.MoveNext()",
                "type": "Common.WebApi.Exceptions.ResourceNotFoundException"
            },
            "details": [],
            "innerError": null,
            "message": "Unable to find snapshot with id: b8317c26-6671-44a6-9859-67a0a7be6afa",
            "target": null
        }
    },
    "url": "https://eastus2.experiments.azureml.net/content/v1.0/subscriptions/fac34303-435d-4486-8c3f-7094d82a0b60/resourceGroups/aml-notebooks/providers/Microsoft.MachineLearningServices/workspaces/haieastus2ws3/snapshots/4a49f51d-3112-42ed-8848-e1f999dfd975?parentSnapshotId=b8317c26-6671-44a6-9859-67a0a7be6afa"
}
Traceback (most recent call last):
  File "./04.dsvm.py", line 71, in <module>
    script_to_run = train_script)
  File "/home/ninghai/miniconda3/envs/preview/lib/python3.6/site-packages/azureml/core/run.py", line 70, in submit
    return _commands.start_run(project_object, run_config_object, telemetry_values=_telemetry_values)
  File "/home/ninghai/miniconda3/envs/preview/lib/python3.6/site-packages/azureml/execution/_commands.py", line 115, in start_run
    telemetry_values=telemetry_values)
  File "/home/ninghai/miniconda3/envs/preview/lib/python3.6/site-packages/azureml/execution/_commands.py", line 384, in _start_internal
    snapshot_id = snapshot_async.get() if snapshot_async else None
  File "/home/ninghai/miniconda3/envs/preview/lib/python3.6/multiprocessing/pool.py", line 644, in get
    raise self._value
  File "/home/ninghai/miniconda3/envs/preview/lib/python3.6/multiprocessing/pool.py", line 119, in worker
    result = (True, func(*args, **kwds))
  File "/home/ninghai/miniconda3/envs/preview/lib/python3.6/site-packages/azureml/base_sdk_common/create_snapshot.py", line 120, in create_snapshot
    raise SnapshotException(get_http_exception_response_string(response))
azureml.exceptions.azureml_exception.SnapshotException: {
    "status_code": 404,
    "text": {
        "correlation": {
            "operation": "967e1882-45d8bb7ace980f9f",
            "request": "0vO1y7YpQiA="
        },
        "error": {
            "code": "UserError",
            "debugInfo": {
                "data": {},
                "errorResponse": null,
                "innerException": null,
                "message": "Unable to find snapshot with id: 4eb7d8fa-4b2e-4c7c-99cc-37dd5695023d",
                "stackTrace": "   at Microsoft.MachineLearning.Project.Services.SnapshotStore.<GetBlobAsStringOrFailNotFound>d__17.MoveNext() in /opt/vsts/work/1/s/src/azureml-api/src/ProjectContent/Services/SnapshotStore.cs:line 271\n--- End of stack trace from previous location where exception was thrown ---\n   at System.Runtime.ExceptionServices.ExceptionDispatchInfo.Throw()\n   at System.Runtime.CompilerServices.TaskAwaiter.HandleNonSuccessAndDebuggerNotification(Task task)\n   at Microsoft.MachineLearning.Project.Services.SnapshotStore.<GetSnapshot>d__7.MoveNext() in /opt/vsts/work/1/s/src/azureml-api/src/ProjectContent/Services/SnapshotStore.cs:line 113\n--- End of stack trace from previous location where exception was thrown ---\n   at System.Runtime.ExceptionServices.ExceptionDispatchInfo.Throw()\n   at System.Runtime.CompilerServices.TaskAwaiter.HandleNonSuccessAndDebuggerNotification(Task task)\n   at Microsoft.MachineLearning.ProjectContent.EntryPoints.Controllers.SnapshotController.<CreateSnapshot>d__12.MoveNext() in /opt/vsts/work/1/s/src/azureml-api/src/ProjectContent/EntryPoints/Controllers/SnapshotController.cs:line 212\n--- End of stack trace from previous location where exception was thrown ---\n   at System.Runtime.ExceptionServices.ExceptionDispatchInfo.Throw()\n   at System.Runtime.CompilerServices.TaskAwaiter.HandleNonSuccessAndDebuggerNotification(Task task)\n   at Microsoft.AspNetCore.Mvc.Internal.ControllerActionInvoker.<InvokeActionMethodAsync>d__12.MoveNext()\n--- End of stack trace from previous location where exception was thrown ---\n   at System.Runtime.ExceptionServices.ExceptionDispatchInfo.Throw()\n   at System.Runtime.CompilerServices.TaskAwaiter.HandleNonSuccessAndDebuggerNotification(Task task)\n   at Microsoft.AspNetCore.Mvc.Internal.ControllerActionInvoker.<InvokeNextActionFilterAsync>d__10.MoveNext()\n--- End of stack trace from previous location where exception was thrown ---\n   at System.Runtime.ExceptionServices.ExceptionDispatchInfo.Throw()\n   at Microsoft.AspNetCore.Mvc.Internal.ControllerActionInvoker.Rethrow(ActionExecutedContext context)\n   at Microsoft.AspNetCore.Mvc.Internal.ControllerActionInvoker.Next(State& next, Scope& scope, Object& state, Boolean& isCompleted)\n   at Microsoft.AspNetCore.Mvc.Internal.ControllerActionInvoker.<InvokeInnerFilterAsync>d__14.MoveNext()\n--- End of stack trace from previous location where exception was thrown ---\n   at System.Runtime.ExceptionServices.ExceptionDispatchInfo.Throw()\n   at System.Runtime.CompilerServices.TaskAwaiter.HandleNonSuccessAndDebuggerNotification(Task task)\n   at Microsoft.AspNetCore.Mvc.Internal.ResourceInvoker.<InvokeNextExceptionFilterAsync>d__23.MoveNext()",
                "type": "Common.WebApi.Exceptions.ResourceNotFoundException"
            },
            "details": [],
            "innerError": null,
            "message": "Unable to find snapshot with id: 4eb7d8fa-4b2e-4c7c-99cc-37dd5695023d",
            "target": null
        }
    },
    "url": "https://eastus2.experiments.azureml.net/content/v1.0/subscriptions/fac34303-435d-4486-8c3f-7094d82a0b60/resourceGroups/aml-notebooks/providers/Microsoft.MachineLearningServices/workspaces/haieastus2ws3/snapshots/062f09a8-530e-4b39-aa74-355bd19773d2?parentSnapshotId=4eb7d8fa-4b2e-4c7c-99cc-37dd5695023d"
}
Traceback (most recent call last):
  File "./05.spark.py", line 81, in <module>
    script_to_run = "train-spark.py")
  File "/home/ninghai/miniconda3/envs/preview/lib/python3.6/site-packages/azureml/core/run.py", line 70, in submit
    return _commands.start_run(project_object, run_config_object, telemetry_values=_telemetry_values)
  File "/home/ninghai/miniconda3/envs/preview/lib/python3.6/site-packages/azureml/execution/_commands.py", line 115, in start_run
    telemetry_values=telemetry_values)
  File "/home/ninghai/miniconda3/envs/preview/lib/python3.6/site-packages/azureml/execution/_commands.py", line 384, in _start_internal
    snapshot_id = snapshot_async.get() if snapshot_async else None
  File "/home/ninghai/miniconda3/envs/preview/lib/python3.6/multiprocessing/pool.py", line 644, in get
    raise self._value
  File "/home/ninghai/miniconda3/envs/preview/lib/python3.6/multiprocessing/pool.py", line 119, in worker
    result = (True, func(*args, **kwds))
  File "/home/ninghai/miniconda3/envs/preview/lib/python3.6/site-packages/azureml/base_sdk_common/create_snapshot.py", line 120, in create_snapshot
    raise SnapshotException(get_http_exception_response_string(response))
azureml.exceptions.azureml_exception.SnapshotException: {
    "status_code": 404,
    "text": {
        "correlation": {
            "operation": "7d94b94-49978cbea9194a9f",
            "request": "vtAc/M93iFI="
        },
        "error": {
            "code": "UserError",
            "debugInfo": {
                "data": {},
                "errorResponse": null,
                "innerException": null,
                "message": "Unable to find snapshot with id: e9c619a7-7486-4eb3-8e27-4efdb021ec32",
                "stackTrace": "   at Microsoft.MachineLearning.Project.Services.SnapshotStore.<GetBlobAsStringOrFailNotFound>d__17.MoveNext() in /opt/vsts/work/1/s/src/azureml-api/src/ProjectContent/Services/SnapshotStore.cs:line 271\n--- End of stack trace from previous location where exception was thrown ---\n   at System.Runtime.ExceptionServices.ExceptionDispatchInfo.Throw()\n   at System.Runtime.CompilerServices.TaskAwaiter.HandleNonSuccessAndDebuggerNotification(Task task)\n   at Microsoft.MachineLearning.Project.Services.SnapshotStore.<GetSnapshot>d__7.MoveNext() in /opt/vsts/work/1/s/src/azureml-api/src/ProjectContent/Services/SnapshotStore.cs:line 113\n--- End of stack trace from previous location where exception was thrown ---\n   at System.Runtime.ExceptionServices.ExceptionDispatchInfo.Throw()\n   at System.Runtime.CompilerServices.TaskAwaiter.HandleNonSuccessAndDebuggerNotification(Task task)\n   at Microsoft.MachineLearning.ProjectContent.EntryPoints.Controllers.SnapshotController.<CreateSnapshot>d__12.MoveNext() in /opt/vsts/work/1/s/src/azureml-api/src/ProjectContent/EntryPoints/Controllers/SnapshotController.cs:line 212\n--- End of stack trace from previous location where exception was thrown ---\n   at System.Runtime.ExceptionServices.ExceptionDispatchInfo.Throw()\n   at System.Runtime.CompilerServices.TaskAwaiter.HandleNonSuccessAndDebuggerNotification(Task task)\n   at Microsoft.AspNetCore.Mvc.Internal.ControllerActionInvoker.<InvokeActionMethodAsync>d__12.MoveNext()\n--- End of stack trace from previous location where exception was thrown ---\n   at System.Runtime.ExceptionServices.ExceptionDispatchInfo.Throw()\n   at System.Runtime.CompilerServices.TaskAwaiter.HandleNonSuccessAndDebuggerNotification(Task task)\n   at Microsoft.AspNetCore.Mvc.Internal.ControllerActionInvoker.<InvokeNextActionFilterAsync>d__10.MoveNext()\n--- End of stack trace from previous location where exception was thrown ---\n   at System.Runtime.ExceptionServices.ExceptionDispatchInfo.Throw()\n   at Microsoft.AspNetCore.Mvc.Internal.ControllerActionInvoker.Rethrow(ActionExecutedContext context)\n   at Microsoft.AspNetCore.Mvc.Internal.ControllerActionInvoker.Next(State& next, Scope& scope, Object& state, Boolean& isCompleted)\n   at Microsoft.AspNetCore.Mvc.Internal.ControllerActionInvoker.<InvokeInnerFilterAsync>d__14.MoveNext()\n--- End of stack trace from previous location where exception was thrown ---\n   at System.Runtime.ExceptionServices.ExceptionDispatchInfo.Throw()\n   at System.Runtime.CompilerServices.TaskAwaiter.HandleNonSuccessAndDebuggerNotification(Task task)\n   at Microsoft.AspNetCore.Mvc.Internal.ResourceInvoker.<InvokeNextExceptionFilterAsync>d__23.MoveNext()",
                "type": "Common.WebApi.Exceptions.ResourceNotFoundException"
            },
            "details": [],
            "innerError": null,
            "message": "Unable to find snapshot with id: e9c619a7-7486-4eb3-8e27-4efdb021ec32",
            "target": null
        }
    },
    "url": "https://eastus2.experiments.azureml.net/content/v1.0/subscriptions/fac34303-435d-4486-8c3f-7094d82a0b60/resourceGroups/aml-notebooks/providers/Microsoft.MachineLearningServices/workspaces/haieastus2ws3/snapshots/aa14071a-82f0-474e-8bdd-74cb5e4a581d?parentSnapshotId=e9c619a7-7486-4eb3-8e27-4efdb021ec32"
}
2018-06-29 12:07:48,116 WARNING Retrying (Retry(total=2, connect=3, read=2, redirect=None, status=None)) after connection broken by 'ReadTimeoutError("HTTPSConnectionPool(host='management.azure.com', port=443): Read timed out. (read timeout=100)",)': /subscriptions/fac34303-435d-4486-8c3f-7094d82a0b60/resourceGroups/aml-notebooks/providers/Microsoft.MachineLearningServices/workspaces/haieastus2ws3?api-version=2018-03-01-preview
WARNING:urllib3.connectionpool:Retrying (Retry(total=2, connect=3, read=2, redirect=None, status=None)) after connection broken by 'ReadTimeoutError("HTTPSConnectionPool(host='management.azure.com', port=443): Read timed out. (read timeout=100)",)': /subscriptions/fac34303-435d-4486-8c3f-7094d82a0b60/resourceGroups/aml-notebooks/providers/Microsoft.MachineLearningServices/workspaces/haieastus2ws3?api-version=2018-03-01-preview
Traceback (most recent call last):
  File "./07.sklearn.hd.py", line 88, in <module>
    run = sk_est.fit()
  File "/home/ninghai/miniconda3/envs/preview/lib/python3.6/site-packages/azureml/train/estimator.py", line 421, in fit
    return super(Estimator, self).fit()
  File "/home/ninghai/miniconda3/envs/preview/lib/python3.6/site-packages/azureml/train/estimator.py", line 78, in fit
    _telemetry_values=telemetry_values)
  File "/home/ninghai/miniconda3/envs/preview/lib/python3.6/site-packages/azureml/core/run.py", line 70, in submit
    return _commands.start_run(project_object, run_config_object, telemetry_values=_telemetry_values)
  File "/home/ninghai/miniconda3/envs/preview/lib/python3.6/site-packages/azureml/execution/_commands.py", line 115, in start_run
    telemetry_values=telemetry_values)
  File "/home/ninghai/miniconda3/envs/preview/lib/python3.6/site-packages/azureml/execution/_commands.py", line 384, in _start_internal
    snapshot_id = snapshot_async.get() if snapshot_async else None
  File "/home/ninghai/miniconda3/envs/preview/lib/python3.6/multiprocessing/pool.py", line 644, in get
    raise self._value
  File "/home/ninghai/miniconda3/envs/preview/lib/python3.6/multiprocessing/pool.py", line 119, in worker
    result = (True, func(*args, **kwds))
  File "/home/ninghai/miniconda3/envs/preview/lib/python3.6/site-packages/azureml/base_sdk_common/create_snapshot.py", line 120, in create_snapshot
    raise SnapshotException(get_http_exception_response_string(response))
azureml.exceptions.azureml_exception.SnapshotException: {
    "status_code": 404,
    "text": {
        "correlation": {
            "operation": "4bc02c3c-4b2e3f096276d1bb",
            "request": "MtQYEzdgnZg="
        },
        "error": {
            "code": "UserError",
            "debugInfo": {
                "data": {},
                "errorResponse": null,
                "innerException": null,
                "message": "Unable to find snapshot with id: 87311c3d-6b5f-4da6-a9ad-6d027c1096bc",
                "stackTrace": "   at Microsoft.MachineLearning.Project.Services.SnapshotStore.<GetBlobAsStringOrFailNotFound>d__17.MoveNext() in /opt/vsts/work/1/s/src/azureml-api/src/ProjectContent/Services/SnapshotStore.cs:line 271\n--- End of stack trace from previous location where exception was thrown ---\n   at System.Runtime.ExceptionServices.ExceptionDispatchInfo.Throw()\n   at System.Runtime.CompilerServices.TaskAwaiter.HandleNonSuccessAndDebuggerNotification(Task task)\n   at Microsoft.MachineLearning.Project.Services.SnapshotStore.<GetSnapshot>d__7.MoveNext() in /opt/vsts/work/1/s/src/azureml-api/src/ProjectContent/Services/SnapshotStore.cs:line 113\n--- End of stack trace from previous location where exception was thrown ---\n   at System.Runtime.ExceptionServices.ExceptionDispatchInfo.Throw()\n   at System.Runtime.CompilerServices.TaskAwaiter.HandleNonSuccessAndDebuggerNotification(Task task)\n   at Microsoft.MachineLearning.ProjectContent.EntryPoints.Controllers.SnapshotController.<CreateSnapshot>d__12.MoveNext() in /opt/vsts/work/1/s/src/azureml-api/src/ProjectContent/EntryPoints/Controllers/SnapshotController.cs:line 212\n--- End of stack trace from previous location where exception was thrown ---\n   at System.Runtime.ExceptionServices.ExceptionDispatchInfo.Throw()\n   at System.Runtime.CompilerServices.TaskAwaiter.HandleNonSuccessAndDebuggerNotification(Task task)\n   at Microsoft.AspNetCore.Mvc.Internal.ControllerActionInvoker.<InvokeActionMethodAsync>d__12.MoveNext()\n--- End of stack trace from previous location where exception was thrown ---\n   at System.Runtime.ExceptionServices.ExceptionDispatchInfo.Throw()\n   at System.Runtime.CompilerServices.TaskAwaiter.HandleNonSuccessAndDebuggerNotification(Task task)\n   at Microsoft.AspNetCore.Mvc.Internal.ControllerActionInvoker.<InvokeNextActionFilterAsync>d__10.MoveNext()\n--- End of stack trace from previous location where exception was thrown ---\n   at System.Runtime.ExceptionServices.ExceptionDispatchInfo.Throw()\n   at Microsoft.AspNetCore.Mvc.Internal.ControllerActionInvoker.Rethrow(ActionExecutedContext context)\n   at Microsoft.AspNetCore.Mvc.Internal.ControllerActionInvoker.Next(State& next, Scope& scope, Object& state, Boolean& isCompleted)\n   at Microsoft.AspNetCore.Mvc.Internal.ControllerActionInvoker.<InvokeInnerFilterAsync>d__14.MoveNext()\n--- End of stack trace from previous location where exception was thrown ---\n   at System.Runtime.ExceptionServices.ExceptionDispatchInfo.Throw()\n   at System.Runtime.CompilerServices.TaskAwaiter.HandleNonSuccessAndDebuggerNotification(Task task)\n   at Microsoft.AspNetCore.Mvc.Internal.ResourceInvoker.<InvokeNextExceptionFilterAsync>d__23.MoveNext()",
                "type": "Common.WebApi.Exceptions.ResourceNotFoundException"
            },
            "details": [],
            "innerError": null,
            "message": "Unable to find snapshot with id: 87311c3d-6b5f-4da6-a9ad-6d027c1096bc",
            "target": null
        }
    },
    "url": "https://eastus2.experiments.azureml.net/content/v1.0/subscriptions/fac34303-435d-4486-8c3f-7094d82a0b60/resourceGroups/aml-notebooks/providers/Microsoft.MachineLearningServices/workspaces/haieastus2ws3/snapshots/42ad09c0-3c8d-480a-a66a-8b2cd5472287?parentSnapshotId=87311c3d-6b5f-4da6-a9ad-6d027c1096bc"
}
Traceback (most recent call last):
  File "./08.tf.hd.py", line 92, in <module>
    run = tfe.fit()
  File "/home/ninghai/miniconda3/envs/preview/lib/python3.6/site-packages/azureml/train/dnn.py", line 332, in fit
    return super(TensorFlow, self).fit()
  File "/home/ninghai/miniconda3/envs/preview/lib/python3.6/site-packages/azureml/train/estimator.py", line 78, in fit
    _telemetry_values=telemetry_values)
  File "/home/ninghai/miniconda3/envs/preview/lib/python3.6/site-packages/azureml/core/run.py", line 70, in submit
    return _commands.start_run(project_object, run_config_object, telemetry_values=_telemetry_values)
  File "/home/ninghai/miniconda3/envs/preview/lib/python3.6/site-packages/azureml/execution/_commands.py", line 115, in start_run
    telemetry_values=telemetry_values)
  File "/home/ninghai/miniconda3/envs/preview/lib/python3.6/site-packages/azureml/execution/_commands.py", line 384, in _start_internal
    snapshot_id = snapshot_async.get() if snapshot_async else None
  File "/home/ninghai/miniconda3/envs/preview/lib/python3.6/multiprocessing/pool.py", line 644, in get
    raise self._value
  File "/home/ninghai/miniconda3/envs/preview/lib/python3.6/multiprocessing/pool.py", line 119, in worker
    result = (True, func(*args, **kwds))
  File "/home/ninghai/miniconda3/envs/preview/lib/python3.6/site-packages/azureml/base_sdk_common/create_snapshot.py", line 120, in create_snapshot
    raise SnapshotException(get_http_exception_response_string(response))
azureml.exceptions.azureml_exception.SnapshotException: {
    "status_code": 404,
    "text": {
        "correlation": {
            "operation": "6df32f22-4512fc201eb8e1c4",
            "request": "+aEw63CWOLE="
        },
        "error": {
            "code": "UserError",
            "debugInfo": {
                "data": {},
                "errorResponse": null,
                "innerException": null,
                "message": "Unable to find snapshot with id: f2407d9f-2238-46f6-92ce-8f95174e96e7",
                "stackTrace": "   at Microsoft.MachineLearning.Project.Services.SnapshotStore.<GetBlobAsStringOrFailNotFound>d__17.MoveNext() in /opt/vsts/work/1/s/src/azureml-api/src/ProjectContent/Services/SnapshotStore.cs:line 271\n--- End of stack trace from previous location where exception was thrown ---\n   at System.Runtime.ExceptionServices.ExceptionDispatchInfo.Throw()\n   at System.Runtime.CompilerServices.TaskAwaiter.HandleNonSuccessAndDebuggerNotification(Task task)\n   at Microsoft.MachineLearning.Project.Services.SnapshotStore.<GetSnapshot>d__7.MoveNext() in /opt/vsts/work/1/s/src/azureml-api/src/ProjectContent/Services/SnapshotStore.cs:line 113\n--- End of stack trace from previous location where exception was thrown ---\n   at System.Runtime.ExceptionServices.ExceptionDispatchInfo.Throw()\n   at System.Runtime.CompilerServices.TaskAwaiter.HandleNonSuccessAndDebuggerNotification(Task task)\n   at Microsoft.MachineLearning.ProjectContent.EntryPoints.Controllers.SnapshotController.<CreateSnapshot>d__12.MoveNext() in /opt/vsts/work/1/s/src/azureml-api/src/ProjectContent/EntryPoints/Controllers/SnapshotController.cs:line 212\n--- End of stack trace from previous location where exception was thrown ---\n   at System.Runtime.ExceptionServices.ExceptionDispatchInfo.Throw()\n   at System.Runtime.CompilerServices.TaskAwaiter.HandleNonSuccessAndDebuggerNotification(Task task)\n   at Microsoft.AspNetCore.Mvc.Internal.ControllerActionInvoker.<InvokeActionMethodAsync>d__12.MoveNext()\n--- End of stack trace from previous location where exception was thrown ---\n   at System.Runtime.ExceptionServices.ExceptionDispatchInfo.Throw()\n   at System.Runtime.CompilerServices.TaskAwaiter.HandleNonSuccessAndDebuggerNotification(Task task)\n   at Microsoft.AspNetCore.Mvc.Internal.ControllerActionInvoker.<InvokeNextActionFilterAsync>d__10.MoveNext()\n--- End of stack trace from previous location where exception was thrown ---\n   at System.Runtime.ExceptionServices.ExceptionDispatchInfo.Throw()\n   at Microsoft.AspNetCore.Mvc.Internal.ControllerActionInvoker.Rethrow(ActionExecutedContext context)\n   at Microsoft.AspNetCore.Mvc.Internal.ControllerActionInvoker.Next(State& next, Scope& scope, Object& state, Boolean& isCompleted)\n   at Microsoft.AspNetCore.Mvc.Internal.ControllerActionInvoker.<InvokeInnerFilterAsync>d__14.MoveNext()\n--- End of stack trace from previous location where exception was thrown ---\n   at System.Runtime.ExceptionServices.ExceptionDispatchInfo.Throw()\n   at System.Runtime.CompilerServices.TaskAwaiter.HandleNonSuccessAndDebuggerNotification(Task task)\n   at Microsoft.AspNetCore.Mvc.Internal.ResourceInvoker.<InvokeNextExceptionFilterAsync>d__23.MoveNext()",
                "type": "Common.WebApi.Exceptions.ResourceNotFoundException"
            },
            "details": [],
            "innerError": null,
            "message": "Unable to find snapshot with id: f2407d9f-2238-46f6-92ce-8f95174e96e7",
            "target": null
        }
    },
    "url": "https://eastus2.experiments.azureml.net/content/v1.0/subscriptions/fac34303-435d-4486-8c3f-7094d82a0b60/resourceGroups/aml-notebooks/providers/Microsoft.MachineLearningServices/workspaces/haieastus2ws3/snapshots/07cf9cba-450b-4026-971a-413ea3b56e3d?parentSnapshotId=f2407d9f-2238-46f6-92ce-8f95174e96e7"
}
Traceback (most recent call last):
  File "/home/ninghai/miniconda3/envs/preview/lib/python3.6/site-packages/azureml/core/webservice/webservice.py", line 268, in _deploy_webservice
    resp.raise_for_status()
  File "/home/ninghai/miniconda3/envs/preview/lib/python3.6/site-packages/requests/models.py", line 939, in raise_for_status
    raise HTTPError(http_error_msg, response=self)
requests.exceptions.HTTPError: 409 Client Error: Conflict for url: https://eastus2.modelmanagement.azureml.net/api/subscriptions/fac34303-435d-4486-8c3f-7094d82a0b60/resourceGroups/aml-notebooks/providers/Microsoft.MachineLearningServices/workspaces/haieastus2ws3/services?api-version=2018-03-01-preview

During handling of the above exception, another exception occurred:

Traceback (most recent call last):
  File "./10.o16n.py", line 65, in <module>
    service = Webservice.deploy_from_image(workspace = ws, name = web_service_name, image = image, deployment_config = aciconfig)
  File "/home/ninghai/miniconda3/envs/preview/lib/python3.6/site-packages/azureml/core/webservice/webservice.py", line 230, in deploy_from_image
    return child._deploy(workspace, name, image, deployment_config)
  File "/home/ninghai/miniconda3/envs/preview/lib/python3.6/site-packages/azureml/core/webservice/aci.py", line 88, in _deploy
    return Webservice._deploy_webservice(workspace, name, create_payload, AciWebservice)
  File "/home/ninghai/miniconda3/envs/preview/lib/python3.6/site-packages/azureml/core/webservice/webservice.py", line 273, in _deploy_webservice
    'Content: {}'.format(resp.status_code, resp.headers, resp.content))
azureml.exceptions.azureml_exception.WebserviceException: Received bad response from Model Management Service:
Response Code: 409
Headers: {'Date': 'Fri, 29 Jun 2018 16:10:29 GMT', 'Content-Type': 'application/json', 'Transfer-Encoding': 'chunked', 'Connection': 'keep-alive', 'api-supported-versions': '2018-03-01-preview', 'x-ms-client-request-id': 'efd67b42d208418eaeba6b9efca6a1dc', 'x-ms-client-session-id': '', 'Strict-Transport-Security': 'max-age=15724800; includeSubDomains; preload'}
Content: b'{"code":"Conflict","statusCode":409,"message":"Conflict","details":[{"code":"ServiceWithNameExists","message":"Workspace haieastus2ws3 already contains a Service with name: rrs02-preview"}]}'
Already on 'master'
