Already on 'master'
ERROR:azure.storage.common.storageclient:Client-Request-ID=22eecf06-7785-11e8-9288-000d3a71b7c3 Retry policy did not allow for a retry: Server-Timestamp=Sun, 24 Jun 2018 08:03:53 GMT, Server-Request-ID=19d02520-901e-00b0-3191-0ba2e4000000, HTTP status code=409, Exception=The specified container already exists.ErrorCode: ContainerAlreadyExists<?xml version="1.0" encoding="utf-8"?><Error><Code>ContainerAlreadyExists</Code><Message>The specified container already exists.RequestId:19d02520-901e-00b0-3191-0ba2e4000000Time:2018-06-24T08:03:53.6352519Z</Message></Error>.
ERROR:azure.storage.common.storageclient:Client-Request-ID=22eecf08-7785-11e8-9288-000d3a71b7c3 Retry policy did not allow for a retry: Server-Timestamp=Sun, 24 Jun 2018 08:03:52 GMT, Server-Request-ID=83a870ce-501e-0025-4591-0bc3d7000000, HTTP status code=409, Exception=The specified container already exists.ErrorCode: ContainerAlreadyExists<?xml version="1.0" encoding="utf-8"?><Error><Code>ContainerAlreadyExists</Code><Message>The specified container already exists.RequestId:83a870ce-501e-0025-4591-0bc3d7000000Time:2018-06-24T08:03:53.8144622Z</Message></Error>.
ERROR:azure.storage.common.storageclient:Client-Request-ID=22eecf0a-7785-11e8-9288-000d3a71b7c3 Retry policy did not allow for a retry: Server-Timestamp=Sun, 24 Jun 2018 08:03:53 GMT, Server-Request-ID=4a119389-701e-0076-3191-0bdfd8000000, HTTP status code=409, Exception=The specified container already exists.ErrorCode: ContainerAlreadyExists<?xml version="1.0" encoding="utf-8"?><Error><Code>ContainerAlreadyExists</Code><Message>The specified container already exists.RequestId:4a119389-701e-0076-3191-0bdfd8000000Time:2018-06-24T08:03:53.9902388Z</Message></Error>.
ERROR:azure.storage.common.storageclient:Client-Request-ID=22eecf0c-7785-11e8-9288-000d3a71b7c3 Retry policy did not allow for a retry: Server-Timestamp=Sun, 24 Jun 2018 08:03:53 GMT, Server-Request-ID=fbe5f791-d01e-0130-6391-0b471b000000, HTTP status code=409, Exception=The specified container already exists.ErrorCode: ContainerAlreadyExists<?xml version="1.0" encoding="utf-8"?><Error><Code>ContainerAlreadyExists</Code><Message>The specified container already exists.RequestId:fbe5f791-d01e-0130-6391-0b471b000000Time:2018-06-24T08:03:54.1650449Z</Message></Error>.
Traceback (most recent call last):
  File "./02.local.py", line 51, in <module>
    script_to_run = train_script)
  File "/home/ninghai/miniconda3/envs/preview/lib/python3.6/site-packages/azureml/core/run.py", line 64, in submit
    return _commands.start_run(project_object, run_config_object, telemetry_values=_telemetry_values)
  File "/home/ninghai/miniconda3/envs/preview/lib/python3.6/site-packages/azureml/execution/_commands.py", line 109, in start_run
    telemetry_values=telemetry_values)
  File "/home/ninghai/miniconda3/envs/preview/lib/python3.6/site-packages/azureml/execution/_commands.py", line 272, in _start_internal_local_cloud
    snapshot_id = snapshot_async.get() if snapshot_async else None
  File "/home/ninghai/miniconda3/envs/preview/lib/python3.6/multiprocessing/pool.py", line 644, in get
    raise self._value
  File "/home/ninghai/miniconda3/envs/preview/lib/python3.6/multiprocessing/pool.py", line 119, in worker
    result = (True, func(*args, **kwds))
  File "/home/ninghai/miniconda3/envs/preview/lib/python3.6/site-packages/azureml/base_sdk_common/create_snapshot.py", line 129, in create_snapshot
    raise SnapshotException(get_http_exception_response_string(response))
azureml.exceptions.azureml_exception.SnapshotException: {
    "status_code": 404,
    "text": {
        "correlation": {
            "operation": "a3872431-475176cfac6b28be",
            "request": "nGkXqFYDRd4="
        },
        "error": {
            "code": "UserError",
            "debugInfo": {
                "data": {},
                "errorResponse": null,
                "innerException": null,
                "message": "Unable to find snapshot with id: 2bd3167f-0978-42bd-9795-6c89fc1e31b2",
                "stackTrace": "   at Microsoft.MachineLearning.Project.Services.SnapshotStore.<GetBlobAsStringOrFailNotFound>d__17.MoveNext() in /opt/vsts/work/1/s/src/azureml-api/src/ProjectContent/Services/SnapshotStore.cs:line 271\n--- End of stack trace from previous location where exception was thrown ---\n   at System.Runtime.ExceptionServices.ExceptionDispatchInfo.Throw()\n   at System.Runtime.CompilerServices.TaskAwaiter.HandleNonSuccessAndDebuggerNotification(Task task)\n   at Microsoft.MachineLearning.Project.Services.SnapshotStore.<GetSnapshot>d__7.MoveNext() in /opt/vsts/work/1/s/src/azureml-api/src/ProjectContent/Services/SnapshotStore.cs:line 113\n--- End of stack trace from previous location where exception was thrown ---\n   at System.Runtime.ExceptionServices.ExceptionDispatchInfo.Throw()\n   at System.Runtime.CompilerServices.TaskAwaiter.HandleNonSuccessAndDebuggerNotification(Task task)\n   at Microsoft.MachineLearning.ProjectContent.EntryPoints.Controllers.SnapshotController.<CreateSnapshot>d__12.MoveNext() in /opt/vsts/work/1/s/src/azureml-api/src/ProjectContent/EntryPoints/Controllers/SnapshotController.cs:line 212\n--- End of stack trace from previous location where exception was thrown ---\n   at System.Runtime.ExceptionServices.ExceptionDispatchInfo.Throw()\n   at System.Runtime.CompilerServices.TaskAwaiter.HandleNonSuccessAndDebuggerNotification(Task task)\n   at Microsoft.AspNetCore.Mvc.Internal.ControllerActionInvoker.<InvokeActionMethodAsync>d__12.MoveNext()\n--- End of stack trace from previous location where exception was thrown ---\n   at System.Runtime.ExceptionServices.ExceptionDispatchInfo.Throw()\n   at System.Runtime.CompilerServices.TaskAwaiter.HandleNonSuccessAndDebuggerNotification(Task task)\n   at Microsoft.AspNetCore.Mvc.Internal.ControllerActionInvoker.<InvokeNextActionFilterAsync>d__10.MoveNext()\n--- End of stack trace from previous location where exception was thrown ---\n   at System.Runtime.ExceptionServices.ExceptionDispatchInfo.Throw()\n   at Microsoft.AspNetCore.Mvc.Internal.ControllerActionInvoker.Rethrow(ActionExecutedContext context)\n   at Microsoft.AspNetCore.Mvc.Internal.ControllerActionInvoker.Next(State& next, Scope& scope, Object& state, Boolean& isCompleted)\n   at Microsoft.AspNetCore.Mvc.Internal.ControllerActionInvoker.<InvokeInnerFilterAsync>d__14.MoveNext()\n--- End of stack trace from previous location where exception was thrown ---\n   at System.Runtime.ExceptionServices.ExceptionDispatchInfo.Throw()\n   at System.Runtime.CompilerServices.TaskAwaiter.HandleNonSuccessAndDebuggerNotification(Task task)\n   at Microsoft.AspNetCore.Mvc.Internal.ResourceInvoker.<InvokeNextExceptionFilterAsync>d__23.MoveNext()",
                "type": "Common.WebApi.Exceptions.ResourceNotFoundException"
            },
            "details": [],
            "innerError": null,
            "message": "Unable to find snapshot with id: 2bd3167f-0978-42bd-9795-6c89fc1e31b2",
            "target": null
        }
    },
    "url": "https://eastus2.experiments.azureml.net/content/v1.0/subscriptions/fac34303-435d-4486-8c3f-7094d82a0b60/resourceGroups/aml-notebooks/providers/Microsoft.MachineLearningServices/workspaces/haieastus2ws3/snapshots/ada28dcf-c9f1-4105-9c75-b3ab171e715a?parentSnapshotId=2bd3167f-0978-42bd-9795-6c89fc1e31b2"
}
Traceback (most recent call last):
  File "./03.aci.py", line 85, in <module>
    script_to_run = train_script)
  File "/home/ninghai/miniconda3/envs/preview/lib/python3.6/site-packages/azureml/core/run.py", line 64, in submit
    return _commands.start_run(project_object, run_config_object, telemetry_values=_telemetry_values)
  File "/home/ninghai/miniconda3/envs/preview/lib/python3.6/site-packages/azureml/execution/_commands.py", line 114, in start_run
    telemetry_values=telemetry_values)
  File "/home/ninghai/miniconda3/envs/preview/lib/python3.6/site-packages/azureml/execution/_commands.py", line 381, in _start_internal
    snapshot_id = snapshot_async.get() if snapshot_async else None
  File "/home/ninghai/miniconda3/envs/preview/lib/python3.6/multiprocessing/pool.py", line 644, in get
    raise self._value
  File "/home/ninghai/miniconda3/envs/preview/lib/python3.6/multiprocessing/pool.py", line 119, in worker
    result = (True, func(*args, **kwds))
  File "/home/ninghai/miniconda3/envs/preview/lib/python3.6/site-packages/azureml/base_sdk_common/create_snapshot.py", line 129, in create_snapshot
    raise SnapshotException(get_http_exception_response_string(response))
azureml.exceptions.azureml_exception.SnapshotException: {
    "status_code": 404,
    "text": {
        "correlation": {
            "operation": "a3872432-475176cfac6b28be",
            "request": "JYiYIBt7NZ0="
        },
        "error": {
            "code": "UserError",
            "debugInfo": {
                "data": {},
                "errorResponse": null,
                "innerException": null,
                "message": "Unable to find snapshot with id: b8317c26-6671-44a6-9859-67a0a7be6afa",
                "stackTrace": "   at Microsoft.MachineLearning.Project.Services.SnapshotStore.<GetBlobAsStringOrFailNotFound>d__17.MoveNext() in /opt/vsts/work/1/s/src/azureml-api/src/ProjectContent/Services/SnapshotStore.cs:line 271\n--- End of stack trace from previous location where exception was thrown ---\n   at System.Runtime.ExceptionServices.ExceptionDispatchInfo.Throw()\n   at System.Runtime.CompilerServices.TaskAwaiter.HandleNonSuccessAndDebuggerNotification(Task task)\n   at Microsoft.MachineLearning.Project.Services.SnapshotStore.<GetSnapshot>d__7.MoveNext() in /opt/vsts/work/1/s/src/azureml-api/src/ProjectContent/Services/SnapshotStore.cs:line 113\n--- End of stack trace from previous location where exception was thrown ---\n   at System.Runtime.ExceptionServices.ExceptionDispatchInfo.Throw()\n   at System.Runtime.CompilerServices.TaskAwaiter.HandleNonSuccessAndDebuggerNotification(Task task)\n   at Microsoft.MachineLearning.ProjectContent.EntryPoints.Controllers.SnapshotController.<CreateSnapshot>d__12.MoveNext() in /opt/vsts/work/1/s/src/azureml-api/src/ProjectContent/EntryPoints/Controllers/SnapshotController.cs:line 212\n--- End of stack trace from previous location where exception was thrown ---\n   at System.Runtime.ExceptionServices.ExceptionDispatchInfo.Throw()\n   at System.Runtime.CompilerServices.TaskAwaiter.HandleNonSuccessAndDebuggerNotification(Task task)\n   at Microsoft.AspNetCore.Mvc.Internal.ControllerActionInvoker.<InvokeActionMethodAsync>d__12.MoveNext()\n--- End of stack trace from previous location where exception was thrown ---\n   at System.Runtime.ExceptionServices.ExceptionDispatchInfo.Throw()\n   at System.Runtime.CompilerServices.TaskAwaiter.HandleNonSuccessAndDebuggerNotification(Task task)\n   at Microsoft.AspNetCore.Mvc.Internal.ControllerActionInvoker.<InvokeNextActionFilterAsync>d__10.MoveNext()\n--- End of stack trace from previous location where exception was thrown ---\n   at System.Runtime.ExceptionServices.ExceptionDispatchInfo.Throw()\n   at Microsoft.AspNetCore.Mvc.Internal.ControllerActionInvoker.Rethrow(ActionExecutedContext context)\n   at Microsoft.AspNetCore.Mvc.Internal.ControllerActionInvoker.Next(State& next, Scope& scope, Object& state, Boolean& isCompleted)\n   at Microsoft.AspNetCore.Mvc.Internal.ControllerActionInvoker.<InvokeInnerFilterAsync>d__14.MoveNext()\n--- End of stack trace from previous location where exception was thrown ---\n   at System.Runtime.ExceptionServices.ExceptionDispatchInfo.Throw()\n   at System.Runtime.CompilerServices.TaskAwaiter.HandleNonSuccessAndDebuggerNotification(Task task)\n   at Microsoft.AspNetCore.Mvc.Internal.ResourceInvoker.<InvokeNextExceptionFilterAsync>d__23.MoveNext()",
                "type": "Common.WebApi.Exceptions.ResourceNotFoundException"
            },
            "details": [],
            "innerError": null,
            "message": "Unable to find snapshot with id: b8317c26-6671-44a6-9859-67a0a7be6afa",
            "target": null
        }
    },
    "url": "https://eastus2.experiments.azureml.net/content/v1.0/subscriptions/fac34303-435d-4486-8c3f-7094d82a0b60/resourceGroups/aml-notebooks/providers/Microsoft.MachineLearningServices/workspaces/haieastus2ws3/snapshots/714ca392-0589-4c59-b2ab-0cd983b196b3?parentSnapshotId=b8317c26-6671-44a6-9859-67a0a7be6afa"
}
Traceback (most recent call last):
  File "./04.dsvm.py", line 71, in <module>
    script_to_run = train_script)
  File "/home/ninghai/miniconda3/envs/preview/lib/python3.6/site-packages/azureml/core/run.py", line 64, in submit
    return _commands.start_run(project_object, run_config_object, telemetry_values=_telemetry_values)
  File "/home/ninghai/miniconda3/envs/preview/lib/python3.6/site-packages/azureml/execution/_commands.py", line 114, in start_run
    telemetry_values=telemetry_values)
  File "/home/ninghai/miniconda3/envs/preview/lib/python3.6/site-packages/azureml/execution/_commands.py", line 381, in _start_internal
    snapshot_id = snapshot_async.get() if snapshot_async else None
  File "/home/ninghai/miniconda3/envs/preview/lib/python3.6/multiprocessing/pool.py", line 644, in get
    raise self._value
  File "/home/ninghai/miniconda3/envs/preview/lib/python3.6/multiprocessing/pool.py", line 119, in worker
    result = (True, func(*args, **kwds))
  File "/home/ninghai/miniconda3/envs/preview/lib/python3.6/site-packages/azureml/base_sdk_common/create_snapshot.py", line 129, in create_snapshot
    raise SnapshotException(get_http_exception_response_string(response))
azureml.exceptions.azureml_exception.SnapshotException: {
    "status_code": 404,
    "text": {
        "correlation": {
            "operation": "70ec622c-4fa154d2e7b3b1f2",
            "request": "vcFGmsB33tc="
        },
        "error": {
            "code": "UserError",
            "debugInfo": {
                "data": {},
                "errorResponse": null,
                "innerException": null,
                "message": "Unable to find snapshot with id: 4eb7d8fa-4b2e-4c7c-99cc-37dd5695023d",
                "stackTrace": "   at Microsoft.MachineLearning.Project.Services.SnapshotStore.<GetBlobAsStringOrFailNotFound>d__17.MoveNext() in /opt/vsts/work/1/s/src/azureml-api/src/ProjectContent/Services/SnapshotStore.cs:line 271\n--- End of stack trace from previous location where exception was thrown ---\n   at System.Runtime.ExceptionServices.ExceptionDispatchInfo.Throw()\n   at System.Runtime.CompilerServices.TaskAwaiter.HandleNonSuccessAndDebuggerNotification(Task task)\n   at Microsoft.MachineLearning.Project.Services.SnapshotStore.<GetSnapshot>d__7.MoveNext() in /opt/vsts/work/1/s/src/azureml-api/src/ProjectContent/Services/SnapshotStore.cs:line 113\n--- End of stack trace from previous location where exception was thrown ---\n   at System.Runtime.ExceptionServices.ExceptionDispatchInfo.Throw()\n   at System.Runtime.CompilerServices.TaskAwaiter.HandleNonSuccessAndDebuggerNotification(Task task)\n   at Microsoft.MachineLearning.ProjectContent.EntryPoints.Controllers.SnapshotController.<CreateSnapshot>d__12.MoveNext() in /opt/vsts/work/1/s/src/azureml-api/src/ProjectContent/EntryPoints/Controllers/SnapshotController.cs:line 212\n--- End of stack trace from previous location where exception was thrown ---\n   at System.Runtime.ExceptionServices.ExceptionDispatchInfo.Throw()\n   at System.Runtime.CompilerServices.TaskAwaiter.HandleNonSuccessAndDebuggerNotification(Task task)\n   at Microsoft.AspNetCore.Mvc.Internal.ControllerActionInvoker.<InvokeActionMethodAsync>d__12.MoveNext()\n--- End of stack trace from previous location where exception was thrown ---\n   at System.Runtime.ExceptionServices.ExceptionDispatchInfo.Throw()\n   at System.Runtime.CompilerServices.TaskAwaiter.HandleNonSuccessAndDebuggerNotification(Task task)\n   at Microsoft.AspNetCore.Mvc.Internal.ControllerActionInvoker.<InvokeNextActionFilterAsync>d__10.MoveNext()\n--- End of stack trace from previous location where exception was thrown ---\n   at System.Runtime.ExceptionServices.ExceptionDispatchInfo.Throw()\n   at Microsoft.AspNetCore.Mvc.Internal.ControllerActionInvoker.Rethrow(ActionExecutedContext context)\n   at Microsoft.AspNetCore.Mvc.Internal.ControllerActionInvoker.Next(State& next, Scope& scope, Object& state, Boolean& isCompleted)\n   at Microsoft.AspNetCore.Mvc.Internal.ControllerActionInvoker.<InvokeInnerFilterAsync>d__14.MoveNext()\n--- End of stack trace from previous location where exception was thrown ---\n   at System.Runtime.ExceptionServices.ExceptionDispatchInfo.Throw()\n   at System.Runtime.CompilerServices.TaskAwaiter.HandleNonSuccessAndDebuggerNotification(Task task)\n   at Microsoft.AspNetCore.Mvc.Internal.ResourceInvoker.<InvokeNextExceptionFilterAsync>d__23.MoveNext()",
                "type": "Common.WebApi.Exceptions.ResourceNotFoundException"
            },
            "details": [],
            "innerError": null,
            "message": "Unable to find snapshot with id: 4eb7d8fa-4b2e-4c7c-99cc-37dd5695023d",
            "target": null
        }
    },
    "url": "https://eastus2.experiments.azureml.net/content/v1.0/subscriptions/fac34303-435d-4486-8c3f-7094d82a0b60/resourceGroups/aml-notebooks/providers/Microsoft.MachineLearningServices/workspaces/haieastus2ws3/snapshots/752a2036-af5b-43bd-b192-b8bd40ae8d4b?parentSnapshotId=4eb7d8fa-4b2e-4c7c-99cc-37dd5695023d"
}
Traceback (most recent call last):
  File "./05.spark.py", line 81, in <module>
    script_to_run = "train-spark.py")
  File "/home/ninghai/miniconda3/envs/preview/lib/python3.6/site-packages/azureml/core/run.py", line 64, in submit
    return _commands.start_run(project_object, run_config_object, telemetry_values=_telemetry_values)
  File "/home/ninghai/miniconda3/envs/preview/lib/python3.6/site-packages/azureml/execution/_commands.py", line 114, in start_run
    telemetry_values=telemetry_values)
  File "/home/ninghai/miniconda3/envs/preview/lib/python3.6/site-packages/azureml/execution/_commands.py", line 381, in _start_internal
    snapshot_id = snapshot_async.get() if snapshot_async else None
  File "/home/ninghai/miniconda3/envs/preview/lib/python3.6/multiprocessing/pool.py", line 644, in get
    raise self._value
  File "/home/ninghai/miniconda3/envs/preview/lib/python3.6/multiprocessing/pool.py", line 119, in worker
    result = (True, func(*args, **kwds))
  File "/home/ninghai/miniconda3/envs/preview/lib/python3.6/site-packages/azureml/base_sdk_common/create_snapshot.py", line 129, in create_snapshot
    raise SnapshotException(get_http_exception_response_string(response))
azureml.exceptions.azureml_exception.SnapshotException: {
    "status_code": 404,
    "text": {
        "correlation": {
            "operation": "e87da64a-4dafe5d5581f0658",
            "request": "W6Te2i3IDjI="
        },
        "error": {
            "code": "UserError",
            "debugInfo": {
                "data": {},
                "errorResponse": null,
                "innerException": null,
                "message": "Unable to find snapshot with id: e9c619a7-7486-4eb3-8e27-4efdb021ec32",
                "stackTrace": "   at Microsoft.MachineLearning.Project.Services.SnapshotStore.<GetBlobAsStringOrFailNotFound>d__17.MoveNext() in /opt/vsts/work/1/s/src/azureml-api/src/ProjectContent/Services/SnapshotStore.cs:line 271\n--- End of stack trace from previous location where exception was thrown ---\n   at System.Runtime.ExceptionServices.ExceptionDispatchInfo.Throw()\n   at System.Runtime.CompilerServices.TaskAwaiter.HandleNonSuccessAndDebuggerNotification(Task task)\n   at Microsoft.MachineLearning.Project.Services.SnapshotStore.<GetSnapshot>d__7.MoveNext() in /opt/vsts/work/1/s/src/azureml-api/src/ProjectContent/Services/SnapshotStore.cs:line 113\n--- End of stack trace from previous location where exception was thrown ---\n   at System.Runtime.ExceptionServices.ExceptionDispatchInfo.Throw()\n   at System.Runtime.CompilerServices.TaskAwaiter.HandleNonSuccessAndDebuggerNotification(Task task)\n   at Microsoft.MachineLearning.ProjectContent.EntryPoints.Controllers.SnapshotController.<CreateSnapshot>d__12.MoveNext() in /opt/vsts/work/1/s/src/azureml-api/src/ProjectContent/EntryPoints/Controllers/SnapshotController.cs:line 212\n--- End of stack trace from previous location where exception was thrown ---\n   at System.Runtime.ExceptionServices.ExceptionDispatchInfo.Throw()\n   at System.Runtime.CompilerServices.TaskAwaiter.HandleNonSuccessAndDebuggerNotification(Task task)\n   at Microsoft.AspNetCore.Mvc.Internal.ControllerActionInvoker.<InvokeActionMethodAsync>d__12.MoveNext()\n--- End of stack trace from previous location where exception was thrown ---\n   at System.Runtime.ExceptionServices.ExceptionDispatchInfo.Throw()\n   at System.Runtime.CompilerServices.TaskAwaiter.HandleNonSuccessAndDebuggerNotification(Task task)\n   at Microsoft.AspNetCore.Mvc.Internal.ControllerActionInvoker.<InvokeNextActionFilterAsync>d__10.MoveNext()\n--- End of stack trace from previous location where exception was thrown ---\n   at System.Runtime.ExceptionServices.ExceptionDispatchInfo.Throw()\n   at Microsoft.AspNetCore.Mvc.Internal.ControllerActionInvoker.Rethrow(ActionExecutedContext context)\n   at Microsoft.AspNetCore.Mvc.Internal.ControllerActionInvoker.Next(State& next, Scope& scope, Object& state, Boolean& isCompleted)\n   at Microsoft.AspNetCore.Mvc.Internal.ControllerActionInvoker.<InvokeInnerFilterAsync>d__14.MoveNext()\n--- End of stack trace from previous location where exception was thrown ---\n   at System.Runtime.ExceptionServices.ExceptionDispatchInfo.Throw()\n   at System.Runtime.CompilerServices.TaskAwaiter.HandleNonSuccessAndDebuggerNotification(Task task)\n   at Microsoft.AspNetCore.Mvc.Internal.ResourceInvoker.<InvokeNextExceptionFilterAsync>d__23.MoveNext()",
                "type": "Common.WebApi.Exceptions.ResourceNotFoundException"
            },
            "details": [],
            "innerError": null,
            "message": "Unable to find snapshot with id: e9c619a7-7486-4eb3-8e27-4efdb021ec32",
            "target": null
        }
    },
    "url": "https://eastus2.experiments.azureml.net/content/v1.0/subscriptions/fac34303-435d-4486-8c3f-7094d82a0b60/resourceGroups/aml-notebooks/providers/Microsoft.MachineLearningServices/workspaces/haieastus2ws3/snapshots/9344d0f1-4b40-4ddb-a33d-2c4ef5d51dd1?parentSnapshotId=e9c619a7-7486-4eb3-8e27-4efdb021ec32"
}
Traceback (most recent call last):
  File "./07.sklearn.hd.py", line 88, in <module>
    run = sk_est.fit()
  File "/home/ninghai/miniconda3/envs/preview/lib/python3.6/site-packages/azureml/train/estimator.py", line 421, in fit
    return super(Estimator, self).fit()
  File "/home/ninghai/miniconda3/envs/preview/lib/python3.6/site-packages/azureml/train/estimator.py", line 78, in fit
    _telemetry_values=telemetry_values)
  File "/home/ninghai/miniconda3/envs/preview/lib/python3.6/site-packages/azureml/core/run.py", line 64, in submit
    return _commands.start_run(project_object, run_config_object, telemetry_values=_telemetry_values)
  File "/home/ninghai/miniconda3/envs/preview/lib/python3.6/site-packages/azureml/execution/_commands.py", line 114, in start_run
    telemetry_values=telemetry_values)
  File "/home/ninghai/miniconda3/envs/preview/lib/python3.6/site-packages/azureml/execution/_commands.py", line 381, in _start_internal
    snapshot_id = snapshot_async.get() if snapshot_async else None
  File "/home/ninghai/miniconda3/envs/preview/lib/python3.6/multiprocessing/pool.py", line 644, in get
    raise self._value
  File "/home/ninghai/miniconda3/envs/preview/lib/python3.6/multiprocessing/pool.py", line 119, in worker
    result = (True, func(*args, **kwds))
  File "/home/ninghai/miniconda3/envs/preview/lib/python3.6/site-packages/azureml/base_sdk_common/create_snapshot.py", line 129, in create_snapshot
    raise SnapshotException(get_http_exception_response_string(response))
azureml.exceptions.azureml_exception.SnapshotException: {
    "status_code": 404,
    "text": {
        "correlation": {
            "operation": "3559b35-422e9e60cd6d6304",
            "request": "x1sFOlCJ3Dk="
        },
        "error": {
            "code": "UserError",
            "debugInfo": {
                "data": {},
                "errorResponse": null,
                "innerException": null,
                "message": "Unable to find snapshot with id: 87311c3d-6b5f-4da6-a9ad-6d027c1096bc",
                "stackTrace": "   at Microsoft.MachineLearning.Project.Services.SnapshotStore.<GetBlobAsStringOrFailNotFound>d__17.MoveNext() in /opt/vsts/work/1/s/src/azureml-api/src/ProjectContent/Services/SnapshotStore.cs:line 271\n--- End of stack trace from previous location where exception was thrown ---\n   at System.Runtime.ExceptionServices.ExceptionDispatchInfo.Throw()\n   at System.Runtime.CompilerServices.TaskAwaiter.HandleNonSuccessAndDebuggerNotification(Task task)\n   at Microsoft.MachineLearning.Project.Services.SnapshotStore.<GetSnapshot>d__7.MoveNext() in /opt/vsts/work/1/s/src/azureml-api/src/ProjectContent/Services/SnapshotStore.cs:line 113\n--- End of stack trace from previous location where exception was thrown ---\n   at System.Runtime.ExceptionServices.ExceptionDispatchInfo.Throw()\n   at System.Runtime.CompilerServices.TaskAwaiter.HandleNonSuccessAndDebuggerNotification(Task task)\n   at Microsoft.MachineLearning.ProjectContent.EntryPoints.Controllers.SnapshotController.<CreateSnapshot>d__12.MoveNext() in /opt/vsts/work/1/s/src/azureml-api/src/ProjectContent/EntryPoints/Controllers/SnapshotController.cs:line 212\n--- End of stack trace from previous location where exception was thrown ---\n   at System.Runtime.ExceptionServices.ExceptionDispatchInfo.Throw()\n   at System.Runtime.CompilerServices.TaskAwaiter.HandleNonSuccessAndDebuggerNotification(Task task)\n   at Microsoft.AspNetCore.Mvc.Internal.ControllerActionInvoker.<InvokeActionMethodAsync>d__12.MoveNext()\n--- End of stack trace from previous location where exception was thrown ---\n   at System.Runtime.ExceptionServices.ExceptionDispatchInfo.Throw()\n   at System.Runtime.CompilerServices.TaskAwaiter.HandleNonSuccessAndDebuggerNotification(Task task)\n   at Microsoft.AspNetCore.Mvc.Internal.ControllerActionInvoker.<InvokeNextActionFilterAsync>d__10.MoveNext()\n--- End of stack trace from previous location where exception was thrown ---\n   at System.Runtime.ExceptionServices.ExceptionDispatchInfo.Throw()\n   at Microsoft.AspNetCore.Mvc.Internal.ControllerActionInvoker.Rethrow(ActionExecutedContext context)\n   at Microsoft.AspNetCore.Mvc.Internal.ControllerActionInvoker.Next(State& next, Scope& scope, Object& state, Boolean& isCompleted)\n   at Microsoft.AspNetCore.Mvc.Internal.ControllerActionInvoker.<InvokeInnerFilterAsync>d__14.MoveNext()\n--- End of stack trace from previous location where exception was thrown ---\n   at System.Runtime.ExceptionServices.ExceptionDispatchInfo.Throw()\n   at System.Runtime.CompilerServices.TaskAwaiter.HandleNonSuccessAndDebuggerNotification(Task task)\n   at Microsoft.AspNetCore.Mvc.Internal.ResourceInvoker.<InvokeNextExceptionFilterAsync>d__23.MoveNext()",
                "type": "Common.WebApi.Exceptions.ResourceNotFoundException"
            },
            "details": [],
            "innerError": null,
            "message": "Unable to find snapshot with id: 87311c3d-6b5f-4da6-a9ad-6d027c1096bc",
            "target": null
        }
    },
    "url": "https://eastus2.experiments.azureml.net/content/v1.0/subscriptions/fac34303-435d-4486-8c3f-7094d82a0b60/resourceGroups/aml-notebooks/providers/Microsoft.MachineLearningServices/workspaces/haieastus2ws3/snapshots/d1902a1e-c0aa-4fad-8ccf-465aaf579990?parentSnapshotId=87311c3d-6b5f-4da6-a9ad-6d027c1096bc"
}
Traceback (most recent call last):
  File "./08.tf.hd.py", line 92, in <module>
    run = tfe.fit()
  File "/home/ninghai/miniconda3/envs/preview/lib/python3.6/site-packages/azureml/train/dnn.py", line 332, in fit
    return super(TensorFlow, self).fit()
  File "/home/ninghai/miniconda3/envs/preview/lib/python3.6/site-packages/azureml/train/estimator.py", line 78, in fit
    _telemetry_values=telemetry_values)
  File "/home/ninghai/miniconda3/envs/preview/lib/python3.6/site-packages/azureml/core/run.py", line 64, in submit
    return _commands.start_run(project_object, run_config_object, telemetry_values=_telemetry_values)
  File "/home/ninghai/miniconda3/envs/preview/lib/python3.6/site-packages/azureml/execution/_commands.py", line 114, in start_run
    telemetry_values=telemetry_values)
  File "/home/ninghai/miniconda3/envs/preview/lib/python3.6/site-packages/azureml/execution/_commands.py", line 381, in _start_internal
    snapshot_id = snapshot_async.get() if snapshot_async else None
  File "/home/ninghai/miniconda3/envs/preview/lib/python3.6/multiprocessing/pool.py", line 644, in get
    raise self._value
  File "/home/ninghai/miniconda3/envs/preview/lib/python3.6/multiprocessing/pool.py", line 119, in worker
    result = (True, func(*args, **kwds))
  File "/home/ninghai/miniconda3/envs/preview/lib/python3.6/site-packages/azureml/base_sdk_common/create_snapshot.py", line 129, in create_snapshot
    raise SnapshotException(get_http_exception_response_string(response))
azureml.exceptions.azureml_exception.SnapshotException: {
    "status_code": 404,
    "text": {
        "correlation": {
            "operation": "48bbfc82-4152fc13217d2006",
            "request": "0o2bMfx5ecA="
        },
        "error": {
            "code": "UserError",
            "debugInfo": {
                "data": {},
                "errorResponse": null,
                "innerException": null,
                "message": "Unable to find snapshot with id: f2407d9f-2238-46f6-92ce-8f95174e96e7",
                "stackTrace": "   at Microsoft.MachineLearning.Project.Services.SnapshotStore.<GetBlobAsStringOrFailNotFound>d__17.MoveNext() in /opt/vsts/work/1/s/src/azureml-api/src/ProjectContent/Services/SnapshotStore.cs:line 271\n--- End of stack trace from previous location where exception was thrown ---\n   at System.Runtime.ExceptionServices.ExceptionDispatchInfo.Throw()\n   at System.Runtime.CompilerServices.TaskAwaiter.HandleNonSuccessAndDebuggerNotification(Task task)\n   at Microsoft.MachineLearning.Project.Services.SnapshotStore.<GetSnapshot>d__7.MoveNext() in /opt/vsts/work/1/s/src/azureml-api/src/ProjectContent/Services/SnapshotStore.cs:line 113\n--- End of stack trace from previous location where exception was thrown ---\n   at System.Runtime.ExceptionServices.ExceptionDispatchInfo.Throw()\n   at System.Runtime.CompilerServices.TaskAwaiter.HandleNonSuccessAndDebuggerNotification(Task task)\n   at Microsoft.MachineLearning.ProjectContent.EntryPoints.Controllers.SnapshotController.<CreateSnapshot>d__12.MoveNext() in /opt/vsts/work/1/s/src/azureml-api/src/ProjectContent/EntryPoints/Controllers/SnapshotController.cs:line 212\n--- End of stack trace from previous location where exception was thrown ---\n   at System.Runtime.ExceptionServices.ExceptionDispatchInfo.Throw()\n   at System.Runtime.CompilerServices.TaskAwaiter.HandleNonSuccessAndDebuggerNotification(Task task)\n   at Microsoft.AspNetCore.Mvc.Internal.ControllerActionInvoker.<InvokeActionMethodAsync>d__12.MoveNext()\n--- End of stack trace from previous location where exception was thrown ---\n   at System.Runtime.ExceptionServices.ExceptionDispatchInfo.Throw()\n   at System.Runtime.CompilerServices.TaskAwaiter.HandleNonSuccessAndDebuggerNotification(Task task)\n   at Microsoft.AspNetCore.Mvc.Internal.ControllerActionInvoker.<InvokeNextActionFilterAsync>d__10.MoveNext()\n--- End of stack trace from previous location where exception was thrown ---\n   at System.Runtime.ExceptionServices.ExceptionDispatchInfo.Throw()\n   at Microsoft.AspNetCore.Mvc.Internal.ControllerActionInvoker.Rethrow(ActionExecutedContext context)\n   at Microsoft.AspNetCore.Mvc.Internal.ControllerActionInvoker.Next(State& next, Scope& scope, Object& state, Boolean& isCompleted)\n   at Microsoft.AspNetCore.Mvc.Internal.ControllerActionInvoker.<InvokeInnerFilterAsync>d__14.MoveNext()\n--- End of stack trace from previous location where exception was thrown ---\n   at System.Runtime.ExceptionServices.ExceptionDispatchInfo.Throw()\n   at System.Runtime.CompilerServices.TaskAwaiter.HandleNonSuccessAndDebuggerNotification(Task task)\n   at Microsoft.AspNetCore.Mvc.Internal.ResourceInvoker.<InvokeNextExceptionFilterAsync>d__23.MoveNext()",
                "type": "Common.WebApi.Exceptions.ResourceNotFoundException"
            },
            "details": [],
            "innerError": null,
            "message": "Unable to find snapshot with id: f2407d9f-2238-46f6-92ce-8f95174e96e7",
            "target": null
        }
    },
    "url": "https://eastus2.experiments.azureml.net/content/v1.0/subscriptions/fac34303-435d-4486-8c3f-7094d82a0b60/resourceGroups/aml-notebooks/providers/Microsoft.MachineLearningServices/workspaces/haieastus2ws3/snapshots/bef66043-a5db-42e6-865c-f5c425ed52d6?parentSnapshotId=f2407d9f-2238-46f6-92ce-8f95174e96e7"
}
ERROR:azure.storage.common.storageclient:Client-Request-ID=42740f3e-7786-11e8-9288-000d3a71b7c3 Retry policy did not allow for a retry: Server-Timestamp=Sun, 24 Jun 2018 08:11:55 GMT, Server-Request-ID=0120e172-301e-003e-6293-0bed45000000, HTTP status code=409, Exception=The specified container already exists.ErrorCode: ContainerAlreadyExists<?xml version="1.0" encoding="utf-8"?><Error><Code>ContainerAlreadyExists</Code><Message>The specified container already exists.RequestId:0120e172-301e-003e-6293-0bed45000000Time:2018-06-24T08:11:56.0120434Z</Message></Error>.
ERROR:azure.storage.common.storageclient:Client-Request-ID=42740f40-7786-11e8-9288-000d3a71b7c3 Retry policy did not allow for a retry: Server-Timestamp=Sun, 24 Jun 2018 08:11:56 GMT, Server-Request-ID=f70033fb-301e-0017-5b93-0b9b07000000, HTTP status code=409, Exception=The specified container already exists.ErrorCode: ContainerAlreadyExists<?xml version="1.0" encoding="utf-8"?><Error><Code>ContainerAlreadyExists</Code><Message>The specified container already exists.RequestId:f70033fb-301e-0017-5b93-0b9b07000000Time:2018-06-24T08:11:56.1991651Z</Message></Error>.
ERROR:azure.storage.common.storageclient:Client-Request-ID=42740f42-7786-11e8-9288-000d3a71b7c3 Retry policy did not allow for a retry: Server-Timestamp=Sun, 24 Jun 2018 08:11:55 GMT, Server-Request-ID=c01a383f-a01e-00b8-1693-0bb997000000, HTTP status code=409, Exception=The specified container already exists.ErrorCode: ContainerAlreadyExists<?xml version="1.0" encoding="utf-8"?><Error><Code>ContainerAlreadyExists</Code><Message>The specified container already exists.RequestId:c01a383f-a01e-00b8-1693-0bb997000000Time:2018-06-24T08:11:56.4328528Z</Message></Error>.
ERROR:azure.storage.common.storageclient:Client-Request-ID=42740f44-7786-11e8-9288-000d3a71b7c3 Retry policy did not allow for a retry: Server-Timestamp=Sun, 24 Jun 2018 08:11:56 GMT, Server-Request-ID=bf624da9-601e-00e1-0193-0bbc11000000, HTTP status code=409, Exception=The specified container already exists.ErrorCode: ContainerAlreadyExists<?xml version="1.0" encoding="utf-8"?><Error><Code>ContainerAlreadyExists</Code><Message>The specified container already exists.RequestId:bf624da9-601e-00e1-0193-0bbc11000000Time:2018-06-24T08:11:56.6009948Z</Message></Error>.
Traceback (most recent call last):
  File "/home/ninghai/miniconda3/envs/preview/lib/python3.6/site-packages/azureml/core/webservice/webservice.py", line 268, in _deploy_webservice
    resp.raise_for_status()
  File "/home/ninghai/miniconda3/envs/preview/lib/python3.6/site-packages/requests/models.py", line 939, in raise_for_status
    raise HTTPError(http_error_msg, response=self)
requests.exceptions.HTTPError: 409 Client Error: Conflict for url: https://eastus2.modelmanagement.azureml.net/api/subscriptions/fac34303-435d-4486-8c3f-7094d82a0b60/resourceGroups/aml-notebooks/providers/Microsoft.MachineLearningServices/workspaces/haieastus2ws3/services?api-version=2018-03-01-preview

During handling of the above exception, another exception occurred:

Traceback (most recent call last):
  File "./10.o16n.py", line 65, in <module>
    service = Webservice.deploy_from_image(workspace = ws, name = web_service_name, image = image, deployment_config = aciconfig)
  File "/home/ninghai/miniconda3/envs/preview/lib/python3.6/site-packages/azureml/core/webservice/webservice.py", line 230, in deploy_from_image
    return child._deploy(workspace, name, image, deployment_config)
  File "/home/ninghai/miniconda3/envs/preview/lib/python3.6/site-packages/azureml/core/webservice/aci.py", line 88, in _deploy
    return Webservice._deploy_webservice(workspace, name, create_payload, AciWebservice)
  File "/home/ninghai/miniconda3/envs/preview/lib/python3.6/site-packages/azureml/core/webservice/webservice.py", line 273, in _deploy_webservice
    'Content: {}'.format(resp.status_code, resp.headers, resp.content))
azureml.exceptions.azureml_exception.WebserviceException: Received bad response from Model Management Service:
Response Code: 409
Headers: {'Date': 'Sun, 24 Jun 2018 08:14:08 GMT', 'Content-Type': 'application/json', 'Transfer-Encoding': 'chunked', 'Connection': 'keep-alive', 'api-supported-versions': '2018-03-01-preview', 'x-ms-client-request-id': '4879cd49dc5e456b9b3c09fc90fd8ca0', 'x-ms-client-session-id': '', 'Strict-Transport-Security': 'max-age=15724800; includeSubDomains; preload'}
Content: b'{"code":"Conflict","statusCode":409,"message":"Conflict","details":[{"code":"ServiceWithNameExists","message":"Workspace haieastus2ws3 already contains a Service with name: rrs02-preview"}]}'
Already on 'master'
